Workbook

Sheet Récap
A1: SubjectID | B1: Notes | C1: Profil | D1: Catégorie | E1: EQ | F1: RED | G1: Comp_Count | H1: Sess_Count | I1: Comp_FP_Ratio | J1: Frac_Long | K1: Mean_Test
A2: =EQ!A2 -> 0685c8001a43b03e0a155e1afa0c7bec2f4e82d24f7ce4843b25a441c45dd335 | B2: {=XLOOKUP(A2, Notes!A:A, Notes!B:B, "")} -> 70.2 | C2: =IFERROR(IMAGE(VLOOKUP(A2,DriveImages!A:C,3,FALSE),4,240,520),"") | D2: =IF($A2="","",IF(AND(N($G2)<=Params!$D$2,N($H2)<=Params!$E$2),"Peu actif",IF(AND(N($I2)>=Params!$F$4,N($E2)<=Params!$B$2,N($F2)<=Params!$C$2),"Efficace",IF(AND(N($F2)>=Params!$C$4,OR(N($I2)<=Params!$F$3,N($E2)>=Params!$B$4)),"Bloqué",IF(AND(OR(N($G2)>=Params!$D$4,N($H2)>=Params!$E$4),N($I2)<=Params!$F$3),"Persévérant",IF(AND(N($J2)>=Params!$G$4,OR(N($G2)<=Params!$D$3,N($H2)<=Params!$E$3)),"Sporadique","Intermédiaire")))))) -> Peu actif | E2: {=XLOOKUP(A2, EQ!A:A, EQ!B:B, "")} -> 0 | F2: {=XLOOKUP(A2, RED!A:A, RED!B:B, "")} -> 0 | G2: =XLOOKUP(A2, INDIRECT("'"&G$1&"'!A:A"), INDIRECT("'"&G$1&"'!B:B"), "") -> 4 | H2: =XLOOKUP($A2, INDIRECT("'"&H$1&"'!A:A"), INDIRECT("'"&H$1&"'!B:B"), "") -> 1 | I2: =XLOOKUP($A2, INDIRECT("'"&I$1&"'!A:A"), INDIRECT("'"&I$1&"'!B:B"), "") -> 1 | J2: =XLOOKUP($A2, INDIRECT("'"&J$1&"'!A:A"), INDIRECT("'"&J$1&"'!B:B"), "") -> 0 | K2: =XLOOKUP($A2, INDIRECT("'"&K$1&"'!A:A"), INDIRECT("'"&K$1&"'!B:B"), "") -> 0.9565215
A3: =EQ!A40 -> 69ea8e8a316c3f982db0286a71ca33c251b858994e27bb848e628967df9d15f9 | B3: {=XLOOKUP(A3, Notes!A:A, Notes!B:B, "")} -> 73.15 | C3: =IFERROR(IMAGE(VLOOKUP(A3,DriveImages!A:C,3,FALSE),4,240,520),"") | D3: =IF($A3="","",IF(AND(N($G3)<=Params!$D$2,N($H3)<=Params!$E$2),"Peu actif",IF(AND(N($I3)>=Params!$F$4,N($E3)<=Params!$B$2,N($F3)<=Params!$C$2),"Efficace",IF(AND(N($F3)>=Params!$C$4,OR(N($I3)<=Params!$F$3,N($E3)>=Params!$B$4)),"Bloqué",IF(AND(OR(N($G3)>=Params!$D$4,N($H3)>=Params!$E$4),N($I3)<=Params!$F$3),"Persévérant",IF(AND(N($J3)>=Params!$G$4,OR(N($G3)<=Params!$D$3,N($H3)<=Params!$E$3)),"Sporadique","Intermédiaire")))))) -> Efficace | E3: {=XLOOKUP(A3, EQ!A:A, EQ!B:B, "")} -> 0 | F3: {=XLOOKUP(A3, RED!A:A, RED!B:B, "")} -> 0 | G3: =XLOOKUP(A3, INDIRECT("'"&G$1&"'!A:A"), INDIRECT("'"&G$1&"'!B:B"), "") -> 4 | H3: =XLOOKUP($A3, INDIRECT("'"&H$1&"'!A:A"), INDIRECT("'"&H$1&"'!B:B"), "") -> 3 | I3: =XLOOKUP($A3, INDIRECT("'"&I$1&"'!A:A"), INDIRECT("'"&I$1&"'!B:B"), "") -> 1 | J3: =XLOOKUP($A3, INDIRECT("'"&J$1&"'!A:A"), INDIRECT("'"&J$1&"'!B:B"), "") -> 0.66666667 | K3: =XLOOKUP($A3, INDIRECT("'"&K$1&"'!A:A"), INDIRECT("'"&K$1&"'!B:B"), "") -> 0.9285715
A4: =EQ!A4 -> 091dc109aa58c7a670f4b61bc23df548fec73c05c7582dfb7c51f3a925d3618f | B4: {=XLOOKUP(A4, Notes!A:A, Notes!B:B, "")} -> 68.44 | C4: =IFERROR(IMAGE(VLOOKUP(A4,DriveImages!A:C,3,FALSE),4,240,520),"") | D4: =IF($A4="","",IF(AND(N($G4)<=Params!$D$2,N($H4)<=Params!$E$2),"Peu actif",IF(AND(N($I4)>=Params!$F$4,N($E4)<=Params!$B$2,N($F4)<=Params!$C$2),"Efficace",IF(AND(N($F4)>=Params!$C$4,OR(N($I4)<=Params!$F$3,N($E4)>=Params!$B$4)),"Bloqué",IF(AND(OR(N($G4)>=Params!$D$4,N($H4)>=Params!$E$4),N($I4)<=Params!$F$3),"Persévérant",IF(AND(N($J4)>=Params!$G$4,OR(N($G4)<=Params!$D$3,N($H4)<=Params!$E$3)),"Sporadique","Intermédiaire")))))) -> Efficace | E4: {=XLOOKUP(A4, EQ!A:A, EQ!B:B, "")} -> 0.045454545 | F4: {=XLOOKUP(A4, RED!A:A, RED!B:B, "")} -> 0.02272727 | G4: =XLOOKUP(A4, INDIRECT("'"&G$1&"'!A:A"), INDIRECT("'"&G$1&"'!B:B"), "") -> 29 | H4: =XLOOKUP($A4, INDIRECT("'"&H$1&"'!A:A"), INDIRECT("'"&H$1&"'!B:B"), "") -> 4 | I4: =XLOOKUP($A4, INDIRECT("'"&I$1&"'!A:A"), INDIRECT("'"&I$1&"'!B:B"), "") -> 0.89655172 | J4: =XLOOKUP($A4, INDIRECT("'"&J$1&"'!A:A"), INDIRECT("'"&J$1&"'!B:B"), "") -> 0.10714286 | K4: =XLOOKUP($A4, INDIRECT("'"&K$1&"'!A:A"), INDIRECT("'"&K$1&"'!B:B"), "") -> 0.87335797
A5: =EQ!A15 -> 275839578ec60b5084d5e18fccb01310e9f1b78293cad00bec043945e0f3e629 | B5: {=XLOOKUP(A5, Notes!A:A, Notes!B:B, "")} -> 70.3 | C5: =IFERROR(IMAGE(VLOOKUP(A5,DriveImages!A:C,3,FALSE),4,240,520),"") | D5: =IF($A5="","",IF(AND(N($G5)<=Params!$D$2,N($H5)<=Params!$E$2),"Peu actif",IF(AND(N($I5)>=Params!$F$4,N($E5)<=Params!$B$2,N($F5)<=Params!$C$2),"Efficace",IF(AND(N($F5)>=Params!$C$4,OR(N($I5)<=Params!$F$3,N($E5)>=Params!$B$4)),"Bloqué",IF(AND(OR(N($G5)>=Params!$D$4,N($H5)>=Params!$E$4),N($I5)<=Params!$F$3),"Persévérant",IF(AND(N($J5)>=Params!$G$4,OR(N($G5)<=Params!$D$3,N($H5)<=Params!$E$3)),"Sporadique","Intermédiaire")))))) -> Efficace | E5: {=XLOOKUP(A5, EQ!A:A, EQ!B:B, "")} -> 0 | F5: {=XLOOKUP(A5, RED!A:A, RED!B:B, "")} -> 0 | G5: =XLOOKUP(A5, INDIRECT("'"&G$1&"'!A:A"), INDIRECT("'"&G$1&"'!B:B"), "") -> 14 | H5: =XLOOKUP($A5, INDIRECT("'"&H$1&"'!A:A"), INDIRECT("'"&H$1&"'!B:B"), "") -> 3 | I5: =XLOOKUP($A5, INDIRECT("'"&I$1&"'!A:A"), INDIRECT("'"&I$1&"'!B:B"), "") -> 0.85714286 | J5: =XLOOKUP($A5, INDIRECT("'"&J$1&"'!A:A"), INDIRECT("'"&J$1&"'!B:B"), "") -> 0.15384615 | K5: =XLOOKUP($A5, INDIRECT("'"&K$1&"'!A:A"), INDIRECT("'"&K$1&"'!B:B"), "") -> 0.83724307
A6: =EQ!A86 -> cbdbb864a7b15c5903aa09adff018a3d184f25c250b86926a5bc3fd9d9169037 | B6: {=XLOOKUP(A6, Notes!A:A, Notes!B:B, "")} -> 0 | C6: =IFERROR(IMAGE(VLOOKUP(A6,DriveImages!A:C,3,FALSE),4,240,520),"") | D6: =IF($A6="","",IF(AND(N($G6)<=Params!$D$2,N($H6)<=Params!$E$2),"Peu actif",IF(AND(N($I6)>=Params!$F$4,N($E6)<=Params!$B$2,N($F6)<=Params!$C$2),"Efficace",IF(AND(N($F6)>=Params!$C$4,OR(N($I6)<=Params!$F$3,N($E6)>=Params!$B$4)),"Bloqué",IF(AND(OR(N($G6)>=Params!$D$4,N($H6)>=Params!$E$4),N($I6)<=Params!$F$3),"Persévérant",IF(AND(N($J6)>=Params!$G$4,OR(N($G6)<=Params!$D$3,N($H6)<=Params!$E$3)),"Sporadique","Intermédiaire")))))) -> Intermédiaire | E6: {=XLOOKUP(A6, EQ!A:A, EQ!B:B, "")} -> 0.25 | F6: {=XLOOKUP(A6, RED!A:A, RED!B:B, "")} -> 0.125 | G6: =XLOOKUP(A6, INDIRECT("'"&G$1&"'!A:A"), INDIRECT("'"&G$1&"'!B:B"), "") -> 14 | H6: =XLOOKUP($A6, INDIRECT("'"&H$1&"'!A:A"), INDIRECT("'"&H$1&"'!B:B"), "") -> 1 | I6: =XLOOKUP($A6, INDIRECT("'"&I$1&"'!A:A"), INDIRECT("'"&I$1&"'!B:B"), "") -> 0.85714286 | J6: =XLOOKUP($A6, INDIRECT("'"&J$1&"'!A:A"), INDIRECT("'"&J$1&"'!B:B"), "") -> 0 | K6: =XLOOKUP($A6, INDIRECT("'"&K$1&"'!A:A"), INDIRECT("'"&K$1&"'!B:B"), "") -> 0.83392486
A7: =EQ!A65 -> 95944dae06f4e15b8e63e41064092bc51db9f568df5abcdb866112b0a58a759a | B7: {=XLOOKUP(A7, Notes!A:A, Notes!B:B, "")} -> 82.53 | C7: =IFERROR(IMAGE(VLOOKUP(A7,DriveImages!A:C,3,FALSE),4,240,520),"") | D7: =IF($A7="","",IF(AND(N($G7)<=Params!$D$2,N($H7)<=Params!$E$2),"Peu actif",IF(AND(N($I7)>=Params!$F$4,N($E7)<=Params!$B$2,N($F7)<=Params!$C$2),"Efficace",IF(AND(N($F7)>=Params!$C$4,OR(N($I7)<=Params!$F$3,N($E7)>=Params!$B$4)),"Bloqué",IF(AND(OR(N($G7)>=Params!$D$4,N($H7)>=Params!$E$4),N($I7)<=Params!$F$3),"Persévérant",IF(AND(N($J7)>=Params!$G$4,OR(N($G7)<=Params!$D$3,N($H7)<=Params!$E$3)),"Sporadique","Intermédiaire")))))) -> Efficace | E7: {=XLOOKUP(A7, EQ!A:A, EQ!B:B, "")} -> 0 | F7: {=XLOOKUP(A7, RED!A:A, RED!B:B, "")} -> 0 | G7: =XLOOKUP(A7, INDIRECT("'"&G$1&"'!A:A"), INDIRECT("'"&G$1&"'!B:B"), "") -> 6 | H7: =XLOOKUP($A7, INDIRECT("'"&H$1&"'!A:A"), INDIRECT("'"&H$1&"'!B:B"), "") -> 1 | I7: =XLOOKUP($A7, INDIRECT("'"&I$1&"'!A:A"), INDIRECT("'"&I$1&"'!B:B"), "") -> 0.83333333 | J7: =XLOOKUP($A7, INDIRECT("'"&J$1&"'!A:A"), INDIRECT("'"&J$1&"'!B:B"), "") -> 0 | K7: =XLOOKUP($A7, INDIRECT("'"&K$1&"'!A:A"), INDIRECT("'"&K$1&"'!B:B"), "") -> 0.83333333
A8: =EQ!A7 -> 0ff8e00eabc873cbfaa0832c3aa0e4a4b03e6f72593a71ecf7e5b2e4d0c82e06 | B8: {=XLOOKUP(A8, Notes!A:A, Notes!B:B, "")} -> 83.25 | C8: =IFERROR(IMAGE(VLOOKUP(A8,DriveImages!A:C,3,FALSE),4,240,520),"") | D8: =IF($A8="","",IF(AND(N($G8)<=Params!$D$2,N($H8)<=Params!$E$2),"Peu actif",IF(AND(N($I8)>=Params!$F$4,N($E8)<=Params!$B$2,N($F8)<=Params!$C$2),"Efficace",IF(AND(N($F8)>=Params!$C$4,OR(N($I8)<=Params!$F$3,N($E8)>=Params!$B$4)),"Bloqué",IF(AND(OR(N($G8)>=Params!$D$4,N($H8)>=Params!$E$4),N($I8)<=Params!$F$3),"Persévérant",IF(AND(N($J8)>=Params!$G$4,OR(N($G8)<=Params!$D$3,N($H8)<=Params!$E$3)),"Sporadique","Intermédiaire")))))) -> Efficace | E8: {=XLOOKUP(A8, EQ!A:A, EQ!B:B, "")} -> 0 | F8: {=XLOOKUP(A8, RED!A:A, RED!B:B, "")} -> 0 | G8: =XLOOKUP(A8, INDIRECT("'"&G$1&"'!A:A"), INDIRECT("'"&G$1&"'!B:B"), "") -> 15 | H8: =XLOOKUP($A8, INDIRECT("'"&H$1&"'!A:A"), INDIRECT("'"&H$1&"'!B:B"), "") -> 1 | I8: =XLOOKUP($A8, INDIRECT("'"&I$1&"'!A:A"), INDIRECT("'"&I$1&"'!B:B"), "") -> 0.86666667 | J8: =XLOOKUP($A8, INDIRECT("'"&J$1&"'!A:A"), INDIRECT("'"&J$1&"'!B:B"), "") -> 0 | K8: =XLOOKUP($A8, INDIRECT("'"&K$1&"'!A:A"), INDIRECT("'"&K$1&"'!B:B"), "") -> 0.82559527
A9: =EQ!A53 -> 7ce2ef889fd3931ddf910c65e58e6b626f658d713486152c54f9f8a0e6f37375 | B9: {=XLOOKUP(A9, Notes!A:A, Notes!B:B, "")} -> 74.78 | C9: =IFERROR(IMAGE(VLOOKUP(A9,DriveImages!A:C,3,FALSE),4,240,520),"") | D9: =IF($A9="","",IF(AND(N($G9)<=Params!$D$2,N($H9)<=Params!$E$2),"Peu actif",IF(AND(N($I9)>=Params!$F$4,N($E9)<=Params!$B$2,N($F9)<=Params!$C$2),"Efficace",IF(AND(N($F9)>=Params!$C$4,OR(N($I9)<=Params!$F$3,N($E9)>=Params!$B$4)),"Bloqué",IF(AND(OR(N($G9)>=Params!$D$4,N($H9)>=Params!$E$4),N($I9)<=Params!$F$3),"Persévérant",IF(AND(N($J9)>=Params!$G$4,OR(N($G9)<=Params!$D$3,N($H9)<=Params!$E$3)),"Sporadique","Intermédiaire")))))) -> Efficace | E9: {=XLOOKUP(A9, EQ!A:A, EQ!B:B, "")} -> 0.125 | F9: {=XLOOKUP(A9, RED!A:A, RED!B:B, "")} -> 0.0625 | G9: =XLOOKUP(A9, INDIRECT("'"&G$1&"'!A:A"), INDIRECT("'"&G$1&"'!B:B"), "") -> 22 | H9: =XLOOKUP($A9, INDIRECT("'"&H$1&"'!A:A"), INDIRECT("'"&H$1&"'!B:B"), "") -> 3 | I9: =XLOOKUP($A9, INDIRECT("'"&I$1&"'!A:A"), INDIRECT("'"&I$1&"'!B:B"), "") -> 0.86363636 | J9: =XLOOKUP($A9, INDIRECT("'"&J$1&"'!A:A"), INDIRECT("'"&J$1&"'!B:B"), "") -> 0.095238095 | K9: =XLOOKUP($A9, INDIRECT("'"&K$1&"'!A:A"), INDIRECT("'"&K$1&"'!B:B"), "") -> 0.81437473
A10: =EQ!A80 -> bee686e3fcc9f3886386d09a5bbd6f4779d852c8bb282b0b6185be70704d9207 | B10: {=XLOOKUP(A10, Notes!A:A, Notes!B:B, "")} -> 85.8 | C10: =IFERROR(IMAGE(VLOOKUP(A10,DriveImages!A:C,3,FALSE),4,240,520),"") | D10: =IF($A10="","",IF(AND(N($G10)<=Params!$D$2,N($H10)<=Params!$E$2),"Peu actif",IF(AND(N($I10)>=Params!$F$4,N($E10)<=Params!$B$2,N($F10)<=Params!$C$2),"Efficace",IF(AND(N($F10)>=Params!$C$4,OR(N($I10)<=Params!$F$3,N($E10)>=Params!$B$4)),"Bloqué",IF(AND(OR(N($G10)>=Params!$D$4,N($H10)>=Params!$E$4),N($I10)<=Params!$F$3),"Persévérant",IF(AND(N($J10)>=Params!$G$4,OR(N($G10)<=Params!$D$3,N($H10)<=Params!$E$3)),"Sporadique","Intermédiaire")))))) -> Efficace | E10: {=XLOOKUP(A10, EQ!A:A, EQ!B:B, "")} -> 0 | F10: {=XLOOKUP(A10, RED!A:A, RED!B:B, "")} -> 0 | G10: =XLOOKUP(A10, INDIRECT("'"&G$1&"'!A:A"), INDIRECT("'"&G$1&"'!B:B"), "") -> 9 | H10: =XLOOKUP($A10, INDIRECT("'"&H$1&"'!A:A"), INDIRECT("'"&H$1&"'!B:B"), "") -> 1 | I10: =XLOOKUP($A10, INDIRECT("'"&I$1&"'!A:A"), INDIRECT("'"&I$1&"'!B:B"), "") -> 0.88888889 | J10: =XLOOKUP($A10, INDIRECT("'"&J$1&"'!A:A"), INDIRECT("'"&J$1&"'!B:B"), "") -> 0 | K10: =XLOOKUP($A10, INDIRECT("'"&K$1&"'!A:A"), INDIRECT("'"&K$1&"'!B:B"), "") -> 0.80886244
A11: =EQ!A91 -> d3f0d126711eb978e948a2cbeb9c2b2b0ffa79541fe717c41575d91f5e21aa61 | B11: {=XLOOKUP(A11, Notes!A:A, Notes!B:B, "")} -> 82.96 | C11: =IFERROR(IMAGE(VLOOKUP(A11,DriveImages!A:C,3,FALSE),4,240,520),"") | D11: =IF($A11="","",IF(AND(N($G11)<=Params!$D$2,N($H11)<=Params!$E$2),"Peu actif",IF(AND(N($I11)>=Params!$F$4,N($E11)<=Params!$B$2,N($F11)<=Params!$C$2),"Efficace",IF(AND(N($F11)>=Params!$C$4,OR(N($I11)<=Params!$F$3,N($E11)>=Params!$B$4)),"Bloqué",IF(AND(OR(N($G11)>=Params!$D$4,N($H11)>=Params!$E$4),N($I11)<=Params!$F$3),"Persévérant",IF(AND(N($J11)>=Params!$G$4,OR(N($G11)<=Params!$D$3,N($H11)<=Params!$E$3)),"Sporadique","Intermédiaire")))))) -> Efficace | E11: {=XLOOKUP(A11, EQ!A:A, EQ!B:B, "")} -> 0 | F11: {=XLOOKUP(A11, RED!A:A, RED!B:B, "")} -> 0 | G11: =XLOOKUP(A11, INDIRECT("'"&G$1&"'!A:A"), INDIRECT("'"&G$1&"'!B:B"), "") -> 18 | H11: =XLOOKUP($A11, INDIRECT("'"&H$1&"'!A:A"), INDIRECT("'"&H$1&"'!B:B"), "") -> 3 | I11: =XLOOKUP($A11, INDIRECT("'"&I$1&"'!A:A"), INDIRECT("'"&I$1&"'!B:B"), "") -> 0.88888889 | J11: =XLOOKUP($A11, INDIRECT("'"&J$1&"'!A:A"), INDIRECT("'"&J$1&"'!B:B"), "") -> 0.11764706 | K11: =XLOOKUP($A11, INDIRECT("'"&K$1&"'!A:A"), INDIRECT("'"&K$1&"'!B:B"), "") -> 0.79307572
A12: =EQ!A100 -> ea47fdcc277117bd663900f36ab09bad41ea1af083ccbc63647b5838e1056ebc | B12: {=XLOOKUP(A12, Notes!A:A, Notes!B:B, "")} -> 83.25 | C12: =IFERROR(IMAGE(VLOOKUP(A12,DriveImages!A:C,3,FALSE),4,240,520),"") | D12: =IF($A12="","",IF(AND(N($G12)<=Params!$D$2,N($H12)<=Params!$E$2),"Peu actif",IF(AND(N($I12)>=Params!$F$4,N($E12)<=Params!$B$2,N($F12)<=Params!$C$2),"Efficace",IF(AND(N($F12)>=Params!$C$4,OR(N($I12)<=Params!$F$3,N($E12)>=Params!$B$4)),"Bloqué",IF(AND(OR(N($G12)>=Params!$D$4,N($H12)>=Params!$E$4),N($I12)<=Params!$F$3),"Persévérant",IF(AND(N($J12)>=Params!$G$4,OR(N($G12)<=Params!$D$3,N($H12)<=Params!$E$3)),"Sporadique","Intermédiaire")))))) -> Efficace | E12: {=XLOOKUP(A12, EQ!A:A, EQ!B:B, "")} -> 0 | F12: {=XLOOKUP(A12, RED!A:A, RED!B:B, "")} -> 0 | G12: =XLOOKUP(A12, INDIRECT("'"&G$1&"'!A:A"), INDIRECT("'"&G$1&"'!B:B"), "") -> 19 | H12: =XLOOKUP($A12, INDIRECT("'"&H$1&"'!A:A"), INDIRECT("'"&H$1&"'!B:B"), "") -> 1 | I12: =XLOOKUP($A12, INDIRECT("'"&I$1&"'!A:A"), INDIRECT("'"&I$1&"'!B:B"), "") -> 0.84210526 | J12: =XLOOKUP($A12, INDIRECT("'"&J$1&"'!A:A"), INDIRECT("'"&J$1&"'!B:B"), "") -> 0 | K12: =XLOOKUP($A12, INDIRECT("'"&K$1&"'!A:A"), INDIRECT("'"&K$1&"'!B:B"), "") -> 0.77161658
A13: =EQ!A23 -> 3d85bc081b5cbae4e23792cd67c1c0fd9af811e86418a20d777c3fbe812ba910 | B13: {=XLOOKUP(A13, Notes!A:A, Notes!B:B, "")} -> 50.06 | C13: =IFERROR(IMAGE(VLOOKUP(A13,DriveImages!A:C,3,FALSE),4,240,520),"") | D13: =IF($A13="","",IF(AND(N($G13)<=Params!$D$2,N($H13)<=Params!$E$2),"Peu actif",IF(AND(N($I13)>=Params!$F$4,N($E13)<=Params!$B$2,N($F13)<=Params!$C$2),"Efficace",IF(AND(N($F13)>=Params!$C$4,OR(N($I13)<=Params!$F$3,N($E13)>=Params!$B$4)),"Bloqué",IF(AND(OR(N($G13)>=Params!$D$4,N($H13)>=Params!$E$4),N($I13)<=Params!$F$3),"Persévérant",IF(AND(N($J13)>=Params!$G$4,OR(N($G13)<=Params!$D$3,N($H13)<=Params!$E$3)),"Sporadique","Intermédiaire")))))) -> Efficace | E13: {=XLOOKUP(A13, EQ!A:A, EQ!B:B, "")} -> 0 | F13: {=XLOOKUP(A13, RED!A:A, RED!B:B, "")} -> 0 | G13: =XLOOKUP(A13, INDIRECT("'"&G$1&"'!A:A"), INDIRECT("'"&G$1&"'!B:B"), "") -> 5 | H13: =XLOOKUP($A13, INDIRECT("'"&H$1&"'!A:A"), INDIRECT("'"&H$1&"'!B:B"), "") -> 2 | I13: =XLOOKUP($A13, INDIRECT("'"&I$1&"'!A:A"), INDIRECT("'"&I$1&"'!B:B"), "") -> 1 | J13: =XLOOKUP($A13, INDIRECT("'"&J$1&"'!A:A"), INDIRECT("'"&J$1&"'!B:B"), "") -> 0.25 | K13: =XLOOKUP($A13, INDIRECT("'"&K$1&"'!A:A"), INDIRECT("'"&K$1&"'!B:B"), "") -> 0.7545456
A14: =EQ!A5 -> 0973288c77f97c9245c444f90526bc6137bc40b48200197fd5bb6134f618f165 | B14: {=XLOOKUP(A14, Notes!A:A, Notes!B:B, "")} -> 49.89 | C14: =IFERROR(IMAGE(VLOOKUP(A14,DriveImages!A:C,3,FALSE),4,240,520),"") | D14: =IF($A14="","",IF(AND(N($G14)<=Params!$D$2,N($H14)<=Params!$E$2),"Peu actif",IF(AND(N($I14)>=Params!$F$4,N($E14)<=Params!$B$2,N($F14)<=Params!$C$2),"Efficace",IF(AND(N($F14)>=Params!$C$4,OR(N($I14)<=Params!$F$3,N($E14)>=Params!$B$4)),"Bloqué",IF(AND(OR(N($G14)>=Params!$D$4,N($H14)>=Params!$E$4),N($I14)<=Params!$F$3),"Persévérant",IF(AND(N($J14)>=Params!$G$4,OR(N($G14)<=Params!$D$3,N($H14)<=Params!$E$3)),"Sporadique","Intermédiaire")))))) -> Efficace | E14: {=XLOOKUP(A14, EQ!A:A, EQ!B:B, "")} -> 0.125 | F14: {=XLOOKUP(A14, RED!A:A, RED!B:B, "")} -> 0.0625 | G14: =XLOOKUP(A14, INDIRECT("'"&G$1&"'!A:A"), INDIRECT("'"&G$1&"'!B:B"), "") -> 16 | H14: =XLOOKUP($A14, INDIRECT("'"&H$1&"'!A:A"), INDIRECT("'"&H$1&"'!B:B"), "") -> 1 | I14: =XLOOKUP($A14, INDIRECT("'"&I$1&"'!A:A"), INDIRECT("'"&I$1&"'!B:B"), "") -> 0.8125 | J14: =XLOOKUP($A14, INDIRECT("'"&J$1&"'!A:A"), INDIRECT("'"&J$1&"'!B:B"), "") -> 0 | K14: =XLOOKUP($A14, INDIRECT("'"&K$1&"'!A:A"), INDIRECT("'"&K$1&"'!B:B"), "") -> 0.74572175
A15: =EQ!A8 -> 109c6e9ad83923fec425f5948621a620bad8efb25d507dbead8bcfa627bc55e6 | B15: {=XLOOKUP(A15, Notes!A:A, Notes!B:B, "")} -> 93.25 | C15: =IFERROR(IMAGE(VLOOKUP(A15,DriveImages!A:C,3,FALSE),4,240,520),"") | D15: =IF($A15="","",IF(AND(N($G15)<=Params!$D$2,N($H15)<=Params!$E$2),"Peu actif",IF(AND(N($I15)>=Params!$F$4,N($E15)<=Params!$B$2,N($F15)<=Params!$C$2),"Efficace",IF(AND(N($F15)>=Params!$C$4,OR(N($I15)<=Params!$F$3,N($E15)>=Params!$B$4)),"Bloqué",IF(AND(OR(N($G15)>=Params!$D$4,N($H15)>=Params!$E$4),N($I15)<=Params!$F$3),"Persévérant",IF(AND(N($J15)>=Params!$G$4,OR(N($G15)<=Params!$D$3,N($H15)<=Params!$E$3)),"Sporadique","Intermédiaire")))))) -> Efficace | E15: {=XLOOKUP(A15, EQ!A:A, EQ!B:B, "")} -> 0 | F15: {=XLOOKUP(A15, RED!A:A, RED!B:B, "")} -> 0 | G15: =XLOOKUP(A15, INDIRECT("'"&G$1&"'!A:A"), INDIRECT("'"&G$1&"'!B:B"), "") -> 18 | H15: =XLOOKUP($A15, INDIRECT("'"&H$1&"'!A:A"), INDIRECT("'"&H$1&"'!B:B"), "") -> 1 | I15: =XLOOKUP($A15, INDIRECT("'"&I$1&"'!A:A"), INDIRECT("'"&I$1&"'!B:B"), "") -> 0.77777778 | J15: =XLOOKUP($A15, INDIRECT("'"&J$1&"'!A:A"), INDIRECT("'"&J$1&"'!B:B"), "") -> 0 | K15: =XLOOKUP($A15, INDIRECT("'"&K$1&"'!A:A"), INDIRECT("'"&K$1&"'!B:B"), "") -> 0.73544978
A16: =EQ!A38 -> 5e8589d4cd67c4b88f84e378d72875ccd07de5c9e20cc666bbf217de9d3567b4 | B16: {=XLOOKUP(A16, Notes!A:A, Notes!B:B, "")} -> 89.45 | C16: =IFERROR(IMAGE(VLOOKUP(A16,DriveImages!A:C,3,FALSE),4,240,520),"") | D16: =IF($A16="","",IF(AND(N($G16)<=Params!$D$2,N($H16)<=Params!$E$2),"Peu actif",IF(AND(N($I16)>=Params!$F$4,N($E16)<=Params!$B$2,N($F16)<=Params!$C$2),"Efficace",IF(AND(N($F16)>=Params!$C$4,OR(N($I16)<=Params!$F$3,N($E16)>=Params!$B$4)),"Bloqué",IF(AND(OR(N($G16)>=Params!$D$4,N($H16)>=Params!$E$4),N($I16)<=Params!$F$3),"Persévérant",IF(AND(N($J16)>=Params!$G$4,OR(N($G16)<=Params!$D$3,N($H16)<=Params!$E$3)),"Sporadique","Intermédiaire")))))) -> Efficace | E16: {=XLOOKUP(A16, EQ!A:A, EQ!B:B, "")} -> 0 | F16: {=XLOOKUP(A16, RED!A:A, RED!B:B, "")} -> 0 | G16: =XLOOKUP(A16, INDIRECT("'"&G$1&"'!A:A"), INDIRECT("'"&G$1&"'!B:B"), "") -> 23 | H16: =XLOOKUP($A16, INDIRECT("'"&H$1&"'!A:A"), INDIRECT("'"&H$1&"'!B:B"), "") -> 3 | I16: =XLOOKUP($A16, INDIRECT("'"&I$1&"'!A:A"), INDIRECT("'"&I$1&"'!B:B"), "") -> 0.86956522 | J16: =XLOOKUP($A16, INDIRECT("'"&J$1&"'!A:A"), INDIRECT("'"&J$1&"'!B:B"), "") -> 0.090909091 | K16: =XLOOKUP($A16, INDIRECT("'"&K$1&"'!A:A"), INDIRECT("'"&K$1&"'!B:B"), "") -> 0.6788357
A17: =EQ!A18 -> 322817f4854f2f71b85db9d2e7c04e4a44c91ea866c689f277a658abc7d22b12 | B17: {=XLOOKUP(A17, Notes!A:A, Notes!B:B, "")} -> 35.44 | C17: =IFERROR(IMAGE(VLOOKUP(A17,DriveImages!A:C,3,FALSE),4,240,520),"") | D17: =IF($A17="","",IF(AND(N($G17)<=Params!$D$2,N($H17)<=Params!$E$2),"Peu actif",IF(AND(N($I17)>=Params!$F$4,N($E17)<=Params!$B$2,N($F17)<=Params!$C$2),"Efficace",IF(AND(N($F17)>=Params!$C$4,OR(N($I17)<=Params!$F$3,N($E17)>=Params!$B$4)),"Bloqué",IF(AND(OR(N($G17)>=Params!$D$4,N($H17)>=Params!$E$4),N($I17)<=Params!$F$3),"Persévérant",IF(AND(N($J17)>=Params!$G$4,OR(N($G17)<=Params!$D$3,N($H17)<=Params!$E$3)),"Sporadique","Intermédiaire")))))) -> Efficace | E17: {=XLOOKUP(A17, EQ!A:A, EQ!B:B, "")} -> 0 | F17: {=XLOOKUP(A17, RED!A:A, RED!B:B, "")} -> 0 | G17: =XLOOKUP($A17, INDIRECT("'"&G$1&"'!A:A"), INDIRECT("'"&G$1&"'!B:B"), "") -> 17 | H17: =XLOOKUP($A17, INDIRECT("'"&H$1&"'!A:A"), INDIRECT("'"&H$1&"'!B:B"), "") -> 3 | I17: =XLOOKUP($A17, INDIRECT("'"&I$1&"'!A:A"), INDIRECT("'"&I$1&"'!B:B"), "") -> 0.94117647 | J17: =XLOOKUP($A17, INDIRECT("'"&J$1&"'!A:A"), INDIRECT("'"&J$1&"'!B:B"), "") -> 0.125 | K17: =XLOOKUP($A17, INDIRECT("'"&K$1&"'!A:A"), INDIRECT("'"&K$1&"'!B:B"), "") -> 0.67851659
A18: =EQ!A12 -> 22d436278c2d2678362e2b3102b5bfa9227eecad30f599801b730e0cc7acd1c6 | B18: {=XLOOKUP(A18, Notes!A:A, Notes!B:B, "")} -> 67.1 | C18: =IFERROR(IMAGE(VLOOKUP(A18,DriveImages!A:C,3,FALSE),4,240,520),"") | D18: =IF($A18="","",IF(AND(N($G18)<=Params!$D$2,N($H18)<=Params!$E$2),"Peu actif",IF(AND(N($I18)>=Params!$F$4,N($E18)<=Params!$B$2,N($F18)<=Params!$C$2),"Efficace",IF(AND(N($F18)>=Params!$C$4,OR(N($I18)<=Params!$F$3,N($E18)>=Params!$B$4)),"Bloqué",IF(AND(OR(N($G18)>=Params!$D$4,N($H18)>=Params!$E$4),N($I18)<=Params!$F$3),"Persévérant",IF(AND(N($J18)>=Params!$G$4,OR(N($G18)<=Params!$D$3,N($H18)<=Params!$E$3)),"Sporadique","Intermédiaire")))))) -> Intermédiaire | E18: {=XLOOKUP(A18, EQ!A:A, EQ!B:B, "")} -> 0.14285714 | F18: {=XLOOKUP(A18, RED!A:A, RED!B:B, "")} -> 0.07142857 | G18: =XLOOKUP(A18, INDIRECT("'"&G$1&"'!A:A"), INDIRECT("'"&G$1&"'!B:B"), "") -> 13 | H18: =XLOOKUP($A18, INDIRECT("'"&H$1&"'!A:A"), INDIRECT("'"&H$1&"'!B:B"), "") -> 5 | I18: =XLOOKUP($A18, INDIRECT("'"&I$1&"'!A:A"), INDIRECT("'"&I$1&"'!B:B"), "") -> 0.76923077 | J18: =XLOOKUP($A18, INDIRECT("'"&J$1&"'!A:A"), INDIRECT("'"&J$1&"'!B:B"), "") -> 0.33333333 | K18: =XLOOKUP($A18, INDIRECT("'"&K$1&"'!A:A"), INDIRECT("'"&K$1&"'!B:B"), "") -> 0.67445054
A19: =EQ!A16 -> 2a9dda5adde456cb4c1ec3735fde1d4591c3b0780ef3d82b8c7fed613382e82f | B19: {=XLOOKUP(A19, Notes!A:A, Notes!B:B, "")} -> 77.44 | C19: =IFERROR(IMAGE(VLOOKUP(A19,DriveImages!A:C,3,FALSE),4,240,520),"") | D19: =IF($A19="","",IF(AND(N($G19)<=Params!$D$2,N($H19)<=Params!$E$2),"Peu actif",IF(AND(N($I19)>=Params!$F$4,N($E19)<=Params!$B$2,N($F19)<=Params!$C$2),"Efficace",IF(AND(N($F19)>=Params!$C$4,OR(N($I19)<=Params!$F$3,N($E19)>=Params!$B$4)),"Bloqué",IF(AND(OR(N($G19)>=Params!$D$4,N($H19)>=Params!$E$4),N($I19)<=Params!$F$3),"Persévérant",IF(AND(N($J19)>=Params!$G$4,OR(N($G19)<=Params!$D$3,N($H19)<=Params!$E$3)),"Sporadique","Intermédiaire")))))) -> Intermédiaire | E19: {=XLOOKUP(A19, EQ!A:A, EQ!B:B, "")} -> 0.375 | F19: {=XLOOKUP(A19, RED!A:A, RED!B:B, "")} -> 0.28125 | G19: =XLOOKUP(A19, INDIRECT("'"&G$1&"'!A:A"), INDIRECT("'"&G$1&"'!B:B"), "") -> 17 | H19: =XLOOKUP($A19, INDIRECT("'"&H$1&"'!A:A"), INDIRECT("'"&H$1&"'!B:B"), "") -> 1 | I19: =XLOOKUP($A19, INDIRECT("'"&I$1&"'!A:A"), INDIRECT("'"&I$1&"'!B:B"), "") -> 0.70588235 | J19: =XLOOKUP($A19, INDIRECT("'"&J$1&"'!A:A"), INDIRECT("'"&J$1&"'!B:B"), "") -> 0 | K19: =XLOOKUP($A19, INDIRECT("'"&K$1&"'!A:A"), INDIRECT("'"&K$1&"'!B:B"), "") -> 0.66666671
A20: =EQ!A103 -> f1adcb66d665ecba393da1490aca01e322bebd658ae2ef41aadee9ec7106def2 | B20: {=XLOOKUP(A20, Notes!A:A, Notes!B:B, "")} -> 93.16 | C20: =IFERROR(IMAGE(VLOOKUP(A20,DriveImages!A:C,3,FALSE),4,240,520),"") | D20: =IF($A20="","",IF(AND(N($G20)<=Params!$D$2,N($H20)<=Params!$E$2),"Peu actif",IF(AND(N($I20)>=Params!$F$4,N($E20)<=Params!$B$2,N($F20)<=Params!$C$2),"Efficace",IF(AND(N($F20)>=Params!$C$4,OR(N($I20)<=Params!$F$3,N($E20)>=Params!$B$4)),"Bloqué",IF(AND(OR(N($G20)>=Params!$D$4,N($H20)>=Params!$E$4),N($I20)<=Params!$F$3),"Persévérant",IF(AND(N($J20)>=Params!$G$4,OR(N($G20)<=Params!$D$3,N($H20)<=Params!$E$3)),"Sporadique","Intermédiaire")))))) -> Efficace | E20: {=XLOOKUP(A20, EQ!A:A, EQ!B:B, "")} -> 0 | F20: {=XLOOKUP(A20, RED!A:A, RED!B:B, "")} -> 0 | G20: =XLOOKUP(A20, INDIRECT("'"&G$1&"'!A:A"), INDIRECT("'"&G$1&"'!B:B"), "") -> 4 | H20: =XLOOKUP($A20, INDIRECT("'"&H$1&"'!A:A"), INDIRECT("'"&H$1&"'!B:B"), "") -> 2 | I20: =XLOOKUP($A20, INDIRECT("'"&I$1&"'!A:A"), INDIRECT("'"&I$1&"'!B:B"), "") -> 0.75 | J20: =XLOOKUP($A20, INDIRECT("'"&J$1&"'!A:A"), INDIRECT("'"&J$1&"'!B:B"), "") -> 0.33333333 | K20: =XLOOKUP($A20, INDIRECT("'"&K$1&"'!A:A"), INDIRECT("'"&K$1&"'!B:B"), "") -> 0.659091
A21: =EQ!A64 -> 950ed53de307960251af3e387e595945da87494d2d2edf58b103f58f4ccfef78 | B21: {=XLOOKUP(A21, Notes!A:A, Notes!B:B, "")} -> 43.28 | C21: =IFERROR(IMAGE(VLOOKUP(A21,DriveImages!A:C,3,FALSE),4,240,520),"") | D21: =IF($A21="","",IF(AND(N($G21)<=Params!$D$2,N($H21)<=Params!$E$2),"Peu actif",IF(AND(N($I21)>=Params!$F$4,N($E21)<=Params!$B$2,N($F21)<=Params!$C$2),"Efficace",IF(AND(N($F21)>=Params!$C$4,OR(N($I21)<=Params!$F$3,N($E21)>=Params!$B$4)),"Bloqué",IF(AND(OR(N($G21)>=Params!$D$4,N($H21)>=Params!$E$4),N($I21)<=Params!$F$3),"Persévérant",IF(AND(N($J21)>=Params!$G$4,OR(N($G21)<=Params!$D$3,N($H21)<=Params!$E$3)),"Sporadique","Intermédiaire")))))) -> Efficace | E21: {=XLOOKUP(A21, EQ!A:A, EQ!B:B, "")} -> 0 | F21: {=XLOOKUP(A21, RED!A:A, RED!B:B, "")} -> 0 | G21: =XLOOKUP(A21, INDIRECT("'"&G$1&"'!A:A"), INDIRECT("'"&G$1&"'!B:B"), "") -> 7 | H21: =XLOOKUP($A21, INDIRECT("'"&H$1&"'!A:A"), INDIRECT("'"&H$1&"'!B:B"), "") -> 3 | I21: =XLOOKUP($A21, INDIRECT("'"&I$1&"'!A:A"), INDIRECT("'"&I$1&"'!B:B"), "") -> 0.85714286 | J21: =XLOOKUP($A21, INDIRECT("'"&J$1&"'!A:A"), INDIRECT("'"&J$1&"'!B:B"), "") -> 0.33333333 | K21: =XLOOKUP($A21, INDIRECT("'"&K$1&"'!A:A"), INDIRECT("'"&K$1&"'!B:B"), "") -> 0.65306129
A22: =EQ!A76 -> b2c90b16a2864cf16993f00192cdb13ee656ac6cd53f745acd473a25224cd05d | B22: {=XLOOKUP(A22, Notes!A:A, Notes!B:B, "")} -> 58.25 | C22: =IFERROR(IMAGE(VLOOKUP(A22,DriveImages!A:C,3,FALSE),4,240,520),"") | D22: =IF($A22="","",IF(AND(N($G22)<=Params!$D$2,N($H22)<=Params!$E$2),"Peu actif",IF(AND(N($I22)>=Params!$F$4,N($E22)<=Params!$B$2,N($F22)<=Params!$C$2),"Efficace",IF(AND(N($F22)>=Params!$C$4,OR(N($I22)<=Params!$F$3,N($E22)>=Params!$B$4)),"Bloqué",IF(AND(OR(N($G22)>=Params!$D$4,N($H22)>=Params!$E$4),N($I22)<=Params!$F$3),"Persévérant",IF(AND(N($J22)>=Params!$G$4,OR(N($G22)<=Params!$D$3,N($H22)<=Params!$E$3)),"Sporadique","Intermédiaire")))))) -> Efficace | E22: {=XLOOKUP(A22, EQ!A:A, EQ!B:B, "")} -> 0.076923077 | F22: {=XLOOKUP(A22, RED!A:A, RED!B:B, "")} -> 0.03846154 | G22: =XLOOKUP(A22, INDIRECT("'"&G$1&"'!A:A"), INDIRECT("'"&G$1&"'!B:B"), "") -> 21 | H22: =XLOOKUP($A22, INDIRECT("'"&H$1&"'!A:A"), INDIRECT("'"&H$1&"'!B:B"), "") -> 6 | I22: =XLOOKUP($A22, INDIRECT("'"&I$1&"'!A:A"), INDIRECT("'"&I$1&"'!B:B"), "") -> 0.76190476 | J22: =XLOOKUP($A22, INDIRECT("'"&J$1&"'!A:A"), INDIRECT("'"&J$1&"'!B:B"), "") -> 0.25 | K22: =XLOOKUP($A22, INDIRECT("'"&K$1&"'!A:A"), INDIRECT("'"&K$1&"'!B:B"), "") -> 0.64557824
A23: =EQ!A72 -> ad1624c5c3a02a3a3b3dcb044b912998b64ca2e7cd54abe79476f86a41a3234b | B23: {=XLOOKUP(A23, Notes!A:A, Notes!B:B, "")} -> 55.71 | C23: =IFERROR(IMAGE(VLOOKUP(A23,DriveImages!A:C,3,FALSE),4,240,520),"") | D23: =IF($A23="","",IF(AND(N($G23)<=Params!$D$2,N($H23)<=Params!$E$2),"Peu actif",IF(AND(N($I23)>=Params!$F$4,N($E23)<=Params!$B$2,N($F23)<=Params!$C$2),"Efficace",IF(AND(N($F23)>=Params!$C$4,OR(N($I23)<=Params!$F$3,N($E23)>=Params!$B$4)),"Bloqué",IF(AND(OR(N($G23)>=Params!$D$4,N($H23)>=Params!$E$4),N($I23)<=Params!$F$3),"Persévérant",IF(AND(N($J23)>=Params!$G$4,OR(N($G23)<=Params!$D$3,N($H23)<=Params!$E$3)),"Sporadique","Intermédiaire")))))) -> Efficace | E23: {=XLOOKUP(A23, EQ!A:A, EQ!B:B, "")} -> 0 | F23: {=XLOOKUP(A23, RED!A:A, RED!B:B, "")} -> 0 | G23: =XLOOKUP(A23, INDIRECT("'"&G$1&"'!A:A"), INDIRECT("'"&G$1&"'!B:B"), "") -> 7 | H23: =XLOOKUP($A23, INDIRECT("'"&H$1&"'!A:A"), INDIRECT("'"&H$1&"'!B:B"), "") -> 3 | I23: =XLOOKUP($A23, INDIRECT("'"&I$1&"'!A:A"), INDIRECT("'"&I$1&"'!B:B"), "") -> 0.85714286 | J23: =XLOOKUP($A23, INDIRECT("'"&J$1&"'!A:A"), INDIRECT("'"&J$1&"'!B:B"), "") -> 0.33333333 | K23: =XLOOKUP($A23, INDIRECT("'"&K$1&"'!A:A"), INDIRECT("'"&K$1&"'!B:B"), "") -> 0.63428571
A24: =EQ!A43 -> 6b6e8c7036722d03a34126403e7106d3512a2d4b72bcd8bde651614e8ad42d7b | B24: {=XLOOKUP(A24, Notes!A:A, Notes!B:B, "")} -> 56.75 | C24: =IFERROR(IMAGE(VLOOKUP(A24,DriveImages!A:C,3,FALSE),4,240,520),"") | D24: =IF($A24="","",IF(AND(N($G24)<=Params!$D$2,N($H24)<=Params!$E$2),"Peu actif",IF(AND(N($I24)>=Params!$F$4,N($E24)<=Params!$B$2,N($F24)<=Params!$C$2),"Efficace",IF(AND(N($F24)>=Params!$C$4,OR(N($I24)<=Params!$F$3,N($E24)>=Params!$B$4)),"Bloqué",IF(AND(OR(N($G24)>=Params!$D$4,N($H24)>=Params!$E$4),N($I24)<=Params!$F$3),"Persévérant",IF(AND(N($J24)>=Params!$G$4,OR(N($G24)<=Params!$D$3,N($H24)<=Params!$E$3)),"Sporadique","Intermédiaire")))))) -> Sporadique | E24: {=XLOOKUP(A24, EQ!A:A, EQ!B:B, "")} -> 0.25 | F24: {=XLOOKUP(A24, RED!A:A, RED!B:B, "")} -> 0.125 | G24: =XLOOKUP(A24, INDIRECT("'"&G$1&"'!A:A"), INDIRECT("'"&G$1&"'!B:B"), "") -> 6 | H24: =XLOOKUP($A24, INDIRECT("'"&H$1&"'!A:A"), INDIRECT("'"&H$1&"'!B:B"), "") -> 2 | I24: =XLOOKUP($A24, INDIRECT("'"&I$1&"'!A:A"), INDIRECT("'"&I$1&"'!B:B"), "") -> 0.66666667 | J24: =XLOOKUP($A24, INDIRECT("'"&J$1&"'!A:A"), INDIRECT("'"&J$1&"'!B:B"), "") -> 0.2 | K24: =XLOOKUP($A24, INDIRECT("'"&K$1&"'!A:A"), INDIRECT("'"&K$1&"'!B:B"), "") -> 0.63095233
A25: =EQ!A98 -> e3d00c0bcfea6e4a68c5c4842d0bedac5e761cfa5be62ec60aae839f44a7f555 | B25: {=XLOOKUP(A25, Notes!A:A, Notes!B:B, "")} -> 62.59 | C25: =IFERROR(IMAGE(VLOOKUP(A25,DriveImages!A:C,3,FALSE),4,240,520),"") | D25: =IF($A25="","",IF(AND(N($G25)<=Params!$D$2,N($H25)<=Params!$E$2),"Peu actif",IF(AND(N($I25)>=Params!$F$4,N($E25)<=Params!$B$2,N($F25)<=Params!$C$2),"Efficace",IF(AND(N($F25)>=Params!$C$4,OR(N($I25)<=Params!$F$3,N($E25)>=Params!$B$4)),"Bloqué",IF(AND(OR(N($G25)>=Params!$D$4,N($H25)>=Params!$E$4),N($I25)<=Params!$F$3),"Persévérant",IF(AND(N($J25)>=Params!$G$4,OR(N($G25)<=Params!$D$3,N($H25)<=Params!$E$3)),"Sporadique","Intermédiaire")))))) -> Efficace | E25: {=XLOOKUP(A25, EQ!A:A, EQ!B:B, "")} -> 0 | F25: {=XLOOKUP(A25, RED!A:A, RED!B:B, "")} -> 0 | G25: =XLOOKUP(A25, INDIRECT("'"&G$1&"'!A:A"), INDIRECT("'"&G$1&"'!B:B"), "") -> 12 | H25: =XLOOKUP($A25, INDIRECT("'"&H$1&"'!A:A"), INDIRECT("'"&H$1&"'!B:B"), "") -> 3 | I25: =XLOOKUP($A25, INDIRECT("'"&I$1&"'!A:A"), INDIRECT("'"&I$1&"'!B:B"), "") -> 0.91666667 | J25: =XLOOKUP($A25, INDIRECT("'"&J$1&"'!A:A"), INDIRECT("'"&J$1&"'!B:B"), "") -> 0.18181818 | K25: =XLOOKUP($A25, INDIRECT("'"&K$1&"'!A:A"), INDIRECT("'"&K$1&"'!B:B"), "") -> 0.628788
A26: =EQ!A104 -> f421319a6d338f4c75d9ce493c2ab35aa31da5115a045fb9149446903d5f1141 | B26: {=XLOOKUP(A26, Notes!A:A, Notes!B:B, "")} -> 72.98 | C26: =IFERROR(IMAGE(VLOOKUP(A26,DriveImages!A:C,3,FALSE),4,240,520),"") | D26: =IF($A26="","",IF(AND(N($G26)<=Params!$D$2,N($H26)<=Params!$E$2),"Peu actif",IF(AND(N($I26)>=Params!$F$4,N($E26)<=Params!$B$2,N($F26)<=Params!$C$2),"Efficace",IF(AND(N($F26)>=Params!$C$4,OR(N($I26)<=Params!$F$3,N($E26)>=Params!$B$4)),"Bloqué",IF(AND(OR(N($G26)>=Params!$D$4,N($H26)>=Params!$E$4),N($I26)<=Params!$F$3),"Persévérant",IF(AND(N($J26)>=Params!$G$4,OR(N($G26)<=Params!$D$3,N($H26)<=Params!$E$3)),"Sporadique","Intermédiaire")))))) -> Intermédiaire | E26: {=XLOOKUP(A26, EQ!A:A, EQ!B:B, "")} -> 0.4 | F26: {=XLOOKUP(A26, RED!A:A, RED!B:B, "")} -> 0.26666667 | G26: =XLOOKUP(A26, INDIRECT("'"&G$1&"'!A:A"), INDIRECT("'"&G$1&"'!B:B"), "") -> 14 | H26: =XLOOKUP($A26, INDIRECT("'"&H$1&"'!A:A"), INDIRECT("'"&H$1&"'!B:B"), "") -> 2 | I26: =XLOOKUP($A26, INDIRECT("'"&I$1&"'!A:A"), INDIRECT("'"&I$1&"'!B:B"), "") -> 0.64285714 | J26: =XLOOKUP($A26, INDIRECT("'"&J$1&"'!A:A"), INDIRECT("'"&J$1&"'!B:B"), "") -> 0.076923077 | K26: =XLOOKUP($A26, INDIRECT("'"&K$1&"'!A:A"), INDIRECT("'"&K$1&"'!B:B"), "") -> 0.622449
A27: =EQ!A21 -> 349cf265b30475874348c4e1b4520dc39d2668fe73f446cde11ed834aef06f6d | B27: {=XLOOKUP(A27, Notes!A:A, Notes!B:B, "")} -> 69.17 | C27: =IFERROR(IMAGE(VLOOKUP(A27,DriveImages!A:C,3,FALSE),4,240,520),"") | D27: =IF($A27="","",IF(AND(N($G27)<=Params!$D$2,N($H27)<=Params!$E$2),"Peu actif",IF(AND(N($I27)>=Params!$F$4,N($E27)<=Params!$B$2,N($F27)<=Params!$C$2),"Efficace",IF(AND(N($F27)>=Params!$C$4,OR(N($I27)<=Params!$F$3,N($E27)>=Params!$B$4)),"Bloqué",IF(AND(OR(N($G27)>=Params!$D$4,N($H27)>=Params!$E$4),N($I27)<=Params!$F$3),"Persévérant",IF(AND(N($J27)>=Params!$G$4,OR(N($G27)<=Params!$D$3,N($H27)<=Params!$E$3)),"Sporadique","Intermédiaire")))))) -> Intermédiaire | E27: {=XLOOKUP(A27, EQ!A:A, EQ!B:B, "")} -> 0.2 | F27: {=XLOOKUP(A27, RED!A:A, RED!B:B, "")} -> 0.1 | G27: =XLOOKUP(A27, INDIRECT("'"&G$1&"'!A:A"), INDIRECT("'"&G$1&"'!B:B"), "") -> 9 | H27: =XLOOKUP($A27, INDIRECT("'"&H$1&"'!A:A"), INDIRECT("'"&H$1&"'!B:B"), "") -> 2 | I27: =XLOOKUP($A27, INDIRECT("'"&I$1&"'!A:A"), INDIRECT("'"&I$1&"'!B:B"), "") -> 0.66666667 | J27: =XLOOKUP($A27, INDIRECT("'"&J$1&"'!A:A"), INDIRECT("'"&J$1&"'!B:B"), "") -> 0.125 | K27: =XLOOKUP($A27, INDIRECT("'"&K$1&"'!A:A"), INDIRECT("'"&K$1&"'!B:B"), "") -> 0.59788367
A28: =EQ!A25 -> 40c1d250c97702986524dae1c4014dbac4abddab4fbfd395737f4e2fe64a247d | B28: {=XLOOKUP(A28, Notes!A:A, Notes!B:B, "")} -> 88.53 | C28: =IFERROR(IMAGE(VLOOKUP(A28,DriveImages!A:C,3,FALSE),4,240,520),"") | D28: =IF($A28="","",IF(AND(N($G28)<=Params!$D$2,N($H28)<=Params!$E$2),"Peu actif",IF(AND(N($I28)>=Params!$F$4,N($E28)<=Params!$B$2,N($F28)<=Params!$C$2),"Efficace",IF(AND(N($F28)>=Params!$C$4,OR(N($I28)<=Params!$F$3,N($E28)>=Params!$B$4)),"Bloqué",IF(AND(OR(N($G28)>=Params!$D$4,N($H28)>=Params!$E$4),N($I28)<=Params!$F$3),"Persévérant",IF(AND(N($J28)>=Params!$G$4,OR(N($G28)<=Params!$D$3,N($H28)<=Params!$E$3)),"Sporadique","Intermédiaire")))))) -> Intermédiaire | E28: {=XLOOKUP(A28, EQ!A:A, EQ!B:B, "")} -> 0.2 | F28: {=XLOOKUP(A28, RED!A:A, RED!B:B, "")} -> 0.1375 | G28: =XLOOKUP(A28, INDIRECT("'"&G$1&"'!A:A"), INDIRECT("'"&G$1&"'!B:B"), "") -> 30 | H28: =XLOOKUP($A28, INDIRECT("'"&H$1&"'!A:A"), INDIRECT("'"&H$1&"'!B:B"), "") -> 2 | I28: =XLOOKUP($A28, INDIRECT("'"&I$1&"'!A:A"), INDIRECT("'"&I$1&"'!B:B"), "") -> 0.63333333 | J28: =XLOOKUP($A28, INDIRECT("'"&J$1&"'!A:A"), INDIRECT("'"&J$1&"'!B:B"), "") -> 0.034482759 | K28: =XLOOKUP($A28, INDIRECT("'"&K$1&"'!A:A"), INDIRECT("'"&K$1&"'!B:B"), "") -> 0.561137
A29: =EQ!A102 -> effa5fafd71a87510e477792561dc4c6a0d7a624d93f5ee78db77ac7c2a41d63 | B29: {=XLOOKUP(A29, Notes!A:A, Notes!B:B, "")} -> 63.66 | C29: =IFERROR(IMAGE(VLOOKUP(A29,DriveImages!A:C,3,FALSE),4,240,520),"") | D29: =IF($A29="","",IF(AND(N($G29)<=Params!$D$2,N($H29)<=Params!$E$2),"Peu actif",IF(AND(N($I29)>=Params!$F$4,N($E29)<=Params!$B$2,N($F29)<=Params!$C$2),"Efficace",IF(AND(N($F29)>=Params!$C$4,OR(N($I29)<=Params!$F$3,N($E29)>=Params!$B$4)),"Bloqué",IF(AND(OR(N($G29)>=Params!$D$4,N($H29)>=Params!$E$4),N($I29)<=Params!$F$3),"Persévérant",IF(AND(N($J29)>=Params!$G$4,OR(N($G29)<=Params!$D$3,N($H29)<=Params!$E$3)),"Sporadique","Intermédiaire")))))) -> Intermédiaire | E29: {=XLOOKUP(A29, EQ!A:A, EQ!B:B, "")} -> 0.21428571 | F29: {=XLOOKUP(A29, RED!A:A, RED!B:B, "")} -> 0.16190476 | G29: =XLOOKUP(A29, INDIRECT("'"&G$1&"'!A:A"), INDIRECT("'"&G$1&"'!B:B"), "") -> 33 | H29: =XLOOKUP($A29, INDIRECT("'"&H$1&"'!A:A"), INDIRECT("'"&H$1&"'!B:B"), "") -> 2 | I29: =XLOOKUP($A29, INDIRECT("'"&I$1&"'!A:A"), INDIRECT("'"&I$1&"'!B:B"), "") -> 0.6969697 | J29: =XLOOKUP($A29, INDIRECT("'"&J$1&"'!A:A"), INDIRECT("'"&J$1&"'!B:B"), "") -> 0.03125 | K29: =XLOOKUP($A29, INDIRECT("'"&K$1&"'!A:A"), INDIRECT("'"&K$1&"'!B:B"), "") -> 0.55661003
A30: =EQ!A59 -> 8c496c831c776415f7491e6de8457bb88c62eefeff270c8e0dbec39b78b9413d | B30: {=XLOOKUP(A30, Notes!A:A, Notes!B:B, "")} -> 72.99 | C30: =IFERROR(IMAGE(VLOOKUP(A30,DriveImages!A:C,3,FALSE),4,240,520),"") | D30: =IF($A30="","",IF(AND(N($G30)<=Params!$D$2,N($H30)<=Params!$E$2),"Peu actif",IF(AND(N($I30)>=Params!$F$4,N($E30)<=Params!$B$2,N($F30)<=Params!$C$2),"Efficace",IF(AND(N($F30)>=Params!$C$4,OR(N($I30)<=Params!$F$3,N($E30)>=Params!$B$4)),"Bloqué",IF(AND(OR(N($G30)>=Params!$D$4,N($H30)>=Params!$E$4),N($I30)<=Params!$F$3),"Persévérant",IF(AND(N($J30)>=Params!$G$4,OR(N($G30)<=Params!$D$3,N($H30)<=Params!$E$3)),"Sporadique","Intermédiaire")))))) -> Sporadique | E30: {=XLOOKUP(A30, EQ!A:A, EQ!B:B, "")} -> 0 | F30: {=XLOOKUP(A30, RED!A:A, RED!B:B, "")} -> 0 | G30: =XLOOKUP(A30, INDIRECT("'"&G$1&"'!A:A"), INDIRECT("'"&G$1&"'!B:B"), "") -> 10 | H30: =XLOOKUP($A30, INDIRECT("'"&H$1&"'!A:A"), INDIRECT("'"&H$1&"'!B:B"), "") -> 3 | I30: =XLOOKUP($A30, INDIRECT("'"&I$1&"'!A:A"), INDIRECT("'"&I$1&"'!B:B"), "") -> 0.6 | J30: =XLOOKUP($A30, INDIRECT("'"&J$1&"'!A:A"), INDIRECT("'"&J$1&"'!B:B"), "") -> 0.22222222 | K30: =XLOOKUP($A30, INDIRECT("'"&K$1&"'!A:A"), INDIRECT("'"&K$1&"'!B:B"), "") -> 0.5466667
A31: =EQ!A41 -> 6a91389bf293538f8bfd1747ffc38730176f9e72e8ed7004fabc8cd25e69df6b | B31: {=XLOOKUP(A31, Notes!A:A, Notes!B:B, "")} -> 42.53 | C31: =IFERROR(IMAGE(VLOOKUP(A31,DriveImages!A:C,3,FALSE),4,240,520),"") | D31: =IF($A31="","",IF(AND(N($G31)<=Params!$D$2,N($H31)<=Params!$E$2),"Peu actif",IF(AND(N($I31)>=Params!$F$4,N($E31)<=Params!$B$2,N($F31)<=Params!$C$2),"Efficace",IF(AND(N($F31)>=Params!$C$4,OR(N($I31)<=Params!$F$3,N($E31)>=Params!$B$4)),"Bloqué",IF(AND(OR(N($G31)>=Params!$D$4,N($H31)>=Params!$E$4),N($I31)<=Params!$F$3),"Persévérant",IF(AND(N($J31)>=Params!$G$4,OR(N($G31)<=Params!$D$3,N($H31)<=Params!$E$3)),"Sporadique","Intermédiaire")))))) -> Efficace | E31: {=XLOOKUP(A31, EQ!A:A, EQ!B:B, "")} -> 0 | F31: {=XLOOKUP(A31, RED!A:A, RED!B:B, "")} -> 0 | G31: =XLOOKUP(A31, INDIRECT("'"&G$1&"'!A:A"), INDIRECT("'"&G$1&"'!B:B"), "") -> 12 | H31: =XLOOKUP($A31, INDIRECT("'"&H$1&"'!A:A"), INDIRECT("'"&H$1&"'!B:B"), "") -> 2 | I31: =XLOOKUP($A31, INDIRECT("'"&I$1&"'!A:A"), INDIRECT("'"&I$1&"'!B:B"), "") -> 1 | J31: =XLOOKUP($A31, INDIRECT("'"&J$1&"'!A:A"), INDIRECT("'"&J$1&"'!B:B"), "") -> 0.090909091 | K31: =XLOOKUP($A31, INDIRECT("'"&K$1&"'!A:A"), INDIRECT("'"&K$1&"'!B:B"), "") -> 0.5345455
A32: =EQ!A50 -> 76b0bf253c0d17b6f275cc641729eda42ebed851893da32c132515023ab1e4e1 | B32: {=XLOOKUP(A32, Notes!A:A, Notes!B:B, "")} -> 62.06 | C32: =IFERROR(IMAGE(VLOOKUP(A32,DriveImages!A:C,3,FALSE),4,240,520),"") | D32: =IF($A32="","",IF(AND(N($G32)<=Params!$D$2,N($H32)<=Params!$E$2),"Peu actif",IF(AND(N($I32)>=Params!$F$4,N($E32)<=Params!$B$2,N($F32)<=Params!$C$2),"Efficace",IF(AND(N($F32)>=Params!$C$4,OR(N($I32)<=Params!$F$3,N($E32)>=Params!$B$4)),"Bloqué",IF(AND(OR(N($G32)>=Params!$D$4,N($H32)>=Params!$E$4),N($I32)<=Params!$F$3),"Persévérant",IF(AND(N($J32)>=Params!$G$4,OR(N($G32)<=Params!$D$3,N($H32)<=Params!$E$3)),"Sporadique","Intermédiaire")))))) -> Intermédiaire | E32: {=XLOOKUP(A32, EQ!A:A, EQ!B:B, "")} -> 0.33333333 | F32: {=XLOOKUP(A32, RED!A:A, RED!B:B, "")} -> 0.22222222 | G32: =XLOOKUP(A32, INDIRECT("'"&G$1&"'!A:A"), INDIRECT("'"&G$1&"'!B:B"), "") -> 11 | H32: =XLOOKUP($A32, INDIRECT("'"&H$1&"'!A:A"), INDIRECT("'"&H$1&"'!B:B"), "") -> 2 | I32: =XLOOKUP($A32, INDIRECT("'"&I$1&"'!A:A"), INDIRECT("'"&I$1&"'!B:B"), "") -> 0.54545455 | J32: =XLOOKUP($A32, INDIRECT("'"&J$1&"'!A:A"), INDIRECT("'"&J$1&"'!B:B"), "") -> 0.1 | K32: =XLOOKUP($A32, INDIRECT("'"&K$1&"'!A:A"), INDIRECT("'"&K$1&"'!B:B"), "") -> 0.53409091
A33: =EQ!A63 -> 93a7aef5296e288f3a39f8c1c0dcb8935c9657f5c87378408e5d1910444e7c70 | B33: {=XLOOKUP(A33, Notes!A:A, Notes!B:B, "")} -> 61.57 | C33: =IFERROR(IMAGE(VLOOKUP(A33,DriveImages!A:C,3,FALSE),4,240,520),"") | D33: =IF($A33="","",IF(AND(N($G33)<=Params!$D$2,N($H33)<=Params!$E$2),"Peu actif",IF(AND(N($I33)>=Params!$F$4,N($E33)<=Params!$B$2,N($F33)<=Params!$C$2),"Efficace",IF(AND(N($F33)>=Params!$C$4,OR(N($I33)<=Params!$F$3,N($E33)>=Params!$B$4)),"Bloqué",IF(AND(OR(N($G33)>=Params!$D$4,N($H33)>=Params!$E$4),N($I33)<=Params!$F$3),"Persévérant",IF(AND(N($J33)>=Params!$G$4,OR(N($G33)<=Params!$D$3,N($H33)<=Params!$E$3)),"Sporadique","Intermédiaire")))))) -> Intermédiaire | E33: {=XLOOKUP(A33, EQ!A:A, EQ!B:B, "")} -> 0.58333333 | F33: {=XLOOKUP(A33, RED!A:A, RED!B:B, "")} -> 0.51041667 | G33: =XLOOKUP(A33, INDIRECT("'"&G$1&"'!A:A"), INDIRECT("'"&G$1&"'!B:B"), "") -> 20 | H33: =XLOOKUP($A33, INDIRECT("'"&H$1&"'!A:A"), INDIRECT("'"&H$1&"'!B:B"), "") -> 4 | I33: =XLOOKUP($A33, INDIRECT("'"&I$1&"'!A:A"), INDIRECT("'"&I$1&"'!B:B"), "") -> 0.55 | J33: =XLOOKUP($A33, INDIRECT("'"&J$1&"'!A:A"), INDIRECT("'"&J$1&"'!B:B"), "") -> 0.15789474 | K33: =XLOOKUP($A33, INDIRECT("'"&K$1&"'!A:A"), INDIRECT("'"&K$1&"'!B:B"), "") -> 0.53333335
A34: =EQ!A11 -> 155464e7a35faffd6b3b4f2e6b757098204e8a24221641b58ee8156acfd2e1fc | B34: {=XLOOKUP(A34, Notes!A:A, Notes!B:B, "")} -> 77.78 | C34: =IFERROR(IMAGE(VLOOKUP(A34,DriveImages!A:C,3,FALSE),4,240,520),"") | D34: =IF($A34="","",IF(AND(N($G34)<=Params!$D$2,N($H34)<=Params!$E$2),"Peu actif",IF(AND(N($I34)>=Params!$F$4,N($E34)<=Params!$B$2,N($F34)<=Params!$C$2),"Efficace",IF(AND(N($F34)>=Params!$C$4,OR(N($I34)<=Params!$F$3,N($E34)>=Params!$B$4)),"Bloqué",IF(AND(OR(N($G34)>=Params!$D$4,N($H34)>=Params!$E$4),N($I34)<=Params!$F$3),"Persévérant",IF(AND(N($J34)>=Params!$G$4,OR(N($G34)<=Params!$D$3,N($H34)<=Params!$E$3)),"Sporadique","Intermédiaire")))))) -> Intermédiaire | E34: {=XLOOKUP(A34, EQ!A:A, EQ!B:B, "")} -> 0.25 | F34: {=XLOOKUP(A34, RED!A:A, RED!B:B, "")} -> 0.16666667 | G34: =XLOOKUP(A34, INDIRECT("'"&G$1&"'!A:A"), INDIRECT("'"&G$1&"'!B:B"), "") -> 10 | H34: =XLOOKUP($A34, INDIRECT("'"&H$1&"'!A:A"), INDIRECT("'"&H$1&"'!B:B"), "") -> 1 | I34: =XLOOKUP($A34, INDIRECT("'"&I$1&"'!A:A"), INDIRECT("'"&I$1&"'!B:B"), "") -> 0.6 | J34: =XLOOKUP($A34, INDIRECT("'"&J$1&"'!A:A"), INDIRECT("'"&J$1&"'!B:B"), "") -> 0 | K34: =XLOOKUP($A34, INDIRECT("'"&K$1&"'!A:A"), INDIRECT("'"&K$1&"'!B:B"), "") -> 0.5251552
A35: =EQ!A97 -> de14d69ecb05cea275dcf6a7cb707626315f3e81931958d7d7b15131368cf4d6 | B35: {=XLOOKUP(A35, Notes!A:A, Notes!B:B, "")} -> 57.33 | C35: =IFERROR(IMAGE(VLOOKUP(A35,DriveImages!A:C,3,FALSE),4,240,520),"") | D35: =IF($A35="","",IF(AND(N($G35)<=Params!$D$2,N($H35)<=Params!$E$2),"Peu actif",IF(AND(N($I35)>=Params!$F$4,N($E35)<=Params!$B$2,N($F35)<=Params!$C$2),"Efficace",IF(AND(N($F35)>=Params!$C$4,OR(N($I35)<=Params!$F$3,N($E35)>=Params!$B$4)),"Bloqué",IF(AND(OR(N($G35)>=Params!$D$4,N($H35)>=Params!$E$4),N($I35)<=Params!$F$3),"Persévérant",IF(AND(N($J35)>=Params!$G$4,OR(N($G35)<=Params!$D$3,N($H35)<=Params!$E$3)),"Sporadique","Intermédiaire")))))) -> Sporadique | E35: {=XLOOKUP(A35, EQ!A:A, EQ!B:B, "")} -> 0 | F35: {=XLOOKUP(A35, RED!A:A, RED!B:B, "")} -> 0 | G35: =XLOOKUP(A35, INDIRECT("'"&G$1&"'!A:A"), INDIRECT("'"&G$1&"'!B:B"), "") -> 9 | H35: =XLOOKUP($A35, INDIRECT("'"&H$1&"'!A:A"), INDIRECT("'"&H$1&"'!B:B"), "") -> 3 | I35: =XLOOKUP($A35, INDIRECT("'"&I$1&"'!A:A"), INDIRECT("'"&I$1&"'!B:B"), "") -> 0.55555556 | J35: =XLOOKUP($A35, INDIRECT("'"&J$1&"'!A:A"), INDIRECT("'"&J$1&"'!B:B"), "") -> 0.25 | K35: =XLOOKUP($A35, INDIRECT("'"&K$1&"'!A:A"), INDIRECT("'"&K$1&"'!B:B"), "") -> 0.50448578
A36: =EQ!A61 -> 9181e670a018653889d5263448f199379588274b90c51348445093423b56396b | B36: {=XLOOKUP(A36, Notes!A:A, Notes!B:B, "")} -> 62.16 | C36: =IFERROR(IMAGE(VLOOKUP(A36,DriveImages!A:C,3,FALSE),4,240,520),"") | D36: =IF($A36="","",IF(AND(N($G36)<=Params!$D$2,N($H36)<=Params!$E$2),"Peu actif",IF(AND(N($I36)>=Params!$F$4,N($E36)<=Params!$B$2,N($F36)<=Params!$C$2),"Efficace",IF(AND(N($F36)>=Params!$C$4,OR(N($I36)<=Params!$F$3,N($E36)>=Params!$B$4)),"Bloqué",IF(AND(OR(N($G36)>=Params!$D$4,N($H36)>=Params!$E$4),N($I36)<=Params!$F$3),"Persévérant",IF(AND(N($J36)>=Params!$G$4,OR(N($G36)<=Params!$D$3,N($H36)<=Params!$E$3)),"Sporadique","Intermédiaire")))))) -> Intermédiaire | E36: {=XLOOKUP(A36, EQ!A:A, EQ!B:B, "")} -> 0.20833333 | F36: {=XLOOKUP(A36, RED!A:A, RED!B:B, "")} -> 0.13541667 | G36: =XLOOKUP(A36, INDIRECT("'"&G$1&"'!A:A"), INDIRECT("'"&G$1&"'!B:B"), "") -> 31 | H36: =XLOOKUP($A36, INDIRECT("'"&H$1&"'!A:A"), INDIRECT("'"&H$1&"'!B:B"), "") -> 1 | I36: =XLOOKUP($A36, INDIRECT("'"&I$1&"'!A:A"), INDIRECT("'"&I$1&"'!B:B"), "") -> 0.61290323 | J36: =XLOOKUP($A36, INDIRECT("'"&J$1&"'!A:A"), INDIRECT("'"&J$1&"'!B:B"), "") -> 0 | K36: =XLOOKUP($A36, INDIRECT("'"&K$1&"'!A:A"), INDIRECT("'"&K$1&"'!B:B"), "") -> 0.50194326
A37: =EQ!A88 -> cef23c3f251969f778435219b38afa60f2e41b3927e82fa6d43de8c59f93f883 | B37: {=XLOOKUP(A37, Notes!A:A, Notes!B:B, "")} -> 71.09 | C37: =IFERROR(IMAGE(VLOOKUP(A37,DriveImages!A:C,3,FALSE),4,240,520),"") | D37: =IF($A37="","",IF(AND(N($G37)<=Params!$D$2,N($H37)<=Params!$E$2),"Peu actif",IF(AND(N($I37)>=Params!$F$4,N($E37)<=Params!$B$2,N($F37)<=Params!$C$2),"Efficace",IF(AND(N($F37)>=Params!$C$4,OR(N($I37)<=Params!$F$3,N($E37)>=Params!$B$4)),"Bloqué",IF(AND(OR(N($G37)>=Params!$D$4,N($H37)>=Params!$E$4),N($I37)<=Params!$F$3),"Persévérant",IF(AND(N($J37)>=Params!$G$4,OR(N($G37)<=Params!$D$3,N($H37)<=Params!$E$3)),"Sporadique","Intermédiaire")))))) -> Intermédiaire | E37: {=XLOOKUP(A37, EQ!A:A, EQ!B:B, "")} -> 0.30434783 | F37: {=XLOOKUP(A37, RED!A:A, RED!B:B, "")} -> 0.2173913 | G37: =XLOOKUP(A37, INDIRECT("'"&G$1&"'!A:A"), INDIRECT("'"&G$1&"'!B:B"), "") -> 36 | H37: =XLOOKUP($A37, INDIRECT("'"&H$1&"'!A:A"), INDIRECT("'"&H$1&"'!B:B"), "") -> 2 | I37: =XLOOKUP($A37, INDIRECT("'"&I$1&"'!A:A"), INDIRECT("'"&I$1&"'!B:B"), "") -> 0.61111111 | J37: =XLOOKUP($A37, INDIRECT("'"&J$1&"'!A:A"), INDIRECT("'"&J$1&"'!B:B"), "") -> 0.028571429 | K37: =XLOOKUP($A37, INDIRECT("'"&K$1&"'!A:A"), INDIRECT("'"&K$1&"'!B:B"), "") -> 0.49802858
A38: =EQ!A57 -> 88faa9b4e525ea83f6efab60ae88469da5222f0b0f52c16c3af4e4763baa1daf | B38: {=XLOOKUP(A38, Notes!A:A, Notes!B:B, "")} -> 59.75 | C38: =IFERROR(IMAGE(VLOOKUP(A38,DriveImages!A:C,3,FALSE),4,240,520),"") | D38: =IF($A38="","",IF(AND(N($G38)<=Params!$D$2,N($H38)<=Params!$E$2),"Peu actif",IF(AND(N($I38)>=Params!$F$4,N($E38)<=Params!$B$2,N($F38)<=Params!$C$2),"Efficace",IF(AND(N($F38)>=Params!$C$4,OR(N($I38)<=Params!$F$3,N($E38)>=Params!$B$4)),"Bloqué",IF(AND(OR(N($G38)>=Params!$D$4,N($H38)>=Params!$E$4),N($I38)<=Params!$F$3),"Persévérant",IF(AND(N($J38)>=Params!$G$4,OR(N($G38)<=Params!$D$3,N($H38)<=Params!$E$3)),"Sporadique","Intermédiaire")))))) -> Intermédiaire | E38: {=XLOOKUP(A38, EQ!A:A, EQ!B:B, "")} -> 0.16666667 | F38: {=XLOOKUP(A38, RED!A:A, RED!B:B, "")} -> 0.11111111 | G38: =XLOOKUP(A38, INDIRECT("'"&G$1&"'!A:A"), INDIRECT("'"&G$1&"'!B:B"), "") -> 14 | H38: =XLOOKUP($A38, INDIRECT("'"&H$1&"'!A:A"), INDIRECT("'"&H$1&"'!B:B"), "") -> 1 | I38: =XLOOKUP($A38, INDIRECT("'"&I$1&"'!A:A"), INDIRECT("'"&I$1&"'!B:B"), "") -> 0.64285714 | J38: =XLOOKUP($A38, INDIRECT("'"&J$1&"'!A:A"), INDIRECT("'"&J$1&"'!B:B"), "") -> 0 | K38: =XLOOKUP($A38, INDIRECT("'"&K$1&"'!A:A"), INDIRECT("'"&K$1&"'!B:B"), "") -> 0.48701307
A39: =EQ!A109 -> fcc829e7dd1db87335c46064982f06853c8a5c39399202b284952458b04f0d5d | B39: {=XLOOKUP(A39, Notes!A:A, Notes!B:B, "")} -> 53.91 | C39: =IFERROR(IMAGE(VLOOKUP(A39,DriveImages!A:C,3,FALSE),4,240,520),"") | D39: =IF($A39="","",IF(AND(N($G39)<=Params!$D$2,N($H39)<=Params!$E$2),"Peu actif",IF(AND(N($I39)>=Params!$F$4,N($E39)<=Params!$B$2,N($F39)<=Params!$C$2),"Efficace",IF(AND(N($F39)>=Params!$C$4,OR(N($I39)<=Params!$F$3,N($E39)>=Params!$B$4)),"Bloqué",IF(AND(OR(N($G39)>=Params!$D$4,N($H39)>=Params!$E$4),N($I39)<=Params!$F$3),"Persévérant",IF(AND(N($J39)>=Params!$G$4,OR(N($G39)<=Params!$D$3,N($H39)<=Params!$E$3)),"Sporadique","Intermédiaire")))))) -> Intermédiaire | E39: {=XLOOKUP(A39, EQ!A:A, EQ!B:B, "")} -> 0.27272727 | F39: {=XLOOKUP(A39, RED!A:A, RED!B:B, "")} -> 0.16666667 | G39: =XLOOKUP(A39, INDIRECT("'"&G$1&"'!A:A"), INDIRECT("'"&G$1&"'!B:B"), "") -> 13 | H39: =XLOOKUP($A39, INDIRECT("'"&H$1&"'!A:A"), INDIRECT("'"&H$1&"'!B:B"), "") -> 3 | I39: =XLOOKUP($A39, INDIRECT("'"&I$1&"'!A:A"), INDIRECT("'"&I$1&"'!B:B"), "") -> 0.61538462 | J39: =XLOOKUP($A39, INDIRECT("'"&J$1&"'!A:A"), INDIRECT("'"&J$1&"'!B:B"), "") -> 0.16666667 | K39: =XLOOKUP($A39, INDIRECT("'"&K$1&"'!A:A"), INDIRECT("'"&K$1&"'!B:B"), "") -> 0.46703292
A40: =EQ!A82 -> c38594bec27d288cfe5bd031cde0cff4c46de188336f74ff3f79854c88c65b00 | B40: {=XLOOKUP(A40, Notes!A:A, Notes!B:B, "")} -> 63.31 | C40: =IFERROR(IMAGE(VLOOKUP(A40,DriveImages!A:C,3,FALSE),4,240,520),"") | D40: =IF($A40="","",IF(AND(N($G40)<=Params!$D$2,N($H40)<=Params!$E$2),"Peu actif",IF(AND(N($I40)>=Params!$F$4,N($E40)<=Params!$B$2,N($F40)<=Params!$C$2),"Efficace",IF(AND(N($F40)>=Params!$C$4,OR(N($I40)<=Params!$F$3,N($E40)>=Params!$B$4)),"Bloqué",IF(AND(OR(N($G40)>=Params!$D$4,N($H40)>=Params!$E$4),N($I40)<=Params!$F$3),"Persévérant",IF(AND(N($J40)>=Params!$G$4,OR(N($G40)<=Params!$D$3,N($H40)<=Params!$E$3)),"Sporadique","Intermédiaire")))))) -> Sporadique | E40: {=XLOOKUP(A40, EQ!A:A, EQ!B:B, "")} -> 0.14285714 | F40: {=XLOOKUP(A40, RED!A:A, RED!B:B, "")} -> 0.07142857 | G40: =XLOOKUP(A40, INDIRECT("'"&G$1&"'!A:A"), INDIRECT("'"&G$1&"'!B:B"), "") -> 10 | H40: =XLOOKUP($A40, INDIRECT("'"&H$1&"'!A:A"), INDIRECT("'"&H$1&"'!B:B"), "") -> 3 | I40: =XLOOKUP($A40, INDIRECT("'"&I$1&"'!A:A"), INDIRECT("'"&I$1&"'!B:B"), "") -> 0.6 | J40: =XLOOKUP($A40, INDIRECT("'"&J$1&"'!A:A"), INDIRECT("'"&J$1&"'!B:B"), "") -> 0.22222222 | K40: =XLOOKUP($A40, INDIRECT("'"&K$1&"'!A:A"), INDIRECT("'"&K$1&"'!B:B"), "") -> 0.4647273
...

Sheet ACP_Norm_Red
A1: SubjectID | B1: ='Récap'!E1 -> EQ | C1: ='Récap'!F1 -> RED | D1: ='Récap'!G1 -> Comp_Count | E1: ='Récap'!H1 -> Sess_Count | F1: ='Récap'!I1 -> Comp_FP_Ratio | G1: ='Récap'!J1 -> Frac_Long | H1: ='Récap'!K1 -> Mean_Test | I1: ='Récap'!L1 | ... L1: ='Récap'!O1
A2: ='Récap'!A2 -> 0685c8001a43b03e0a155e1afa0c7bec2f4e82d24f7ce4843b25a441c45dd335 | B2: =(XLOOKUP($A2, INDIRECT("'"&B$1&"'!A:A"), INDIRECT("'"&B$1&"'!B:B"), "")-AVERAGE(INDIRECT("'"&B$1&"'!B2:B")))/STDEV(INDIRECT("'"&B$1&"'!B2:B")) -> -1.2260897 | C2: =(XLOOKUP($A2, INDIRECT("'"&C$1&"'!A:A"), INDIRECT("'"&C$1&"'!B:B"), "")-AVERAGE(INDIRECT("'"&C$1&"'!B2:B")))/STDEV(INDIRECT("'"&C$1&"'!B2:B")) -> -1.0886419 | D2: =(XLOOKUP($A2, INDIRECT("'"&D$1&"'!A:A"), INDIRECT("'"&D$1&"'!B:B"), "")-AVERAGE(INDIRECT("'"&D$1&"'!B2:B")))/STDEV(INDIRECT("'"&D$1&"'!B2:B")) -> -0.82242418 | E2: =(XLOOKUP($A2, INDIRECT("'"&E$1&"'!A:A"), INDIRECT("'"&E$1&"'!B:B"), "")-AVERAGE(INDIRECT("'"&E$1&"'!B2:B")))/STDEV(INDIRECT("'"&E$1&"'!B2:B")) -> -0.91682969 | F2: =(XLOOKUP($A2, INDIRECT("'"&F$1&"'!A:A"), INDIRECT("'"&F$1&"'!B:B"), "")-AVERAGE(INDIRECT("'"&F$1&"'!B2:B")))/STDEV(INDIRECT("'"&F$1&"'!B2:B")) -> 1.6255931 | G2: =(XLOOKUP($A2, INDIRECT("'"&G$1&"'!A:A"), INDIRECT("'"&G$1&"'!B:B"), "")-AVERAGE(INDIRECT("'"&G$1&"'!B2:B")))/STDEV(INDIRECT("'"&G$1&"'!B2:B")) -> -0.81460495 | H2: =(XLOOKUP($A2, INDIRECT("'"&H$1&"'!A:A"), INDIRECT("'"&H$1&"'!B:B"), "")-AVERAGE(INDIRECT("'"&H$1&"'!B2:B")))/STDEV(INDIRECT("'"&H$1&"'!B2:B")) -> 1.9894003
A3: ='Récap'!A3 -> 69ea8e8a316c3f982db0286a71ca33c251b858994e27bb848e628967df9d15f9 | B3: =(XLOOKUP(A3, INDIRECT("'"&B$1&"'!A:A"), INDIRECT("'"&B$1&"'!B:B"), "")-AVERAGE(INDIRECT("'"&B$1&"'!B2:B")))/STDEV(INDIRECT("'"&B$1&"'!B2:B")) -> -1.2260897 | C3: =(XLOOKUP($A3, INDIRECT("'"&C$1&"'!A:A"), INDIRECT("'"&C$1&"'!B:B"), "")-AVERAGE(INDIRECT("'"&C$1&"'!B2:B")))/STDEV(INDIRECT("'"&C$1&"'!B2:B")) -> -1.0886419 | D3: =(XLOOKUP($A3, INDIRECT("'"&D$1&"'!A:A"), INDIRECT("'"&D$1&"'!B:B"), "")-AVERAGE(INDIRECT("'"&D$1&"'!B2:B")))/STDEV(INDIRECT("'"&D$1&"'!B2:B")) -> -0.82242418 | E3: =(XLOOKUP($A3, INDIRECT("'"&E$1&"'!A:A"), INDIRECT("'"&E$1&"'!B:B"), "")-AVERAGE(INDIRECT("'"&E$1&"'!B2:B")))/STDEV(INDIRECT("'"&E$1&"'!B2:B")) -> 0.94525852 | F3: =(XLOOKUP($A3, INDIRECT("'"&F$1&"'!A:A"), INDIRECT("'"&F$1&"'!B:B"), "")-AVERAGE(INDIRECT("'"&F$1&"'!B2:B")))/STDEV(INDIRECT("'"&F$1&"'!B2:B")) -> 1.6255931 | G3: =(XLOOKUP($A3, INDIRECT("'"&G$1&"'!A:A"), INDIRECT("'"&G$1&"'!B:B"), "")-AVERAGE(INDIRECT("'"&G$1&"'!B2:B")))/STDEV(INDIRECT("'"&G$1&"'!B2:B")) -> 4.6524842 | H3: =(XLOOKUP($A3, INDIRECT("'"&H$1&"'!A:A"), INDIRECT("'"&H$1&"'!B:B"), "")-AVERAGE(INDIRECT("'"&H$1&"'!B2:B")))/STDEV(INDIRECT("'"&H$1&"'!B2:B")) -> 1.8878861
A4: ='Récap'!A4 -> 091dc109aa58c7a670f4b61bc23df548fec73c05c7582dfb7c51f3a925d3618f | B4: =(XLOOKUP(A4, INDIRECT("'"&B$1&"'!A:A"), INDIRECT("'"&B$1&"'!B:B"), "")-AVERAGE(INDIRECT("'"&B$1&"'!B2:B")))/STDEV(INDIRECT("'"&B$1&"'!B2:B")) -> -1.0862668 | C4: =(XLOOKUP($A4, INDIRECT("'"&C$1&"'!A:A"), INDIRECT("'"&C$1&"'!B:B"), "")-AVERAGE(INDIRECT("'"&C$1&"'!B2:B")))/STDEV(INDIRECT("'"&C$1&"'!B2:B")) -> -1.0080484 | D4: =(XLOOKUP($A4, INDIRECT("'"&D$1&"'!A:A"), INDIRECT("'"&D$1&"'!B:B"), "")-AVERAGE(INDIRECT("'"&D$1&"'!B2:B")))/STDEV(INDIRECT("'"&D$1&"'!B2:B")) -> 1.5299245 | E4: =(XLOOKUP($A4, INDIRECT("'"&E$1&"'!A:A"), INDIRECT("'"&E$1&"'!B:B"), "")-AVERAGE(INDIRECT("'"&E$1&"'!B2:B")))/STDEV(INDIRECT("'"&E$1&"'!B2:B")) -> 1.8763026 | F4: =(XLOOKUP($A4, INDIRECT("'"&F$1&"'!A:A"), INDIRECT("'"&F$1&"'!B:B"), "")-AVERAGE(INDIRECT("'"&F$1&"'!B2:B")))/STDEV(INDIRECT("'"&F$1&"'!B2:B")) -> 1.2913455 | G4: =(XLOOKUP($A4, INDIRECT("'"&G$1&"'!A:A"), INDIRECT("'"&G$1&"'!B:B"), "")-AVERAGE(INDIRECT("'"&G$1&"'!B2:B")))/STDEV(INDIRECT("'"&G$1&"'!B2:B")) -> 0.064034371 | H4: =(XLOOKUP($A4, INDIRECT("'"&H$1&"'!A:A"), INDIRECT("'"&H$1&"'!B:B"), "")-AVERAGE(INDIRECT("'"&H$1&"'!B2:B")))/STDEV(INDIRECT("'"&H$1&"'!B2:B")) -> 1.6873509
A5: ='Récap'!A5 -> 275839578ec60b5084d5e18fccb01310e9f1b78293cad00bec043945e0f3e629 | B5: =(XLOOKUP(A5, INDIRECT("'"&B$1&"'!A:A"), INDIRECT("'"&B$1&"'!B:B"), "")-AVERAGE(INDIRECT("'"&B$1&"'!B2:B")))/STDEV(INDIRECT("'"&B$1&"'!B2:B")) -> -1.2260897 | C5: =(XLOOKUP($A5, INDIRECT("'"&C$1&"'!A:A"), INDIRECT("'"&C$1&"'!B:B"), "")-AVERAGE(INDIRECT("'"&C$1&"'!B2:B")))/STDEV(INDIRECT("'"&C$1&"'!B2:B")) -> -1.0886419 | D5: =(XLOOKUP($A5, INDIRECT("'"&D$1&"'!A:A"), INDIRECT("'"&D$1&"'!B:B"), "")-AVERAGE(INDIRECT("'"&D$1&"'!B2:B")))/STDEV(INDIRECT("'"&D$1&"'!B2:B")) -> 0.11851528 | E5: =(XLOOKUP($A5, INDIRECT("'"&E$1&"'!A:A"), INDIRECT("'"&E$1&"'!B:B"), "")-AVERAGE(INDIRECT("'"&E$1&"'!B2:B")))/STDEV(INDIRECT("'"&E$1&"'!B2:B")) -> 0.94525852 | F5: =(XLOOKUP($A5, INDIRECT("'"&F$1&"'!A:A"), INDIRECT("'"&F$1&"'!B:B"), "")-AVERAGE(INDIRECT("'"&F$1&"'!B2:B")))/STDEV(INDIRECT("'"&F$1&"'!B2:B")) -> 1.1640131 | G5: =(XLOOKUP($A5, INDIRECT("'"&G$1&"'!A:A"), INDIRECT("'"&G$1&"'!B:B"), "")-AVERAGE(INDIRECT("'"&G$1&"'!B2:B")))/STDEV(INDIRECT("'"&G$1&"'!B2:B")) -> 0.447031 | H5: =(XLOOKUP($A5, INDIRECT("'"&H$1&"'!A:A"), INDIRECT("'"&H$1&"'!B:B"), "")-AVERAGE(INDIRECT("'"&H$1&"'!B2:B")))/STDEV(INDIRECT("'"&H$1&"'!B2:B")) -> 1.5561818
A6: ='Récap'!A6 -> cbdbb864a7b15c5903aa09adff018a3d184f25c250b86926a5bc3fd9d9169037 | B6: =(XLOOKUP(A6, INDIRECT("'"&B$1&"'!A:A"), INDIRECT("'"&B$1&"'!B:B"), "")-AVERAGE(INDIRECT("'"&B$1&"'!B2:B")))/STDEV(INDIRECT("'"&B$1&"'!B2:B")) -> -0.45706406 | C6: =(XLOOKUP($A6, INDIRECT("'"&C$1&"'!A:A"), INDIRECT("'"&C$1&"'!B:B"), "")-AVERAGE(INDIRECT("'"&C$1&"'!B2:B")))/STDEV(INDIRECT("'"&C$1&"'!B2:B")) -> -0.64537744 | D6: =(XLOOKUP($A6, INDIRECT("'"&D$1&"'!A:A"), INDIRECT("'"&D$1&"'!B:B"), "")-AVERAGE(INDIRECT("'"&D$1&"'!B2:B")))/STDEV(INDIRECT("'"&D$1&"'!B2:B")) -> 0.11851528 | E6: =(XLOOKUP($A6, INDIRECT("'"&E$1&"'!A:A"), INDIRECT("'"&E$1&"'!B:B"), "")-AVERAGE(INDIRECT("'"&E$1&"'!B2:B")))/STDEV(INDIRECT("'"&E$1&"'!B2:B")) -> -0.91682969 | F6: =(XLOOKUP($A6, INDIRECT("'"&F$1&"'!A:A"), INDIRECT("'"&F$1&"'!B:B"), "")-AVERAGE(INDIRECT("'"&F$1&"'!B2:B")))/STDEV(INDIRECT("'"&F$1&"'!B2:B")) -> 1.1640131 | G6: =(XLOOKUP($A6, INDIRECT("'"&G$1&"'!A:A"), INDIRECT("'"&G$1&"'!B:B"), "")-AVERAGE(INDIRECT("'"&G$1&"'!B2:B")))/STDEV(INDIRECT("'"&G$1&"'!B2:B")) -> -0.81460495 | H6: =(XLOOKUP($A6, INDIRECT("'"&H$1&"'!A:A"), INDIRECT("'"&H$1&"'!B:B"), "")-AVERAGE(INDIRECT("'"&H$1&"'!B2:B")))/STDEV(INDIRECT("'"&H$1&"'!B2:B")) -> 1.5441301
A7: ='Récap'!A7 -> 95944dae06f4e15b8e63e41064092bc51db9f568df5abcdb866112b0a58a759a | B7: =(XLOOKUP(A7, INDIRECT("'"&B$1&"'!A:A"), INDIRECT("'"&B$1&"'!B:B"), "")-AVERAGE(INDIRECT("'"&B$1&"'!B2:B")))/STDEV(INDIRECT("'"&B$1&"'!B2:B")) -> -1.2260897 | C7: =(XLOOKUP($A7, INDIRECT("'"&C$1&"'!A:A"), INDIRECT("'"&C$1&"'!B:B"), "")-AVERAGE(INDIRECT("'"&C$1&"'!B2:B")))/STDEV(INDIRECT("'"&C$1&"'!B2:B")) -> -1.0886419 | D7: =(XLOOKUP($A7, INDIRECT("'"&D$1&"'!A:A"), INDIRECT("'"&D$1&"'!B:B"), "")-AVERAGE(INDIRECT("'"&D$1&"'!B2:B")))/STDEV(INDIRECT("'"&D$1&"'!B2:B")) -> -0.63423629 | E7: =(XLOOKUP($A7, INDIRECT("'"&E$1&"'!A:A"), INDIRECT("'"&E$1&"'!B:B"), "")-AVERAGE(INDIRECT("'"&E$1&"'!B2:B")))/STDEV(INDIRECT("'"&E$1&"'!B2:B")) -> -0.91682969 | F7: =(XLOOKUP($A7, INDIRECT("'"&F$1&"'!A:A"), INDIRECT("'"&F$1&"'!B:B"), "")-AVERAGE(INDIRECT("'"&F$1&"'!B2:B")))/STDEV(INDIRECT("'"&F$1&"'!B2:B")) -> 1.0870831 | G7: =(XLOOKUP($A7, INDIRECT("'"&G$1&"'!A:A"), INDIRECT("'"&G$1&"'!B:B"), "")-AVERAGE(INDIRECT("'"&G$1&"'!B2:B")))/STDEV(INDIRECT("'"&G$1&"'!B2:B")) -> -0.81460495 | H7: =(XLOOKUP($A7, INDIRECT("'"&H$1&"'!A:A"), INDIRECT("'"&H$1&"'!B:B"), "")-AVERAGE(INDIRECT("'"&H$1&"'!B2:B")))/STDEV(INDIRECT("'"&H$1&"'!B2:B")) -> 1.5419816
A8: ='Récap'!A8 -> 0ff8e00eabc873cbfaa0832c3aa0e4a4b03e6f72593a71ecf7e5b2e4d0c82e06 | B8: =(XLOOKUP(A8, INDIRECT("'"&B$1&"'!A:A"), INDIRECT("'"&B$1&"'!B:B"), "")-AVERAGE(INDIRECT("'"&B$1&"'!B2:B")))/STDEV(INDIRECT("'"&B$1&"'!B2:B")) -> -1.2260897 | C8: =(XLOOKUP($A8, INDIRECT("'"&C$1&"'!A:A"), INDIRECT("'"&C$1&"'!B:B"), "")-AVERAGE(INDIRECT("'"&C$1&"'!B2:B")))/STDEV(INDIRECT("'"&C$1&"'!B2:B")) -> -1.0886419 | D8: =(XLOOKUP($A8, INDIRECT("'"&D$1&"'!A:A"), INDIRECT("'"&D$1&"'!B:B"), "")-AVERAGE(INDIRECT("'"&D$1&"'!B2:B")))/STDEV(INDIRECT("'"&D$1&"'!B2:B")) -> 0.21260922 | E8: =(XLOOKUP($A8, INDIRECT("'"&E$1&"'!A:A"), INDIRECT("'"&E$1&"'!B:B"), "")-AVERAGE(INDIRECT("'"&E$1&"'!B2:B")))/STDEV(INDIRECT("'"&E$1&"'!B2:B")) -> -0.91682969 | F8: =(XLOOKUP($A8, INDIRECT("'"&F$1&"'!A:A"), INDIRECT("'"&F$1&"'!B:B"), "")-AVERAGE(INDIRECT("'"&F$1&"'!B2:B")))/STDEV(INDIRECT("'"&F$1&"'!B2:B")) -> 1.1947851 | G8: =(XLOOKUP($A8, INDIRECT("'"&G$1&"'!A:A"), INDIRECT("'"&G$1&"'!B:B"), "")-AVERAGE(INDIRECT("'"&G$1&"'!B2:B")))/STDEV(INDIRECT("'"&G$1&"'!B2:B")) -> -0.81460495 | H8: =(XLOOKUP($A8, INDIRECT("'"&H$1&"'!A:A"), INDIRECT("'"&H$1&"'!B:B"), "")-AVERAGE(INDIRECT("'"&H$1&"'!B2:B")))/STDEV(INDIRECT("'"&H$1&"'!B2:B")) -> 1.513877
A9: ='Récap'!A9 -> 7ce2ef889fd3931ddf910c65e58e6b626f658d713486152c54f9f8a0e6f37375 | B9: =(XLOOKUP(A9, INDIRECT("'"&B$1&"'!A:A"), INDIRECT("'"&B$1&"'!B:B"), "")-AVERAGE(INDIRECT("'"&B$1&"'!B2:B")))/STDEV(INDIRECT("'"&B$1&"'!B2:B")) -> -0.84157687 | C9: =(XLOOKUP($A9, INDIRECT("'"&C$1&"'!A:A"), INDIRECT("'"&C$1&"'!B:B"), "")-AVERAGE(INDIRECT("'"&C$1&"'!B2:B")))/STDEV(INDIRECT("'"&C$1&"'!B2:B")) -> -0.86700967 | D9: =(XLOOKUP($A9, INDIRECT("'"&D$1&"'!A:A"), INDIRECT("'"&D$1&"'!B:B"), "")-AVERAGE(INDIRECT("'"&D$1&"'!B2:B")))/STDEV(INDIRECT("'"&D$1&"'!B2:B")) -> 0.87126684 | E9: =(XLOOKUP($A9, INDIRECT("'"&E$1&"'!A:A"), INDIRECT("'"&E$1&"'!B:B"), "")-AVERAGE(INDIRECT("'"&E$1&"'!B2:B")))/STDEV(INDIRECT("'"&E$1&"'!B2:B")) -> 0.94525852 | F9: =(XLOOKUP($A9, INDIRECT("'"&F$1&"'!A:A"), INDIRECT("'"&F$1&"'!B:B"), "")-AVERAGE(INDIRECT("'"&F$1&"'!B2:B")))/STDEV(INDIRECT("'"&F$1&"'!B2:B")) -> 1.184994 | G9: =(XLOOKUP($A9, INDIRECT("'"&G$1&"'!A:A"), INDIRECT("'"&G$1&"'!B:B"), "")-AVERAGE(INDIRECT("'"&G$1&"'!B2:B")))/STDEV(INDIRECT("'"&G$1&"'!B2:B")) -> -0.03359222 | H9: =(XLOOKUP($A9, INDIRECT("'"&H$1&"'!A:A"), INDIRECT("'"&H$1&"'!B:B"), "")-AVERAGE(INDIRECT("'"&H$1&"'!B2:B")))/STDEV(INDIRECT("'"&H$1&"'!B2:B")) -> 1.4731241
A10: ='Récap'!A10 -> bee686e3fcc9f3886386d09a5bbd6f4779d852c8bb282b0b6185be70704d9207 | B10: =(XLOOKUP(A10, INDIRECT("'"&B$1&"'!A:A"), INDIRECT("'"&B$1&"'!B:B"), "")-AVERAGE(INDIRECT("'"&B$1&"'!B2:B")))/STDEV(INDIRECT("'"&B$1&"'!B2:B")) -> -1.2260897 | C10: =(XLOOKUP($A10, INDIRECT("'"&C$1&"'!A:A"), INDIRECT("'"&C$1&"'!B:B"), "")-AVERAGE(INDIRECT("'"&C$1&"'!B2:B")))/STDEV(INDIRECT("'"&C$1&"'!B2:B")) -> -1.0886419 | D10: =(XLOOKUP($A10, INDIRECT("'"&D$1&"'!A:A"), INDIRECT("'"&D$1&"'!B:B"), "")-AVERAGE(INDIRECT("'"&D$1&"'!B2:B")))/STDEV(INDIRECT("'"&D$1&"'!B2:B")) -> -0.35195445 | E10: =(XLOOKUP($A10, INDIRECT("'"&E$1&"'!A:A"), INDIRECT("'"&E$1&"'!B:B"), "")-AVERAGE(INDIRECT("'"&E$1&"'!B2:B")))/STDEV(INDIRECT("'"&E$1&"'!B2:B")) -> -0.91682969 | F10: =(XLOOKUP($A10, INDIRECT("'"&F$1&"'!A:A"), INDIRECT("'"&F$1&"'!B:B"), "")-AVERAGE(INDIRECT("'"&F$1&"'!B2:B")))/STDEV(INDIRECT("'"&F$1&"'!B2:B")) -> 1.2665864 | G10: =(XLOOKUP($A10, INDIRECT("'"&G$1&"'!A:A"), INDIRECT("'"&G$1&"'!B:B"), "")-AVERAGE(INDIRECT("'"&G$1&"'!B2:B")))/STDEV(INDIRECT("'"&G$1&"'!B2:B")) -> -0.81460495 | H10: =(XLOOKUP($A10, INDIRECT("'"&H$1&"'!A:A"), INDIRECT("'"&H$1&"'!B:B"), "")-AVERAGE(INDIRECT("'"&H$1&"'!B2:B")))/STDEV(INDIRECT("'"&H$1&"'!B2:B")) -> 1.4531035
