Workbook

Sheet Récap
A1: SubjectID | B1: Notes | C1: Profil | D1: Catégorie | E1: EQ | F1: RED | G1: Comp_Count | H1: Sess_Count | I1: Comp_FP_Ratio | J1: Frac_Long | K1: Mean_Test | L1: First_Compile | M1: Compile_Span | N1: Last_Compile | O1: Time_To_Score1
A2: =EQ!A10 -> 13b34a353ac9ea6554f0bfc998b55f394ed800dfc03b32dc37d311d2551a5749 | B2: {=XLOOKUP(A2, Notes!A:A, Notes!B:B, "")} -> 70.71 | C2: =IFERROR(IMAGE(VLOOKUP(A2,DriveImages!A:C,3,FALSE),4,240,520),"") | D2: =IF($A2="","",IF(AND(N($G2)<=Params!$D$2,N($H2)<=Params!$E$2),"Peu actif",IF(AND(N($I2)>=Params!$F$4,N($E2)<=Params!$B$2,N($F2)<=Params!$C$2),"Efficace",IF(AND(N($F2)>=Params!$C$4,OR(N($I2)<=Params!$F$3,N($E2)>=Params!$B$4)),"Bloqué",IF(AND(OR(N($G2)>=Params!$D$4,N($H2)>=Params!$E$4),N($I2)<=Params!$F$3),"Persévérant",IF(AND(N($J2)>=Params!$G$4,OR(N($G2)<=Params!$D$3,N($H2)<=Params!$E$3)),"Sporadique","Intermédiaire")))))) -> Bloqué | E2: {=XLOOKUP(A2, EQ!A:A, EQ!B:B, "")} -> 0.72222222 | F2: {=XLOOKUP(A2, RED!A:A, RED!B:B, "")} -> 0.61871025 | G2: =XLOOKUP(A2, INDIRECT("'"&G$1&"'!A:A"), INDIRECT("'"&G$1&"'!B:B"), "") -> 59 | H2: =XLOOKUP($A2, INDIRECT("'"&H$1&"'!A:A"), INDIRECT("'"&H$1&"'!B:B"), "") -> 2 | I2: =XLOOKUP($A2, INDIRECT("'"&I$1&"'!A:A"), INDIRECT("'"&I$1&"'!B:B"), "") -> 0.16949153 | J2: =XLOOKUP($A2, INDIRECT("'"&J$1&"'!A:A"), INDIRECT("'"&J$1&"'!B:B"), "") -> 0.017241379 | K2: =XLOOKUP($A2, INDIRECT("'"&K$1&"'!A:A"), INDIRECT("'"&K$1&"'!B:B"), "") -> 0.13947741 | L2: =XLOOKUP($A2, INDIRECT("'"&L$1&"'!A:A"), INDIRECT("'"&L$1&"'!B:B"), "") -> 0 | M2: =XLOOKUP($A2, INDIRECT("'"&M$1&"'!A:A"), INDIRECT("'"&M$1&"'!B:B"), "") -> 51.05 | N2: =XLOOKUP($A2, INDIRECT("'"&N$1&"'!A:A"), INDIRECT("'"&N$1&"'!B:B"), "") -> 7.5166667 | O2: =XLOOKUP($A2, INDIRECT("'"&O$1&"'!A:A"), INDIRECT("'"&O$1&"'!B:B"), "") -> 18.616667
A3: =EQ!A22 -> 351cff49ce968bd6bb542470c3004131a5042932b5f2cb0e7ea8492770b77485 | B3: {=XLOOKUP(A3, Notes!A:A, Notes!B:B, "")} -> 48 | C3: =IFERROR(IMAGE(VLOOKUP(A3,DriveImages!A:C,3,FALSE),4,240,520),"") | D3: =IF($A3="","",IF(AND(N($G3)<=Params!$D$2,N($H3)<=Params!$E$2),"Peu actif",IF(AND(N($I3)>=Params!$F$4,N($E3)<=Params!$B$2,N($F3)<=Params!$C$2),"Efficace",IF(AND(N($F3)>=Params!$C$4,OR(N($I3)<=Params!$F$3,N($E3)>=Params!$B$4)),"Bloqué",IF(AND(OR(N($G3)>=Params!$D$4,N($H3)>=Params!$E$4),N($I3)<=Params!$F$3),"Persévérant",IF(AND(N($J3)>=Params!$G$4,OR(N($G3)<=Params!$D$3,N($H3)<=Params!$E$3)),"Sporadique","Intermédiaire")))))) -> Sporadique | E3: {=XLOOKUP(A3, EQ!A:A, EQ!B:B, "")} -> 0.33333333 | F3: {=XLOOKUP(A3, RED!A:A, RED!B:B, "")} -> 0.16666667 | G3: =XLOOKUP(A3, INDIRECT("'"&G$1&"'!A:A"), INDIRECT("'"&G$1&"'!B:B"), "") -> 5 | H3: =XLOOKUP($A3, INDIRECT("'"&H$1&"'!A:A"), INDIRECT("'"&H$1&"'!B:B"), "") -> 2 | I3: =XLOOKUP($A3, INDIRECT("'"&I$1&"'!A:A"), INDIRECT("'"&I$1&"'!B:B"), "") -> 0.4 | J3: =XLOOKUP($A3, INDIRECT("'"&J$1&"'!A:A"), INDIRECT("'"&J$1&"'!B:B"), "") -> 0.25 | K3: =XLOOKUP($A3, INDIRECT("'"&K$1&"'!A:A"), INDIRECT("'"&K$1&"'!B:B"), "") -> 0.4 | L3: =XLOOKUP($A3, INDIRECT("'"&L$1&"'!A:A"), INDIRECT("'"&L$1&"'!B:B"), "") -> 0.033333333 | M3: =XLOOKUP($A3, INDIRECT("'"&M$1&"'!A:A"), INDIRECT("'"&M$1&"'!B:B"), "") -> 8.5666667 | N3: =XLOOKUP($A3, INDIRECT("'"&N$1&"'!A:A"), INDIRECT("'"&N$1&"'!B:B"), "") -> 49.966667 | O3: =XLOOKUP($A3, INDIRECT("'"&O$1&"'!A:A"), INDIRECT("'"&O$1&"'!B:B"), "") -> 0.71666667
A4: =EQ!A88 -> cef23c3f251969f778435219b38afa60f2e41b3927e82fa6d43de8c59f93f883 | B4: {=XLOOKUP(A4, Notes!A:A, Notes!B:B, "")} -> 71.09 | C4: =IFERROR(IMAGE(VLOOKUP(A4,DriveImages!A:C,3,FALSE),4,240,520),"") | D4: =IF($A4="","",IF(AND(N($G4)<=Params!$D$2,N($H4)<=Params!$E$2),"Peu actif",IF(AND(N($I4)>=Params!$F$4,N($E4)<=Params!$B$2,N($F4)<=Params!$C$2),"Efficace",IF(AND(N($F4)>=Params!$C$4,OR(N($I4)<=Params!$F$3,N($E4)>=Params!$B$4)),"Bloqué",IF(AND(OR(N($G4)>=Params!$D$4,N($H4)>=Params!$E$4),N($I4)<=Params!$F$3),"Persévérant",IF(AND(N($J4)>=Params!$G$4,OR(N($G4)<=Params!$D$3,N($H4)<=Params!$E$3)),"Sporadique","Intermédiaire")))))) -> Intermédiaire | E4: {=XLOOKUP(A4, EQ!A:A, EQ!B:B, "")} -> 0.30434783 | F4: {=XLOOKUP(A4, RED!A:A, RED!B:B, "")} -> 0.2173913 | G4: =XLOOKUP(A4, INDIRECT("'"&G$1&"'!A:A"), INDIRECT("'"&G$1&"'!B:B"), "") -> 36 | H4: =XLOOKUP($A4, INDIRECT("'"&H$1&"'!A:A"), INDIRECT("'"&H$1&"'!B:B"), "") -> 2 | I4: =XLOOKUP($A4, INDIRECT("'"&I$1&"'!A:A"), INDIRECT("'"&I$1&"'!B:B"), "") -> 0.61111111 | J4: =XLOOKUP($A4, INDIRECT("'"&J$1&"'!A:A"), INDIRECT("'"&J$1&"'!B:B"), "") -> 0.028571429 | K4: =XLOOKUP($A4, INDIRECT("'"&K$1&"'!A:A"), INDIRECT("'"&K$1&"'!B:B"), "") -> 0.49802858 | L4: =XLOOKUP($A4, INDIRECT("'"&L$1&"'!A:A"), INDIRECT("'"&L$1&"'!B:B"), "") -> 0.18333333 | M4: =XLOOKUP($A4, INDIRECT("'"&M$1&"'!A:A"), INDIRECT("'"&M$1&"'!B:B"), "") -> 43.25 | N4: =XLOOKUP($A4, INDIRECT("'"&N$1&"'!A:A"), INDIRECT("'"&N$1&"'!B:B"), "") -> 15.133333 | O4: =XLOOKUP($A4, INDIRECT("'"&O$1&"'!A:A"), INDIRECT("'"&O$1&"'!B:B"), "") -> 13.05
A5: =EQ!A83 -> c547e37e3c5d2add9a3cb5fdeecfbc779e0ee9d6a7dbb489c799cc94e7b9abd2 | B5: {=XLOOKUP(A5, Notes!A:A, Notes!B:B, "")} -> 75.94 | C5: =IFERROR(IMAGE(VLOOKUP(A5,DriveImages!A:C,3,FALSE),4,240,520),"") | D5: =IF($A5="","",IF(AND(N($G5)<=Params!$D$2,N($H5)<=Params!$E$2),"Peu actif",IF(AND(N($I5)>=Params!$F$4,N($E5)<=Params!$B$2,N($F5)<=Params!$C$2),"Efficace",IF(AND(N($F5)>=Params!$C$4,OR(N($I5)<=Params!$F$3,N($E5)>=Params!$B$4)),"Bloqué",IF(AND(OR(N($G5)>=Params!$D$4,N($H5)>=Params!$E$4),N($I5)<=Params!$F$3),"Persévérant",IF(AND(N($J5)>=Params!$G$4,OR(N($G5)<=Params!$D$3,N($H5)<=Params!$E$3)),"Sporadique","Intermédiaire")))))) -> Intermédiaire | E5: {=XLOOKUP(A5, EQ!A:A, EQ!B:B, "")} -> 0.66666667 | F5: {=XLOOKUP(A5, RED!A:A, RED!B:B, "")} -> 0.5037037 | G5: =XLOOKUP(A5, INDIRECT("'"&G$1&"'!A:A"), INDIRECT("'"&G$1&"'!B:B"), "") -> 10 | H5: =XLOOKUP($A5, INDIRECT("'"&H$1&"'!A:A"), INDIRECT("'"&H$1&"'!B:B"), "") -> 1 | I5: =XLOOKUP($A5, INDIRECT("'"&I$1&"'!A:A"), INDIRECT("'"&I$1&"'!B:B"), "") -> 0.2 | J5: =XLOOKUP($A5, INDIRECT("'"&J$1&"'!A:A"), INDIRECT("'"&J$1&"'!B:B"), "") -> 0 | K5: =XLOOKUP($A5, INDIRECT("'"&K$1&"'!A:A"), INDIRECT("'"&K$1&"'!B:B"), "") -> 0.1714286 | L5: =XLOOKUP($A5, INDIRECT("'"&L$1&"'!A:A"), INDIRECT("'"&L$1&"'!B:B"), "") -> 1.2 | M5: =XLOOKUP($A5, INDIRECT("'"&M$1&"'!A:A"), INDIRECT("'"&M$1&"'!B:B"), "") -> 12.65 | N5: =XLOOKUP($A5, INDIRECT("'"&N$1&"'!A:A"), INDIRECT("'"&N$1&"'!B:B"), "") -> 44.716667 | O5: =XLOOKUP($A5, INDIRECT("'"&O$1&"'!A:A"), INDIRECT("'"&O$1&"'!B:B"), "") -> 12.65
A6: =EQ!A6 -> 098d08de95d38eeec0842ad11e1e98d03c5afff456588f8ec0e9b2842aae39a3 | B6: {=XLOOKUP(A6, Notes!A:A, Notes!B:B, "")} -> 86.16 | C6: =IFERROR(IMAGE(VLOOKUP(A6,DriveImages!A:C,3,FALSE),4,240,520),"") | D6: =IF($A6="","",IF(AND(N($G6)<=Params!$D$2,N($H6)<=Params!$E$2),"Peu actif",IF(AND(N($I6)>=Params!$F$4,N($E6)<=Params!$B$2,N($F6)<=Params!$C$2),"Efficace",IF(AND(N($F6)>=Params!$C$4,OR(N($I6)<=Params!$F$3,N($E6)>=Params!$B$4)),"Bloqué",IF(AND(OR(N($G6)>=Params!$D$4,N($H6)>=Params!$E$4),N($I6)<=Params!$F$3),"Persévérant",IF(AND(N($J6)>=Params!$G$4,OR(N($G6)<=Params!$D$3,N($H6)<=Params!$E$3)),"Sporadique","Intermédiaire")))))) -> Efficace | E6: {=XLOOKUP(A6, EQ!A:A, EQ!B:B, "")} -> 0 | F6: {=XLOOKUP(A6, RED!A:A, RED!B:B, "")} -> 0 | G6: =XLOOKUP(A6, INDIRECT("'"&G$1&"'!A:A"), INDIRECT("'"&G$1&"'!B:B"), "") -> 4 | H6: =XLOOKUP($A6, INDIRECT("'"&H$1&"'!A:A"), INDIRECT("'"&H$1&"'!B:B"), "") -> 2 | I6: =XLOOKUP($A6, INDIRECT("'"&I$1&"'!A:A"), INDIRECT("'"&I$1&"'!B:B"), "") -> 0.75 | J6: =XLOOKUP($A6, INDIRECT("'"&J$1&"'!A:A"), INDIRECT("'"&J$1&"'!B:B"), "") -> 0.33333333 | K6: =XLOOKUP($A6, INDIRECT("'"&K$1&"'!A:A"), INDIRECT("'"&K$1&"'!B:B"), "") -> 0.43 | L6: =XLOOKUP($A6, INDIRECT("'"&L$1&"'!A:A"), INDIRECT("'"&L$1&"'!B:B"), "") -> 1.4 | M6: =XLOOKUP($A6, INDIRECT("'"&M$1&"'!A:A"), INDIRECT("'"&M$1&"'!B:B"), "") -> 13.633333 | N6: =XLOOKUP($A6, INDIRECT("'"&N$1&"'!A:A"), INDIRECT("'"&N$1&"'!B:B"), "") -> 43.533333 | O6: =XLOOKUP($A6, INDIRECT("'"&O$1&"'!A:A"), INDIRECT("'"&O$1&"'!B:B"), "") -> 0
A7: =EQ!A76 -> b2c90b16a2864cf16993f00192cdb13ee656ac6cd53f745acd473a25224cd05d | B7: {=XLOOKUP(A7, Notes!A:A, Notes!B:B, "")} -> 58.25 | C7: =IFERROR(IMAGE(VLOOKUP(A7,DriveImages!A:C,3,FALSE),4,240,520),"") | D7: =IF($A7="","",IF(AND(N($G7)<=Params!$D$2,N($H7)<=Params!$E$2),"Peu actif",IF(AND(N($I7)>=Params!$F$4,N($E7)<=Params!$B$2,N($F7)<=Params!$C$2),"Efficace",IF(AND(N($F7)>=Params!$C$4,OR(N($I7)<=Params!$F$3,N($E7)>=Params!$B$4)),"Bloqué",IF(AND(OR(N($G7)>=Params!$D$4,N($H7)>=Params!$E$4),N($I7)<=Params!$F$3),"Persévérant",IF(AND(N($J7)>=Params!$G$4,OR(N($G7)<=Params!$D$3,N($H7)<=Params!$E$3)),"Sporadique","Intermédiaire")))))) -> Efficace | E7: {=XLOOKUP(A7, EQ!A:A, EQ!B:B, "")} -> 0.076923077 | F7: {=XLOOKUP(A7, RED!A:A, RED!B:B, "")} -> 0.03846154 | G7: =XLOOKUP(A7, INDIRECT("'"&G$1&"'!A:A"), INDIRECT("'"&G$1&"'!B:B"), "") -> 21 | H7: =XLOOKUP($A7, INDIRECT("'"&H$1&"'!A:A"), INDIRECT("'"&H$1&"'!B:B"), "") -> 6 | I7: =XLOOKUP($A7, INDIRECT("'"&I$1&"'!A:A"), INDIRECT("'"&I$1&"'!B:B"), "") -> 0.76190476 | J7: =XLOOKUP($A7, INDIRECT("'"&J$1&"'!A:A"), INDIRECT("'"&J$1&"'!B:B"), "") -> 0.25 | K7: =XLOOKUP($A7, INDIRECT("'"&K$1&"'!A:A"), INDIRECT("'"&K$1&"'!B:B"), "") -> 0.64557824 | L7: =XLOOKUP($A7, INDIRECT("'"&L$1&"'!A:A"), INDIRECT("'"&L$1&"'!B:B"), "") -> 2.05 | M7: =XLOOKUP($A7, INDIRECT("'"&M$1&"'!A:A"), INDIRECT("'"&M$1&"'!B:B"), "") -> 56.283333 | N7: =XLOOKUP($A7, INDIRECT("'"&N$1&"'!A:A"), INDIRECT("'"&N$1&"'!B:B"), "") -> 0.23333333 | O7: =XLOOKUP($A7, INDIRECT("'"&O$1&"'!A:A"), INDIRECT("'"&O$1&"'!B:B"), "") -> 0
A8: =EQ!A41 -> 6a91389bf293538f8bfd1747ffc38730176f9e72e8ed7004fabc8cd25e69df6b | B8: {=XLOOKUP(A8, Notes!A:A, Notes!B:B, "")} -> 42.53 | C8: =IFERROR(IMAGE(VLOOKUP(A8,DriveImages!A:C,3,FALSE),4,240,520),"") | D8: =IF($A8="","",IF(AND(N($G8)<=Params!$D$2,N($H8)<=Params!$E$2),"Peu actif",IF(AND(N($I8)>=Params!$F$4,N($E8)<=Params!$B$2,N($F8)<=Params!$C$2),"Efficace",IF(AND(N($F8)>=Params!$C$4,OR(N($I8)<=Params!$F$3,N($E8)>=Params!$B$4)),"Bloqué",IF(AND(OR(N($G8)>=Params!$D$4,N($H8)>=Params!$E$4),N($I8)<=Params!$F$3),"Persévérant",IF(AND(N($J8)>=Params!$G$4,OR(N($G8)<=Params!$D$3,N($H8)<=Params!$E$3)),"Sporadique","Intermédiaire")))))) -> Efficace | E8: {=XLOOKUP(A8, EQ!A:A, EQ!B:B, "")} -> 0 | F8: {=XLOOKUP(A8, RED!A:A, RED!B:B, "")} -> 0 | G8: =XLOOKUP(A8, INDIRECT("'"&G$1&"'!A:A"), INDIRECT("'"&G$1&"'!B:B"), "") -> 12 | H8: =XLOOKUP($A8, INDIRECT("'"&H$1&"'!A:A"), INDIRECT("'"&H$1&"'!B:B"), "") -> 2 | I8: =XLOOKUP($A8, INDIRECT("'"&I$1&"'!A:A"), INDIRECT("'"&I$1&"'!B:B"), "") -> 1 | J8: =XLOOKUP($A8, INDIRECT("'"&J$1&"'!A:A"), INDIRECT("'"&J$1&"'!B:B"), "") -> 0.090909091 | K8: =XLOOKUP($A8, INDIRECT("'"&K$1&"'!A:A"), INDIRECT("'"&K$1&"'!B:B"), "") -> 0.5345455 | L8: =XLOOKUP($A8, INDIRECT("'"&L$1&"'!A:A"), INDIRECT("'"&L$1&"'!B:B"), "") -> 2.1166667 | M8: =XLOOKUP($A8, INDIRECT("'"&M$1&"'!A:A"), INDIRECT("'"&M$1&"'!B:B"), "") -> 30.883333 | N8: =XLOOKUP($A8, INDIRECT("'"&N$1&"'!A:A"), INDIRECT("'"&N$1&"'!B:B"), "") -> 25.566667 | O8: =XLOOKUP($A8, INDIRECT("'"&O$1&"'!A:A"), INDIRECT("'"&O$1&"'!B:B"), "") -> 1.4833333
A9: =EQ!A63 -> 93a7aef5296e288f3a39f8c1c0dcb8935c9657f5c87378408e5d1910444e7c70 | B9: {=XLOOKUP(A9, Notes!A:A, Notes!B:B, "")} -> 61.57 | C9: =IFERROR(IMAGE(VLOOKUP(A9,DriveImages!A:C,3,FALSE),4,240,520),"") | D9: =IF($A9="","",IF(AND(N($G9)<=Params!$D$2,N($H9)<=Params!$E$2),"Peu actif",IF(AND(N($I9)>=Params!$F$4,N($E9)<=Params!$B$2,N($F9)<=Params!$C$2),"Efficace",IF(AND(N($F9)>=Params!$C$4,OR(N($I9)<=Params!$F$3,N($E9)>=Params!$B$4)),"Bloqué",IF(AND(OR(N($G9)>=Params!$D$4,N($H9)>=Params!$E$4),N($I9)<=Params!$F$3),"Persévérant",IF(AND(N($J9)>=Params!$G$4,OR(N($G9)<=Params!$D$3,N($H9)<=Params!$E$3)),"Sporadique","Intermédiaire")))))) -> Intermédiaire | E9: {=XLOOKUP(A9, EQ!A:A, EQ!B:B, "")} -> 0.58333333 | F9: {=XLOOKUP(A9, RED!A:A, RED!B:B, "")} -> 0.51041667 | G9: =XLOOKUP(A9, INDIRECT("'"&G$1&"'!A:A"), INDIRECT("'"&G$1&"'!B:B"), "") -> 20 | H9: =XLOOKUP($A9, INDIRECT("'"&H$1&"'!A:A"), INDIRECT("'"&H$1&"'!B:B"), "") -> 4 | I9: =XLOOKUP($A9, INDIRECT("'"&I$1&"'!A:A"), INDIRECT("'"&I$1&"'!B:B"), "") -> 0.55 | J9: =XLOOKUP($A9, INDIRECT("'"&J$1&"'!A:A"), INDIRECT("'"&J$1&"'!B:B"), "") -> 0.15789474 | K9: =XLOOKUP($A9, INDIRECT("'"&K$1&"'!A:A"), INDIRECT("'"&K$1&"'!B:B"), "") -> 0.53333335 | L9: =XLOOKUP($A9, INDIRECT("'"&L$1&"'!A:A"), INDIRECT("'"&L$1&"'!B:B"), "") -> 2.35 | M9: =XLOOKUP($A9, INDIRECT("'"&M$1&"'!A:A"), INDIRECT("'"&M$1&"'!B:B"), "") -> 48.266667 | N9: =XLOOKUP($A9, INDIRECT("'"&N$1&"'!A:A"), INDIRECT("'"&N$1&"'!B:B"), "") -> 7.95 | O9: =XLOOKUP($A9, INDIRECT("'"&O$1&"'!A:A"), INDIRECT("'"&O$1&"'!B:B"), "") -> 23.633333
A10: =EQ!A50 -> 76b0bf253c0d17b6f275cc641729eda42ebed851893da32c132515023ab1e4e1 | B10: {=XLOOKUP(A10, Notes!A:A, Notes!B:B, "")} -> 62.06 | C10: =IFERROR(IMAGE(VLOOKUP(A10,DriveImages!A:C,3,FALSE),4,240,520),"") | D10: =IF($A10="","",IF(AND(N($G10)<=Params!$D$2,N($H10)<=Params!$E$2),"Peu actif",IF(AND(N($I10)>=Params!$F$4,N($E10)<=Params!$B$2,N($F10)<=Params!$C$2),"Efficace",IF(AND(N($F10)>=Params!$C$4,OR(N($I10)<=Params!$F$3,N($E10)>=Params!$B$4)),"Bloqué",IF(AND(OR(N($G10)>=Params!$D$4,N($H10)>=Params!$E$4),N($I10)<=Params!$F$3),"Persévérant",IF(AND(N($J10)>=Params!$G$4,OR(N($G10)<=Params!$D$3,N($H10)<=Params!$E$3)),"Sporadique","Intermédiaire")))))) -> Intermédiaire | E10: {=XLOOKUP(A10, EQ!A:A, EQ!B:B, "")} -> 0.33333333 | F10: {=XLOOKUP(A10, RED!A:A, RED!B:B, "")} -> 0.22222222 | G10: =XLOOKUP(A10, INDIRECT("'"&G$1&"'!A:A"), INDIRECT("'"&G$1&"'!B:B"), "") -> 11 | H10: =XLOOKUP($A10, INDIRECT("'"&H$1&"'!A:A"), INDIRECT("'"&H$1&"'!B:B"), "") -> 2 | I10: =XLOOKUP($A10, INDIRECT("'"&I$1&"'!A:A"), INDIRECT("'"&I$1&"'!B:B"), "") -> 0.54545455 | J10: =XLOOKUP($A10, INDIRECT("'"&J$1&"'!A:A"), INDIRECT("'"&J$1&"'!B:B"), "") -> 0.1 | K10: =XLOOKUP($A10, INDIRECT("'"&K$1&"'!A:A"), INDIRECT("'"&K$1&"'!B:B"), "") -> 0.53409091 | L10: =XLOOKUP($A10, INDIRECT("'"&L$1&"'!A:A"), INDIRECT("'"&L$1&"'!B:B"), "") -> 2.4333333 | M10: =XLOOKUP($A10, INDIRECT("'"&M$1&"'!A:A"), INDIRECT("'"&M$1&"'!B:B"), "") -> 20.866667 | N10: =XLOOKUP($A10, INDIRECT("'"&N$1&"'!A:A"), INDIRECT("'"&N$1&"'!B:B"), "") -> 35.266667 | O10: =XLOOKUP($A10, INDIRECT("'"&O$1&"'!A:A"), INDIRECT("'"&O$1&"'!B:B"), "") -> 2.1333333
A11: =EQ!A62 -> 9323ada035535298a0de65f40698a45122446c861947978f1be17123ecf09a53 | B11: {=XLOOKUP(A11, Notes!A:A, Notes!B:B, "")} -> 61.57 | C11: =IFERROR(IMAGE(VLOOKUP(A11,DriveImages!A:C,3,FALSE),4,240,520),"") | D11: =IF($A11="","",IF(AND(N($G11)<=Params!$D$2,N($H11)<=Params!$E$2),"Peu actif",IF(AND(N($I11)>=Params!$F$4,N($E11)<=Params!$B$2,N($F11)<=Params!$C$2),"Efficace",IF(AND(N($F11)>=Params!$C$4,OR(N($I11)<=Params!$F$3,N($E11)>=Params!$B$4)),"Bloqué",IF(AND(OR(N($G11)>=Params!$D$4,N($H11)>=Params!$E$4),N($I11)<=Params!$F$3),"Persévérant",IF(AND(N($J11)>=Params!$G$4,OR(N($G11)<=Params!$D$3,N($H11)<=Params!$E$3)),"Sporadique","Intermédiaire")))))) -> Bloqué | E11: {=XLOOKUP(A11, EQ!A:A, EQ!B:B, "")} -> 1 | F11: {=XLOOKUP(A11, RED!A:A, RED!B:B, "")} -> 0.83333333 | G11: =XLOOKUP(A11, INDIRECT("'"&G$1&"'!A:A"), INDIRECT("'"&G$1&"'!B:B"), "") -> 6 | H11: =XLOOKUP($A11, INDIRECT("'"&H$1&"'!A:A"), INDIRECT("'"&H$1&"'!B:B"), "") -> 2 | I11: =XLOOKUP($A11, INDIRECT("'"&I$1&"'!A:A"), INDIRECT("'"&I$1&"'!B:B"), "") -> 0 | J11: =XLOOKUP($A11, INDIRECT("'"&J$1&"'!A:A"), INDIRECT("'"&J$1&"'!B:B"), "") -> 0.2 | K11: =XLOOKUP($A11, INDIRECT("'"&K$1&"'!A:A"), INDIRECT("'"&K$1&"'!B:B"), "") -> 0 | L11: =XLOOKUP($A11, INDIRECT("'"&L$1&"'!A:A"), INDIRECT("'"&L$1&"'!B:B"), "") -> 2.7166667 | M11: =XLOOKUP($A11, INDIRECT("'"&M$1&"'!A:A"), INDIRECT("'"&M$1&"'!B:B"), "") -> 17.4 | N11: =XLOOKUP($A11, INDIRECT("'"&N$1&"'!A:A"), INDIRECT("'"&N$1&"'!B:B"), "") -> 38.45 | O11: =XLOOKUP($A11, INDIRECT("'"&O$1&"'!A:A"), INDIRECT("'"&O$1&"'!B:B"), "") -> 60
A12: =EQ!A78 -> bd41cbdc04707f80b319802470a1871b99d36766f9d020cc0f9a569a4d1bb54b | B12: {=XLOOKUP(A12, Notes!A:A, Notes!B:B, "")} -> 68.44 | C12: =IFERROR(IMAGE(VLOOKUP(A12,DriveImages!A:C,3,FALSE),4,240,520),"") | D12: =IF($A12="","",IF(AND(N($G12)<=Params!$D$2,N($H12)<=Params!$E$2),"Peu actif",IF(AND(N($I12)>=Params!$F$4,N($E12)<=Params!$B$2,N($F12)<=Params!$C$2),"Efficace",IF(AND(N($F12)>=Params!$C$4,OR(N($I12)<=Params!$F$3,N($E12)>=Params!$B$4)),"Bloqué",IF(AND(OR(N($G12)>=Params!$D$4,N($H12)>=Params!$E$4),N($I12)<=Params!$F$3),"Persévérant",IF(AND(N($J12)>=Params!$G$4,OR(N($G12)<=Params!$D$3,N($H12)<=Params!$E$3)),"Sporadique","Intermédiaire")))))) -> Peu actif | E12: {=XLOOKUP(A12, EQ!A:A, EQ!B:B, "")} -> 0.33333333 | F12: {=XLOOKUP(A12, RED!A:A, RED!B:B, "")} -> 0.16666667 | G12: =XLOOKUP(A12, INDIRECT("'"&G$1&"'!A:A"), INDIRECT("'"&G$1&"'!B:B"), "") -> 4 | H12: =XLOOKUP($A12, INDIRECT("'"&H$1&"'!A:A"), INDIRECT("'"&H$1&"'!B:B"), "") -> 1 | I12: =XLOOKUP($A12, INDIRECT("'"&I$1&"'!A:A"), INDIRECT("'"&I$1&"'!B:B"), "") -> 0.5 | J12: =XLOOKUP($A12, INDIRECT("'"&J$1&"'!A:A"), INDIRECT("'"&J$1&"'!B:B"), "") -> 0 | K12: =XLOOKUP($A12, INDIRECT("'"&K$1&"'!A:A"), INDIRECT("'"&K$1&"'!B:B"), "") -> 0.44230775 | L12: =XLOOKUP($A12, INDIRECT("'"&L$1&"'!A:A"), INDIRECT("'"&L$1&"'!B:B"), "") -> 2.9666667 | M12: =XLOOKUP($A12, INDIRECT("'"&M$1&"'!A:A"), INDIRECT("'"&M$1&"'!B:B"), "") -> 1.2333333 | N12: =XLOOKUP($A12, INDIRECT("'"&N$1&"'!A:A"), INDIRECT("'"&N$1&"'!B:B"), "") -> 54.366667 | O12: =XLOOKUP($A12, INDIRECT("'"&O$1&"'!A:A"), INDIRECT("'"&O$1&"'!B:B"), "") -> 1.2333333
A13: =EQ!A36 -> 5c075290e921279538ad0cbf9786e8855bd2c7f97a066c94d059d313cb34273b | B13: {=XLOOKUP(A13, Notes!A:A, Notes!B:B, "")} -> 61.23 | C13: =IFERROR(IMAGE(VLOOKUP(A13,DriveImages!A:C,3,FALSE),4,240,520),"") | D13: =IF($A13="","",IF(AND(N($G13)<=Params!$D$2,N($H13)<=Params!$E$2),"Peu actif",IF(AND(N($I13)>=Params!$F$4,N($E13)<=Params!$B$2,N($F13)<=Params!$C$2),"Efficace",IF(AND(N($F13)>=Params!$C$4,OR(N($I13)<=Params!$F$3,N($E13)>=Params!$B$4)),"Bloqué",IF(AND(OR(N($G13)>=Params!$D$4,N($H13)>=Params!$E$4),N($I13)<=Params!$F$3),"Persévérant",IF(AND(N($J13)>=Params!$G$4,OR(N($G13)<=Params!$D$3,N($H13)<=Params!$E$3)),"Sporadique","Intermédiaire")))))) -> Intermédiaire | E13: {=XLOOKUP(A13, EQ!A:A, EQ!B:B, "")} -> 0.1875 | F13: {=XLOOKUP(A13, RED!A:A, RED!B:B, "")} -> 0.140625 | G13: =XLOOKUP(A13, INDIRECT("'"&G$1&"'!A:A"), INDIRECT("'"&G$1&"'!B:B"), "") -> 23 | H13: =XLOOKUP($A13, INDIRECT("'"&H$1&"'!A:A"), INDIRECT("'"&H$1&"'!B:B"), "") -> 4 | I13: =XLOOKUP($A13, INDIRECT("'"&I$1&"'!A:A"), INDIRECT("'"&I$1&"'!B:B"), "") -> 0.56521739 | J13: =XLOOKUP($A13, INDIRECT("'"&J$1&"'!A:A"), INDIRECT("'"&J$1&"'!B:B"), "") -> 0.13636364 | K13: =XLOOKUP($A13, INDIRECT("'"&K$1&"'!A:A"), INDIRECT("'"&K$1&"'!B:B"), "") -> 0.40518396 | L13: =XLOOKUP($A13, INDIRECT("'"&L$1&"'!A:A"), INDIRECT("'"&L$1&"'!B:B"), "") -> 3.3666667 | M13: =XLOOKUP($A13, INDIRECT("'"&M$1&"'!A:A"), INDIRECT("'"&M$1&"'!B:B"), "") -> 47.466667 | N13: =XLOOKUP($A13, INDIRECT("'"&N$1&"'!A:A"), INDIRECT("'"&N$1&"'!B:B"), "") -> 7.7333333 | O13: =XLOOKUP($A13, INDIRECT("'"&O$1&"'!A:A"), INDIRECT("'"&O$1&"'!B:B"), "") -> 6.0333333
A14: =EQ!A94 -> d9381190f981d16a88149206249465bb181ce58d6359562dea944f4d477363e3 | B14: {=XLOOKUP(A14, Notes!A:A, Notes!B:B, "")} -> 52.9 | C14: =IFERROR(IMAGE(VLOOKUP(A14,DriveImages!A:C,3,FALSE),4,240,520),"") | D14: =IF($A14="","",IF(AND(N($G14)<=Params!$D$2,N($H14)<=Params!$E$2),"Peu actif",IF(AND(N($I14)>=Params!$F$4,N($E14)<=Params!$B$2,N($F14)<=Params!$C$2),"Efficace",IF(AND(N($F14)>=Params!$C$4,OR(N($I14)<=Params!$F$3,N($E14)>=Params!$B$4)),"Bloqué",IF(AND(OR(N($G14)>=Params!$D$4,N($H14)>=Params!$E$4),N($I14)<=Params!$F$3),"Persévérant",IF(AND(N($J14)>=Params!$G$4,OR(N($G14)<=Params!$D$3,N($H14)<=Params!$E$3)),"Sporadique","Intermédiaire")))))) -> Intermédiaire | E14: {=XLOOKUP(A14, EQ!A:A, EQ!B:B, "")} -> 0.25 | F14: {=XLOOKUP(A14, RED!A:A, RED!B:B, "")} -> 0.125 | G14: =XLOOKUP(A14, INDIRECT("'"&G$1&"'!A:A"), INDIRECT("'"&G$1&"'!B:B"), "") -> 12 | H14: =XLOOKUP($A14, INDIRECT("'"&H$1&"'!A:A"), INDIRECT("'"&H$1&"'!B:B"), "") -> 1 | I14: =XLOOKUP($A14, INDIRECT("'"&I$1&"'!A:A"), INDIRECT("'"&I$1&"'!B:B"), "") -> 0.41666667 | J14: =XLOOKUP($A14, INDIRECT("'"&J$1&"'!A:A"), INDIRECT("'"&J$1&"'!B:B"), "") -> 0 | K14: =XLOOKUP($A14, INDIRECT("'"&K$1&"'!A:A"), INDIRECT("'"&K$1&"'!B:B"), "") -> 0.40333333 | L14: =XLOOKUP($A14, INDIRECT("'"&L$1&"'!A:A"), INDIRECT("'"&L$1&"'!B:B"), "") -> 3.55 | M14: =XLOOKUP($A14, INDIRECT("'"&M$1&"'!A:A"), INDIRECT("'"&M$1&"'!B:B"), "") -> 11.516667 | N14: =XLOOKUP($A14, INDIRECT("'"&N$1&"'!A:A"), INDIRECT("'"&N$1&"'!B:B"), "") -> 43.5 | O14: =XLOOKUP($A14, INDIRECT("'"&O$1&"'!A:A"), INDIRECT("'"&O$1&"'!B:B"), "") -> 0.86666667
A15: =EQ!A31 -> 48f565383f47c6752893810686bd0c5f07fef08e34bc22a3f398d3b8c8db7c43 | B15: {=XLOOKUP(A15, Notes!A:A, Notes!B:B, "")} -> 56.91 | C15: =IFERROR(IMAGE(VLOOKUP(A15,DriveImages!A:C,3,FALSE),4,240,520),"") | D15: =IF($A15="","",IF(AND(N($G15)<=Params!$D$2,N($H15)<=Params!$E$2),"Peu actif",IF(AND(N($I15)>=Params!$F$4,N($E15)<=Params!$B$2,N($F15)<=Params!$C$2),"Efficace",IF(AND(N($F15)>=Params!$C$4,OR(N($I15)<=Params!$F$3,N($E15)>=Params!$B$4)),"Bloqué",IF(AND(OR(N($G15)>=Params!$D$4,N($H15)>=Params!$E$4),N($I15)<=Params!$F$3),"Persévérant",IF(AND(N($J15)>=Params!$G$4,OR(N($G15)<=Params!$D$3,N($H15)<=Params!$E$3)),"Sporadique","Intermédiaire")))))) -> Bloqué | E15: {=XLOOKUP(A15, EQ!A:A, EQ!B:B, "")} -> 0.69565217 | F15: {=XLOOKUP(A15, RED!A:A, RED!B:B, "")} -> 0.59075224 | G15: =XLOOKUP(A15, INDIRECT("'"&G$1&"'!A:A"), INDIRECT("'"&G$1&"'!B:B"), "") -> 29 | H15: =XLOOKUP($A15, INDIRECT("'"&H$1&"'!A:A"), INDIRECT("'"&H$1&"'!B:B"), "") -> 2 | I15: =XLOOKUP($A15, INDIRECT("'"&I$1&"'!A:A"), INDIRECT("'"&I$1&"'!B:B"), "") -> 0.31034483 | J15: =XLOOKUP($A15, INDIRECT("'"&J$1&"'!A:A"), INDIRECT("'"&J$1&"'!B:B"), "") -> 0.035714286 | K15: =XLOOKUP($A15, INDIRECT("'"&K$1&"'!A:A"), INDIRECT("'"&K$1&"'!B:B"), "") -> 0.27032021 | L15: =XLOOKUP($A15, INDIRECT("'"&L$1&"'!A:A"), INDIRECT("'"&L$1&"'!B:B"), "") -> 4.35 | M15: =XLOOKUP($A15, INDIRECT("'"&M$1&"'!A:A"), INDIRECT("'"&M$1&"'!B:B"), "") -> 47.483333 | N15: =XLOOKUP($A15, INDIRECT("'"&N$1&"'!A:A"), INDIRECT("'"&N$1&"'!B:B"), "") -> 6.7333333 | O15: =XLOOKUP($A15, INDIRECT("'"&O$1&"'!A:A"), INDIRECT("'"&O$1&"'!B:B"), "") -> 10.283333
A16: =EQ!A85 -> ca1b7797566e850c3e583a2fbda610a51d5504ca9b0d611a0a3e2770c912d52d | B16: {=XLOOKUP(A16, Notes!A:A, Notes!B:B, "")} -> 48 | C16: =IFERROR(IMAGE(VLOOKUP(A16,DriveImages!A:C,3,FALSE),4,240,520),"") | D16: =IF($A16="","",IF(AND(N($G16)<=Params!$D$2,N($H16)<=Params!$E$2),"Peu actif",IF(AND(N($I16)>=Params!$F$4,N($E16)<=Params!$B$2,N($F16)<=Params!$C$2),"Efficace",IF(AND(N($F16)>=Params!$C$4,OR(N($I16)<=Params!$F$3,N($E16)>=Params!$B$4)),"Bloqué",IF(AND(OR(N($G16)>=Params!$D$4,N($H16)>=Params!$E$4),N($I16)<=Params!$F$3),"Persévérant",IF(AND(N($J16)>=Params!$G$4,OR(N($G16)<=Params!$D$3,N($H16)<=Params!$E$3)),"Sporadique","Intermédiaire")))))) -> Intermédiaire | E16: {=XLOOKUP(A16, EQ!A:A, EQ!B:B, "")} -> 0.41666667 | F16: {=XLOOKUP(A16, RED!A:A, RED!B:B, "")} -> 0.29861111 | G16: =XLOOKUP(A16, INDIRECT("'"&G$1&"'!A:A"), INDIRECT("'"&G$1&"'!B:B"), "") -> 18 | H16: =XLOOKUP($A16, INDIRECT("'"&H$1&"'!A:A"), INDIRECT("'"&H$1&"'!B:B"), "") -> 2 | I16: =XLOOKUP($A16, INDIRECT("'"&I$1&"'!A:A"), INDIRECT("'"&I$1&"'!B:B"), "") -> 0.55555556 | J16: =XLOOKUP($A16, INDIRECT("'"&J$1&"'!A:A"), INDIRECT("'"&J$1&"'!B:B"), "") -> 0.058823529 | K16: =XLOOKUP($A16, INDIRECT("'"&K$1&"'!A:A"), INDIRECT("'"&K$1&"'!B:B"), "") -> 0.45405983 | L16: =XLOOKUP($A16, INDIRECT("'"&L$1&"'!A:A"), INDIRECT("'"&L$1&"'!B:B"), "") -> 4.5333333 | M16: =XLOOKUP($A16, INDIRECT("'"&M$1&"'!A:A"), INDIRECT("'"&M$1&"'!B:B"), "") -> 16.316667 | N16: =XLOOKUP($A16, INDIRECT("'"&N$1&"'!A:A"), INDIRECT("'"&N$1&"'!B:B"), "") -> 37.716667 | O16: =XLOOKUP($A16, INDIRECT("'"&O$1&"'!A:A"), INDIRECT("'"&O$1&"'!B:B"), "") -> 10.933333
A17: =EQ!A80 -> bee686e3fcc9f3886386d09a5bbd6f4779d852c8bb282b0b6185be70704d9207 | B17: {=XLOOKUP(A17, Notes!A:A, Notes!B:B, "")} -> 85.8 | C17: =IFERROR(IMAGE(VLOOKUP(A17,DriveImages!A:C,3,FALSE),4,240,520),"") | D17: =IF($A17="","",IF(AND(N($G17)<=Params!$D$2,N($H17)<=Params!$E$2),"Peu actif",IF(AND(N($I17)>=Params!$F$4,N($E17)<=Params!$B$2,N($F17)<=Params!$C$2),"Efficace",IF(AND(N($F17)>=Params!$C$4,OR(N($I17)<=Params!$F$3,N($E17)>=Params!$B$4)),"Bloqué",IF(AND(OR(N($G17)>=Params!$D$4,N($H17)>=Params!$E$4),N($I17)<=Params!$F$3),"Persévérant",IF(AND(N($J17)>=Params!$G$4,OR(N($G17)<=Params!$D$3,N($H17)<=Params!$E$3)),"Sporadique","Intermédiaire")))))) -> Efficace | E17: {=XLOOKUP(A17, EQ!A:A, EQ!B:B, "")} -> 0 | F17: {=XLOOKUP(A17, RED!A:A, RED!B:B, "")} -> 0 | G17: =XLOOKUP(A17, INDIRECT("'"&G$1&"'!A:A"), INDIRECT("'"&G$1&"'!B:B"), "") -> 9 | H17: =XLOOKUP($A17, INDIRECT("'"&H$1&"'!A:A"), INDIRECT("'"&H$1&"'!B:B"), "") -> 1 | I17: =XLOOKUP($A17, INDIRECT("'"&I$1&"'!A:A"), INDIRECT("'"&I$1&"'!B:B"), "") -> 0.88888889 | J17: =XLOOKUP($A17, INDIRECT("'"&J$1&"'!A:A"), INDIRECT("'"&J$1&"'!B:B"), "") -> 0 | K17: =XLOOKUP($A17, INDIRECT("'"&K$1&"'!A:A"), INDIRECT("'"&K$1&"'!B:B"), "") -> 0.80886244 | L17: =XLOOKUP($A17, INDIRECT("'"&L$1&"'!A:A"), INDIRECT("'"&L$1&"'!B:B"), "") -> 5.05 | M17: =XLOOKUP($A17, INDIRECT("'"&M$1&"'!A:A"), INDIRECT("'"&M$1&"'!B:B"), "") -> 21.416667 | N17: =XLOOKUP($A17, INDIRECT("'"&N$1&"'!A:A"), INDIRECT("'"&N$1&"'!B:B"), "") -> 32.1 | O17: =XLOOKUP($A17, INDIRECT("'"&O$1&"'!A:A"), INDIRECT("'"&O$1&"'!B:B"), "") -> 3.0333333
A18: =EQ!A64 -> 950ed53de307960251af3e387e595945da87494d2d2edf58b103f58f4ccfef78 | B18: {=XLOOKUP(A18, Notes!A:A, Notes!B:B, "")} -> 43.28 | C18: =IFERROR(IMAGE(VLOOKUP(A18,DriveImages!A:C,3,FALSE),4,240,520),"") | D18: =IF($A18="","",IF(AND(N($G18)<=Params!$D$2,N($H18)<=Params!$E$2),"Peu actif",IF(AND(N($I18)>=Params!$F$4,N($E18)<=Params!$B$2,N($F18)<=Params!$C$2),"Efficace",IF(AND(N($F18)>=Params!$C$4,OR(N($I18)<=Params!$F$3,N($E18)>=Params!$B$4)),"Bloqué",IF(AND(OR(N($G18)>=Params!$D$4,N($H18)>=Params!$E$4),N($I18)<=Params!$F$3),"Persévérant",IF(AND(N($J18)>=Params!$G$4,OR(N($G18)<=Params!$D$3,N($H18)<=Params!$E$3)),"Sporadique","Intermédiaire")))))) -> Efficace | E18: {=XLOOKUP(A18, EQ!A:A, EQ!B:B, "")} -> 0 | F18: {=XLOOKUP(A18, RED!A:A, RED!B:B, "")} -> 0 | G18: =XLOOKUP(A18, INDIRECT("'"&G$1&"'!A:A"), INDIRECT("'"&G$1&"'!B:B"), "") -> 7 | H18: =XLOOKUP($A18, INDIRECT("'"&H$1&"'!A:A"), INDIRECT("'"&H$1&"'!B:B"), "") -> 3 | I18: =XLOOKUP($A18, INDIRECT("'"&I$1&"'!A:A"), INDIRECT("'"&I$1&"'!B:B"), "") -> 0.85714286 | J18: =XLOOKUP($A18, INDIRECT("'"&J$1&"'!A:A"), INDIRECT("'"&J$1&"'!B:B"), "") -> 0.33333333 | K18: =XLOOKUP($A18, INDIRECT("'"&K$1&"'!A:A"), INDIRECT("'"&K$1&"'!B:B"), "") -> 0.65306129 | L18: =XLOOKUP($A18, INDIRECT("'"&L$1&"'!A:A"), INDIRECT("'"&L$1&"'!B:B"), "") -> 5.3333333 | M18: =XLOOKUP($A18, INDIRECT("'"&M$1&"'!A:A"), INDIRECT("'"&M$1&"'!B:B"), "") -> 20.2 | N18: =XLOOKUP($A18, INDIRECT("'"&N$1&"'!A:A"), INDIRECT("'"&N$1&"'!B:B"), "") -> 33.033333 | O18: =XLOOKUP($A18, INDIRECT("'"&O$1&"'!A:A"), INDIRECT("'"&O$1&"'!B:B"), "") -> 10.8
A19: =EQ!A53 -> 7ce2ef889fd3931ddf910c65e58e6b626f658d713486152c54f9f8a0e6f37375 | B19: {=XLOOKUP(A19, Notes!A:A, Notes!B:B, "")} -> 74.78 | C19: =IFERROR(IMAGE(VLOOKUP(A19,DriveImages!A:C,3,FALSE),4,240,520),"") | D19: =IF($A19="","",IF(AND(N($G19)<=Params!$D$2,N($H19)<=Params!$E$2),"Peu actif",IF(AND(N($I19)>=Params!$F$4,N($E19)<=Params!$B$2,N($F19)<=Params!$C$2),"Efficace",IF(AND(N($F19)>=Params!$C$4,OR(N($I19)<=Params!$F$3,N($E19)>=Params!$B$4)),"Bloqué",IF(AND(OR(N($G19)>=Params!$D$4,N($H19)>=Params!$E$4),N($I19)<=Params!$F$3),"Persévérant",IF(AND(N($J19)>=Params!$G$4,OR(N($G19)<=Params!$D$3,N($H19)<=Params!$E$3)),"Sporadique","Intermédiaire")))))) -> Efficace | E19: {=XLOOKUP(A19, EQ!A:A, EQ!B:B, "")} -> 0.125 | F19: {=XLOOKUP(A19, RED!A:A, RED!B:B, "")} -> 0.0625 | G19: =XLOOKUP(A19, INDIRECT("'"&G$1&"'!A:A"), INDIRECT("'"&G$1&"'!B:B"), "") -> 22 | H19: =XLOOKUP($A19, INDIRECT("'"&H$1&"'!A:A"), INDIRECT("'"&H$1&"'!B:B"), "") -> 3 | I19: =XLOOKUP($A19, INDIRECT("'"&I$1&"'!A:A"), INDIRECT("'"&I$1&"'!B:B"), "") -> 0.86363636 | J19: =XLOOKUP($A19, INDIRECT("'"&J$1&"'!A:A"), INDIRECT("'"&J$1&"'!B:B"), "") -> 0.095238095 | K19: =XLOOKUP($A19, INDIRECT("'"&K$1&"'!A:A"), INDIRECT("'"&K$1&"'!B:B"), "") -> 0.81437473 | L19: =XLOOKUP($A19, INDIRECT("'"&L$1&"'!A:A"), INDIRECT("'"&L$1&"'!B:B"), "") -> 5.6333333 | M19: =XLOOKUP($A19, INDIRECT("'"&M$1&"'!A:A"), INDIRECT("'"&M$1&"'!B:B"), "") -> 45.233333 | N19: =XLOOKUP($A19, INDIRECT("'"&N$1&"'!A:A"), INDIRECT("'"&N$1&"'!B:B"), "") -> 7.7 | O19: =XLOOKUP($A19, INDIRECT("'"&O$1&"'!A:A"), INDIRECT("'"&O$1&"'!B:B"), "") -> 0.23333333
A20: =EQ!A8 -> 109c6e9ad83923fec425f5948621a620bad8efb25d507dbead8bcfa627bc55e6 | B20: {=XLOOKUP(A20, Notes!A:A, Notes!B:B, "")} -> 93.25 | C20: =IFERROR(IMAGE(VLOOKUP(A20,DriveImages!A:C,3,FALSE),4,240,520),"") | D20: =IF($A20="","",IF(AND(N($G20)<=Params!$D$2,N($H20)<=Params!$E$2),"Peu actif",IF(AND(N($I20)>=Params!$F$4,N($E20)<=Params!$B$2,N($F20)<=Params!$C$2),"Efficace",IF(AND(N($F20)>=Params!$C$4,OR(N($I20)<=Params!$F$3,N($E20)>=Params!$B$4)),"Bloqué",IF(AND(OR(N($G20)>=Params!$D$4,N($H20)>=Params!$E$4),N($I20)<=Params!$F$3),"Persévérant",IF(AND(N($J20)>=Params!$G$4,OR(N($G20)<=Params!$D$3,N($H20)<=Params!$E$3)),"Sporadique","Intermédiaire")))))) -> Efficace | E20: {=XLOOKUP(A20, EQ!A:A, EQ!B:B, "")} -> 0 | F20: {=XLOOKUP(A20, RED!A:A, RED!B:B, "")} -> 0 | G20: =XLOOKUP(A20, INDIRECT("'"&G$1&"'!A:A"), INDIRECT("'"&G$1&"'!B:B"), "") -> 18 | H20: =XLOOKUP($A20, INDIRECT("'"&H$1&"'!A:A"), INDIRECT("'"&H$1&"'!B:B"), "") -> 1 | I20: =XLOOKUP($A20, INDIRECT("'"&I$1&"'!A:A"), INDIRECT("'"&I$1&"'!B:B"), "") -> 0.77777778 | J20: =XLOOKUP($A20, INDIRECT("'"&J$1&"'!A:A"), INDIRECT("'"&J$1&"'!B:B"), "") -> 0 | K20: =XLOOKUP($A20, INDIRECT("'"&K$1&"'!A:A"), INDIRECT("'"&K$1&"'!B:B"), "") -> 0.73544978 | L20: =XLOOKUP($A20, INDIRECT("'"&L$1&"'!A:A"), INDIRECT("'"&L$1&"'!B:B"), "") -> 5.6666667 | M20: =XLOOKUP($A20, INDIRECT("'"&M$1&"'!A:A"), INDIRECT("'"&M$1&"'!B:B"), "") -> 33.2 | N20: =XLOOKUP($A20, INDIRECT("'"&N$1&"'!A:A"), INDIRECT("'"&N$1&"'!B:B"), "") -> 19.7 | O20: =XLOOKUP($A20, INDIRECT("'"&O$1&"'!A:A"), INDIRECT("'"&O$1&"'!B:B"), "") -> 0.3
A21: =EQ!A98 -> e3d00c0bcfea6e4a68c5c4842d0bedac5e761cfa5be62ec60aae839f44a7f555 | B21: {=XLOOKUP(A21, Notes!A:A, Notes!B:B, "")} -> 62.59 | C21: =IFERROR(IMAGE(VLOOKUP(A21,DriveImages!A:C,3,FALSE),4,240,520),"") | D21: =IF($A21="","",IF(AND(N($G21)<=Params!$D$2,N($H21)<=Params!$E$2),"Peu actif",IF(AND(N($I21)>=Params!$F$4,N($E21)<=Params!$B$2,N($F21)<=Params!$C$2),"Efficace",IF(AND(N($F21)>=Params!$C$4,OR(N($I21)<=Params!$F$3,N($E21)>=Params!$B$4)),"Bloqué",IF(AND(OR(N($G21)>=Params!$D$4,N($H21)>=Params!$E$4),N($I21)<=Params!$F$3),"Persévérant",IF(AND(N($J21)>=Params!$G$4,OR(N($G21)<=Params!$D$3,N($H21)<=Params!$E$3)),"Sporadique","Intermédiaire")))))) -> Efficace | E21: {=XLOOKUP(A21, EQ!A:A, EQ!B:B, "")} -> 0 | F21: {=XLOOKUP(A21, RED!A:A, RED!B:B, "")} -> 0 | G21: =XLOOKUP(A21, INDIRECT("'"&G$1&"'!A:A"), INDIRECT("'"&G$1&"'!B:B"), "") -> 12 | H21: =XLOOKUP($A21, INDIRECT("'"&H$1&"'!A:A"), INDIRECT("'"&H$1&"'!B:B"), "") -> 3 | I21: =XLOOKUP($A21, INDIRECT("'"&I$1&"'!A:A"), INDIRECT("'"&I$1&"'!B:B"), "") -> 0.91666667 | J21: =XLOOKUP($A21, INDIRECT("'"&J$1&"'!A:A"), INDIRECT("'"&J$1&"'!B:B"), "") -> 0.18181818 | K21: =XLOOKUP($A21, INDIRECT("'"&K$1&"'!A:A"), INDIRECT("'"&K$1&"'!B:B"), "") -> 0.628788 | L21: =XLOOKUP($A21, INDIRECT("'"&L$1&"'!A:A"), INDIRECT("'"&L$1&"'!B:B"), "") -> 5.6666667 | M21: =XLOOKUP($A21, INDIRECT("'"&M$1&"'!A:A"), INDIRECT("'"&M$1&"'!B:B"), "") -> 34.283333 | N21: =XLOOKUP($A21, INDIRECT("'"&N$1&"'!A:A"), INDIRECT("'"&N$1&"'!B:B"), "") -> 18.616667 | O21: =XLOOKUP($A21, INDIRECT("'"&O$1&"'!A:A"), INDIRECT("'"&O$1&"'!B:B"), "") -> 6.7333333
A22: =EQ!A4 -> 091dc109aa58c7a670f4b61bc23df548fec73c05c7582dfb7c51f3a925d3618f | B22: {=XLOOKUP(A22, Notes!A:A, Notes!B:B, "")} -> 68.44 | C22: =IFERROR(IMAGE(VLOOKUP(A22,DriveImages!A:C,3,FALSE),4,240,520),"") | D22: =IF($A22="","",IF(AND(N($G22)<=Params!$D$2,N($H22)<=Params!$E$2),"Peu actif",IF(AND(N($I22)>=Params!$F$4,N($E22)<=Params!$B$2,N($F22)<=Params!$C$2),"Efficace",IF(AND(N($F22)>=Params!$C$4,OR(N($I22)<=Params!$F$3,N($E22)>=Params!$B$4)),"Bloqué",IF(AND(OR(N($G22)>=Params!$D$4,N($H22)>=Params!$E$4),N($I22)<=Params!$F$3),"Persévérant",IF(AND(N($J22)>=Params!$G$4,OR(N($G22)<=Params!$D$3,N($H22)<=Params!$E$3)),"Sporadique","Intermédiaire")))))) -> Efficace | E22: {=XLOOKUP(A22, EQ!A:A, EQ!B:B, "")} -> 0.045454545 | F22: {=XLOOKUP(A22, RED!A:A, RED!B:B, "")} -> 0.02272727 | G22: =XLOOKUP(A22, INDIRECT("'"&G$1&"'!A:A"), INDIRECT("'"&G$1&"'!B:B"), "") -> 29 | H22: =XLOOKUP($A22, INDIRECT("'"&H$1&"'!A:A"), INDIRECT("'"&H$1&"'!B:B"), "") -> 4 | I22: =XLOOKUP($A22, INDIRECT("'"&I$1&"'!A:A"), INDIRECT("'"&I$1&"'!B:B"), "") -> 0.89655172 | J22: =XLOOKUP($A22, INDIRECT("'"&J$1&"'!A:A"), INDIRECT("'"&J$1&"'!B:B"), "") -> 0.10714286 | K22: =XLOOKUP($A22, INDIRECT("'"&K$1&"'!A:A"), INDIRECT("'"&K$1&"'!B:B"), "") -> 0.87335797 | L22: =XLOOKUP($A22, INDIRECT("'"&L$1&"'!A:A"), INDIRECT("'"&L$1&"'!B:B"), "") -> 5.9166667 | M22: =XLOOKUP($A22, INDIRECT("'"&M$1&"'!A:A"), INDIRECT("'"&M$1&"'!B:B"), "") -> 45.6 | N22: =XLOOKUP($A22, INDIRECT("'"&N$1&"'!A:A"), INDIRECT("'"&N$1&"'!B:B"), "") -> 7.05 | O22: =XLOOKUP($A22, INDIRECT("'"&O$1&"'!A:A"), INDIRECT("'"&O$1&"'!B:B"), "") -> 1.15
A23: =EQ!A51 -> 7854ad4022596904b137ebbb044e0bbbd2f590b0dac7f5a46d9991f3c049d647 | B23: {=XLOOKUP(A23, Notes!A:A, Notes!B:B, "")} -> 45.5 | C23: =IFERROR(IMAGE(VLOOKUP(A23,DriveImages!A:C,3,FALSE),4,240,520),"") | D23: =IF($A23="","",IF(AND(N($G23)<=Params!$D$2,N($H23)<=Params!$E$2),"Peu actif",IF(AND(N($I23)>=Params!$F$4,N($E23)<=Params!$B$2,N($F23)<=Params!$C$2),"Efficace",IF(AND(N($F23)>=Params!$C$4,OR(N($I23)<=Params!$F$3,N($E23)>=Params!$B$4)),"Bloqué",IF(AND(OR(N($G23)>=Params!$D$4,N($H23)>=Params!$E$4),N($I23)<=Params!$F$3),"Persévérant",IF(AND(N($J23)>=Params!$G$4,OR(N($G23)<=Params!$D$3,N($H23)<=Params!$E$3)),"Sporadique","Intermédiaire")))))) -> Bloqué | E23: {=XLOOKUP(A23, EQ!A:A, EQ!B:B, "")} -> 1 | F23: {=XLOOKUP(A23, RED!A:A, RED!B:B, "")} -> 0.93333333 | G23: =XLOOKUP(A23, INDIRECT("'"&G$1&"'!A:A"), INDIRECT("'"&G$1&"'!B:B"), "") -> 16 | H23: =XLOOKUP($A23, INDIRECT("'"&H$1&"'!A:A"), INDIRECT("'"&H$1&"'!B:B"), "") -> 3 | I23: =XLOOKUP($A23, INDIRECT("'"&I$1&"'!A:A"), INDIRECT("'"&I$1&"'!B:B"), "") -> 0 | J23: =XLOOKUP($A23, INDIRECT("'"&J$1&"'!A:A"), INDIRECT("'"&J$1&"'!B:B"), "") -> 0.13333333 | K23: =XLOOKUP($A23, INDIRECT("'"&K$1&"'!A:A"), INDIRECT("'"&K$1&"'!B:B"), "") -> 0 | L23: =XLOOKUP($A23, INDIRECT("'"&L$1&"'!A:A"), INDIRECT("'"&L$1&"'!B:B"), "") -> 6.0666667 | M23: =XLOOKUP($A23, INDIRECT("'"&M$1&"'!A:A"), INDIRECT("'"&M$1&"'!B:B"), "") -> 36.25 | N23: =XLOOKUP($A23, INDIRECT("'"&N$1&"'!A:A"), INDIRECT("'"&N$1&"'!B:B"), "") -> 16.25 | O23: =XLOOKUP($A23, INDIRECT("'"&O$1&"'!A:A"), INDIRECT("'"&O$1&"'!B:B"), "") -> 60
A24: =EQ!A66 -> 95e604186e18386f749a6d26e0868477c65803267b7c4d7bf606f77b8bbe1da4 | B24: {=XLOOKUP(A24, Notes!A:A, Notes!B:B, "")} -> 60.89 | C24: =IFERROR(IMAGE(VLOOKUP(A24,DriveImages!A:C,3,FALSE),4,240,520),"") | D24: =IF($A24="","",IF(AND(N($G24)<=Params!$D$2,N($H24)<=Params!$E$2),"Peu actif",IF(AND(N($I24)>=Params!$F$4,N($E24)<=Params!$B$2,N($F24)<=Params!$C$2),"Efficace",IF(AND(N($F24)>=Params!$C$4,OR(N($I24)<=Params!$F$3,N($E24)>=Params!$B$4)),"Bloqué",IF(AND(OR(N($G24)>=Params!$D$4,N($H24)>=Params!$E$4),N($I24)<=Params!$F$3),"Persévérant",IF(AND(N($J24)>=Params!$G$4,OR(N($G24)<=Params!$D$3,N($H24)<=Params!$E$3)),"Sporadique","Intermédiaire")))))) -> Persévérant | E24: {=XLOOKUP(A24, EQ!A:A, EQ!B:B, "")} -> 0.57894737 | F24: {=XLOOKUP(A24, RED!A:A, RED!B:B, "")} -> 0.49649123 | G24: =XLOOKUP(A24, INDIRECT("'"&G$1&"'!A:A"), INDIRECT("'"&G$1&"'!B:B"), "") -> 23 | H24: =XLOOKUP($A24, INDIRECT("'"&H$1&"'!A:A"), INDIRECT("'"&H$1&"'!B:B"), "") -> 3 | I24: =XLOOKUP($A24, INDIRECT("'"&I$1&"'!A:A"), INDIRECT("'"&I$1&"'!B:B"), "") -> 0.39130435 | J24: =XLOOKUP($A24, INDIRECT("'"&J$1&"'!A:A"), INDIRECT("'"&J$1&"'!B:B"), "") -> 0.090909091 | K24: =XLOOKUP($A24, INDIRECT("'"&K$1&"'!A:A"), INDIRECT("'"&K$1&"'!B:B"), "") -> 0.32095596 | L24: =XLOOKUP($A24, INDIRECT("'"&L$1&"'!A:A"), INDIRECT("'"&L$1&"'!B:B"), "") -> 6.85 | M24: =XLOOKUP($A24, INDIRECT("'"&M$1&"'!A:A"), INDIRECT("'"&M$1&"'!B:B"), "") -> 44.716667 | N24: =XLOOKUP($A24, INDIRECT("'"&N$1&"'!A:A"), INDIRECT("'"&N$1&"'!B:B"), "") -> 7 | O24: =XLOOKUP($A24, INDIRECT("'"&O$1&"'!A:A"), INDIRECT("'"&O$1&"'!B:B"), "") -> 16.216667
A25: =EQ!A110 -> fcf731e2be9a1377e7aed9c84be49e59ff2b3595fd86235d37d58011462b8fcf | B25: {=XLOOKUP(A25, Notes!A:A, Notes!B:B, "")} -> 55.16 | C25: =IFERROR(IMAGE(VLOOKUP(A25,DriveImages!A:C,3,FALSE),4,240,520),"") | D25: =IF($A25="","",IF(AND(N($G25)<=Params!$D$2,N($H25)<=Params!$E$2),"Peu actif",IF(AND(N($I25)>=Params!$F$4,N($E25)<=Params!$B$2,N($F25)<=Params!$C$2),"Efficace",IF(AND(N($F25)>=Params!$C$4,OR(N($I25)<=Params!$F$3,N($E25)>=Params!$B$4)),"Bloqué",IF(AND(OR(N($G25)>=Params!$D$4,N($H25)>=Params!$E$4),N($I25)<=Params!$F$3),"Persévérant",IF(AND(N($J25)>=Params!$G$4,OR(N($G25)<=Params!$D$3,N($H25)<=Params!$E$3)),"Sporadique","Intermédiaire")))))) -> Bloqué | E25: {=XLOOKUP(A25, EQ!A:A, EQ!B:B, "")} -> 1 | F25: {=XLOOKUP(A25, RED!A:A, RED!B:B, "")} -> 0.90909091 | G25: =XLOOKUP(A25, INDIRECT("'"&G$1&"'!A:A"), INDIRECT("'"&G$1&"'!B:B"), "") -> 11 | H25: =XLOOKUP($A25, INDIRECT("'"&H$1&"'!A:A"), INDIRECT("'"&H$1&"'!B:B"), "") -> 2 | I25: =XLOOKUP($A25, INDIRECT("'"&I$1&"'!A:A"), INDIRECT("'"&I$1&"'!B:B"), "") -> 0 | J25: =XLOOKUP($A25, INDIRECT("'"&J$1&"'!A:A"), INDIRECT("'"&J$1&"'!B:B"), "") -> 0.1 | K25: =XLOOKUP($A25, INDIRECT("'"&K$1&"'!A:A"), INDIRECT("'"&K$1&"'!B:B"), "") -> 0 | L25: =XLOOKUP($A25, INDIRECT("'"&L$1&"'!A:A"), INDIRECT("'"&L$1&"'!B:B"), "") -> 7.3333333 | M25: =XLOOKUP($A25, INDIRECT("'"&M$1&"'!A:A"), INDIRECT("'"&M$1&"'!B:B"), "") -> 23.033333 | N25: =XLOOKUP($A25, INDIRECT("'"&N$1&"'!A:A"), INDIRECT("'"&N$1&"'!B:B"), "") -> 28.2 | O25: =XLOOKUP($A25, INDIRECT("'"&O$1&"'!A:A"), INDIRECT("'"&O$1&"'!B:B"), "") -> 60
A26: =EQ!A95 -> d981675479ab443031cba32f40c3dca9e031547c59346a4c0ea7c624c054d936 | B26: {=XLOOKUP(A26, Notes!A:A, Notes!B:B, "")} -> 54.94 | C26: =IFERROR(IMAGE(VLOOKUP(A26,DriveImages!A:C,3,FALSE),4,240,520),"") | D26: =IF($A26="","",IF(AND(N($G26)<=Params!$D$2,N($H26)<=Params!$E$2),"Peu actif",IF(AND(N($I26)>=Params!$F$4,N($E26)<=Params!$B$2,N($F26)<=Params!$C$2),"Efficace",IF(AND(N($F26)>=Params!$C$4,OR(N($I26)<=Params!$F$3,N($E26)>=Params!$B$4)),"Bloqué",IF(AND(OR(N($G26)>=Params!$D$4,N($H26)>=Params!$E$4),N($I26)<=Params!$F$3),"Persévérant",IF(AND(N($J26)>=Params!$G$4,OR(N($G26)<=Params!$D$3,N($H26)<=Params!$E$3)),"Sporadique","Intermédiaire")))))) -> Bloqué | E26: {=XLOOKUP(A26, EQ!A:A, EQ!B:B, "")} -> 0.75 | F26: {=XLOOKUP(A26, RED!A:A, RED!B:B, "")} -> 0.61607143 | G26: =XLOOKUP(A26, INDIRECT("'"&G$1&"'!A:A"), INDIRECT("'"&G$1&"'!B:B"), "") -> 14 | H26: =XLOOKUP($A26, INDIRECT("'"&H$1&"'!A:A"), INDIRECT("'"&H$1&"'!B:B"), "") -> 2 | I26: =XLOOKUP($A26, INDIRECT("'"&I$1&"'!A:A"), INDIRECT("'"&I$1&"'!B:B"), "") -> 0.21428571 | J26: =XLOOKUP($A26, INDIRECT("'"&J$1&"'!A:A"), INDIRECT("'"&J$1&"'!B:B"), "") -> 0.076923077 | K26: =XLOOKUP($A26, INDIRECT("'"&K$1&"'!A:A"), INDIRECT("'"&K$1&"'!B:B"), "") -> 0.19565214 | L26: =XLOOKUP($A26, INDIRECT("'"&L$1&"'!A:A"), INDIRECT("'"&L$1&"'!B:B"), "") -> 7.3833333 | M26: =XLOOKUP($A26, INDIRECT("'"&M$1&"'!A:A"), INDIRECT("'"&M$1&"'!B:B"), "") -> 18.683333 | N26: =XLOOKUP($A26, INDIRECT("'"&N$1&"'!A:A"), INDIRECT("'"&N$1&"'!B:B"), "") -> 32.5 | O26: =XLOOKUP($A26, INDIRECT("'"&O$1&"'!A:A"), INDIRECT("'"&O$1&"'!B:B"), "") -> 5.35
A27: =EQ!A72 -> ad1624c5c3a02a3a3b3dcb044b912998b64ca2e7cd54abe79476f86a41a3234b | B27: {=XLOOKUP(A27, Notes!A:A, Notes!B:B, "")} -> 55.71 | C27: =IFERROR(IMAGE(VLOOKUP(A27,DriveImages!A:C,3,FALSE),4,240,520),"") | D27: =IF($A27="","",IF(AND(N($G27)<=Params!$D$2,N($H27)<=Params!$E$2),"Peu actif",IF(AND(N($I27)>=Params!$F$4,N($E27)<=Params!$B$2,N($F27)<=Params!$C$2),"Efficace",IF(AND(N($F27)>=Params!$C$4,OR(N($I27)<=Params!$F$3,N($E27)>=Params!$B$4)),"Bloqué",IF(AND(OR(N($G27)>=Params!$D$4,N($H27)>=Params!$E$4),N($I27)<=Params!$F$3),"Persévérant",IF(AND(N($J27)>=Params!$G$4,OR(N($G27)<=Params!$D$3,N($H27)<=Params!$E$3)),"Sporadique","Intermédiaire")))))) -> Efficace | E27: {=XLOOKUP(A27, EQ!A:A, EQ!B:B, "")} -> 0 | F27: {=XLOOKUP(A27, RED!A:A, RED!B:B, "")} -> 0 | G27: =XLOOKUP(A27, INDIRECT("'"&G$1&"'!A:A"), INDIRECT("'"&G$1&"'!B:B"), "") -> 7 | H27: =XLOOKUP($A27, INDIRECT("'"&H$1&"'!A:A"), INDIRECT("'"&H$1&"'!B:B"), "") -> 3 | I27: =XLOOKUP($A27, INDIRECT("'"&I$1&"'!A:A"), INDIRECT("'"&I$1&"'!B:B"), "") -> 0.85714286 | J27: =XLOOKUP($A27, INDIRECT("'"&J$1&"'!A:A"), INDIRECT("'"&J$1&"'!B:B"), "") -> 0.33333333 | K27: =XLOOKUP($A27, INDIRECT("'"&K$1&"'!A:A"), INDIRECT("'"&K$1&"'!B:B"), "") -> 0.63428571 | L27: =XLOOKUP($A27, INDIRECT("'"&L$1&"'!A:A"), INDIRECT("'"&L$1&"'!B:B"), "") -> 7.8 | M27: =XLOOKUP($A27, INDIRECT("'"&M$1&"'!A:A"), INDIRECT("'"&M$1&"'!B:B"), "") -> 44.216667 | N27: =XLOOKUP($A27, INDIRECT("'"&N$1&"'!A:A"), INDIRECT("'"&N$1&"'!B:B"), "") -> 6.55 | O27: =XLOOKUP($A27, INDIRECT("'"&O$1&"'!A:A"), INDIRECT("'"&O$1&"'!B:B"), "") -> 0
A28: =EQ!A59 -> 8c496c831c776415f7491e6de8457bb88c62eefeff270c8e0dbec39b78b9413d | B28: {=XLOOKUP(A28, Notes!A:A, Notes!B:B, "")} -> 72.99 | C28: =IFERROR(IMAGE(VLOOKUP(A28,DriveImages!A:C,3,FALSE),4,240,520),"") | D28: =IF($A28="","",IF(AND(N($G28)<=Params!$D$2,N($H28)<=Params!$E$2),"Peu actif",IF(AND(N($I28)>=Params!$F$4,N($E28)<=Params!$B$2,N($F28)<=Params!$C$2),"Efficace",IF(AND(N($F28)>=Params!$C$4,OR(N($I28)<=Params!$F$3,N($E28)>=Params!$B$4)),"Bloqué",IF(AND(OR(N($G28)>=Params!$D$4,N($H28)>=Params!$E$4),N($I28)<=Params!$F$3),"Persévérant",IF(AND(N($J28)>=Params!$G$4,OR(N($G28)<=Params!$D$3,N($H28)<=Params!$E$3)),"Sporadique","Intermédiaire")))))) -> Sporadique | E28: {=XLOOKUP(A28, EQ!A:A, EQ!B:B, "")} -> 0 | F28: {=XLOOKUP(A28, RED!A:A, RED!B:B, "")} -> 0 | G28: =XLOOKUP(A28, INDIRECT("'"&G$1&"'!A:A"), INDIRECT("'"&G$1&"'!B:B"), "") -> 10 | H28: =XLOOKUP($A28, INDIRECT("'"&H$1&"'!A:A"), INDIRECT("'"&H$1&"'!B:B"), "") -> 3 | I28: =XLOOKUP($A28, INDIRECT("'"&I$1&"'!A:A"), INDIRECT("'"&I$1&"'!B:B"), "") -> 0.6 | J28: =XLOOKUP($A28, INDIRECT("'"&J$1&"'!A:A"), INDIRECT("'"&J$1&"'!B:B"), "") -> 0.22222222 | K28: =XLOOKUP($A28, INDIRECT("'"&K$1&"'!A:A"), INDIRECT("'"&K$1&"'!B:B"), "") -> 0.5466667 | L28: =XLOOKUP($A28, INDIRECT("'"&L$1&"'!A:A"), INDIRECT("'"&L$1&"'!B:B"), "") -> 7.85 | M28: =XLOOKUP($A28, INDIRECT("'"&M$1&"'!A:A"), INDIRECT("'"&M$1&"'!B:B"), "") -> 23.9 | N28: =XLOOKUP($A28, INDIRECT("'"&N$1&"'!A:A"), INDIRECT("'"&N$1&"'!B:B"), "") -> 26.816667 | O28: =XLOOKUP($A28, INDIRECT("'"&O$1&"'!A:A"), INDIRECT("'"&O$1&"'!B:B"), "") -> 0.28333333
A29: =EQ!A38 -> 5e8589d4cd67c4b88f84e378d72875ccd07de5c9e20cc666bbf217de9d3567b4 | B29: {=XLOOKUP(A29, Notes!A:A, Notes!B:B, "")} -> 89.45 | C29: =IFERROR(IMAGE(VLOOKUP(A29,DriveImages!A:C,3,FALSE),4,240,520),"") | D29: =IF($A29="","",IF(AND(N($G29)<=Params!$D$2,N($H29)<=Params!$E$2),"Peu actif",IF(AND(N($I29)>=Params!$F$4,N($E29)<=Params!$B$2,N($F29)<=Params!$C$2),"Efficace",IF(AND(N($F29)>=Params!$C$4,OR(N($I29)<=Params!$F$3,N($E29)>=Params!$B$4)),"Bloqué",IF(AND(OR(N($G29)>=Params!$D$4,N($H29)>=Params!$E$4),N($I29)<=Params!$F$3),"Persévérant",IF(AND(N($J29)>=Params!$G$4,OR(N($G29)<=Params!$D$3,N($H29)<=Params!$E$3)),"Sporadique","Intermédiaire")))))) -> Efficace | E29: {=XLOOKUP(A29, EQ!A:A, EQ!B:B, "")} -> 0 | F29: {=XLOOKUP(A29, RED!A:A, RED!B:B, "")} -> 0 | G29: =XLOOKUP(A29, INDIRECT("'"&G$1&"'!A:A"), INDIRECT("'"&G$1&"'!B:B"), "") -> 23 | H29: =XLOOKUP($A29, INDIRECT("'"&H$1&"'!A:A"), INDIRECT("'"&H$1&"'!B:B"), "") -> 3 | I29: =XLOOKUP($A29, INDIRECT("'"&I$1&"'!A:A"), INDIRECT("'"&I$1&"'!B:B"), "") -> 0.86956522 | J29: =XLOOKUP($A29, INDIRECT("'"&J$1&"'!A:A"), INDIRECT("'"&J$1&"'!B:B"), "") -> 0.090909091 | K29: =XLOOKUP($A29, INDIRECT("'"&K$1&"'!A:A"), INDIRECT("'"&K$1&"'!B:B"), "") -> 0.6788357 | L29: =XLOOKUP($A29, INDIRECT("'"&L$1&"'!A:A"), INDIRECT("'"&L$1&"'!B:B"), "") -> 8.9333333 | M29: =XLOOKUP($A29, INDIRECT("'"&M$1&"'!A:A"), INDIRECT("'"&M$1&"'!B:B"), "") -> 38.35 | N29: =XLOOKUP($A29, INDIRECT("'"&N$1&"'!A:A"), INDIRECT("'"&N$1&"'!B:B"), "") -> 11.283333 | O29: =XLOOKUP($A29, INDIRECT("'"&O$1&"'!A:A"), INDIRECT("'"&O$1&"'!B:B"), "") -> 5.25
A30: =EQ!A37 -> 5d60fc4768a0d01e3d533d2d5353bdffb58877bc2971bc7053a54071fa4c2f49 | B30: {=XLOOKUP(A30, Notes!A:A, Notes!B:B, "")} -> 75.96 | C30: =IFERROR(IMAGE(VLOOKUP(A30,DriveImages!A:C,3,FALSE),4,240,520),"") | D30: =IF($A30="","",IF(AND(N($G30)<=Params!$D$2,N($H30)<=Params!$E$2),"Peu actif",IF(AND(N($I30)>=Params!$F$4,N($E30)<=Params!$B$2,N($F30)<=Params!$C$2),"Efficace",IF(AND(N($F30)>=Params!$C$4,OR(N($I30)<=Params!$F$3,N($E30)>=Params!$B$4)),"Bloqué",IF(AND(OR(N($G30)>=Params!$D$4,N($H30)>=Params!$E$4),N($I30)<=Params!$F$3),"Persévérant",IF(AND(N($J30)>=Params!$G$4,OR(N($G30)<=Params!$D$3,N($H30)<=Params!$E$3)),"Sporadique","Intermédiaire")))))) -> Intermédiaire | E30: {=XLOOKUP(A30, EQ!A:A, EQ!B:B, "")} -> 0.27777778 | F30: {=XLOOKUP(A30, RED!A:A, RED!B:B, "")} -> 0.18055556 | G30: =XLOOKUP(A30, INDIRECT("'"&G$1&"'!A:A"), INDIRECT("'"&G$1&"'!B:B"), "") -> 25 | H30: =XLOOKUP($A30, INDIRECT("'"&H$1&"'!A:A"), INDIRECT("'"&H$1&"'!B:B"), "") -> 3 | I30: =XLOOKUP($A30, INDIRECT("'"&I$1&"'!A:A"), INDIRECT("'"&I$1&"'!B:B"), "") -> 0.52 | J30: =XLOOKUP($A30, INDIRECT("'"&J$1&"'!A:A"), INDIRECT("'"&J$1&"'!B:B"), "") -> 0.083333333 | K30: =XLOOKUP($A30, INDIRECT("'"&K$1&"'!A:A"), INDIRECT("'"&K$1&"'!B:B"), "") -> 0.4624638 | L30: =XLOOKUP($A30, INDIRECT("'"&L$1&"'!A:A"), INDIRECT("'"&L$1&"'!B:B"), "") -> 9.0833333 | M30: =XLOOKUP($A30, INDIRECT("'"&M$1&"'!A:A"), INDIRECT("'"&M$1&"'!B:B"), "") -> 42.166667 | N30: =XLOOKUP($A30, INDIRECT("'"&N$1&"'!A:A"), INDIRECT("'"&N$1&"'!B:B"), "") -> 7.3166667 | O30: =XLOOKUP($A30, INDIRECT("'"&O$1&"'!A:A"), INDIRECT("'"&O$1&"'!B:B"), "") -> 11.166667
A31: =EQ!A55 -> 8630de5bd303be8b63ba99b787f0f5ed4422765c8917b234cb8a2af6b762ca1d | B31: {=XLOOKUP(A31, Notes!A:A, Notes!B:B, "")} -> 34.25 | C31: =IFERROR(IMAGE(VLOOKUP(A31,DriveImages!A:C,3,FALSE),4,240,520),"") | D31: =IF($A31="","",IF(AND(N($G31)<=Params!$D$2,N($H31)<=Params!$E$2),"Peu actif",IF(AND(N($I31)>=Params!$F$4,N($E31)<=Params!$B$2,N($F31)<=Params!$C$2),"Efficace",IF(AND(N($F31)>=Params!$C$4,OR(N($I31)<=Params!$F$3,N($E31)>=Params!$B$4)),"Bloqué",IF(AND(OR(N($G31)>=Params!$D$4,N($H31)>=Params!$E$4),N($I31)<=Params!$F$3),"Persévérant",IF(AND(N($J31)>=Params!$G$4,OR(N($G31)<=Params!$D$3,N($H31)<=Params!$E$3)),"Sporadique","Intermédiaire")))))) -> Bloqué | E31: {=XLOOKUP(A31, EQ!A:A, EQ!B:B, "")} -> 0.7 | F31: {=XLOOKUP(A31, RED!A:A, RED!B:B, "")} -> 0.6125 | G31: =XLOOKUP(A31, INDIRECT("'"&G$1&"'!A:A"), INDIRECT("'"&G$1&"'!B:B"), "") -> 11 | H31: =XLOOKUP($A31, INDIRECT("'"&H$1&"'!A:A"), INDIRECT("'"&H$1&"'!B:B"), "") -> 3 | I31: =XLOOKUP($A31, INDIRECT("'"&I$1&"'!A:A"), INDIRECT("'"&I$1&"'!B:B"), "") -> 0.27272727 | J31: =XLOOKUP($A31, INDIRECT("'"&J$1&"'!A:A"), INDIRECT("'"&J$1&"'!B:B"), "") -> 0.2 | K31: =XLOOKUP($A31, INDIRECT("'"&K$1&"'!A:A"), INDIRECT("'"&K$1&"'!B:B"), "") -> 0.24901191 | L31: =XLOOKUP($A31, INDIRECT("'"&L$1&"'!A:A"), INDIRECT("'"&L$1&"'!B:B"), "") -> 9.55 | M31: =XLOOKUP($A31, INDIRECT("'"&M$1&"'!A:A"), INDIRECT("'"&M$1&"'!B:B"), "") -> 37.9 | N31: =XLOOKUP($A31, INDIRECT("'"&N$1&"'!A:A"), INDIRECT("'"&N$1&"'!B:B"), "") -> 11.116667 | O31: =XLOOKUP($A31, INDIRECT("'"&O$1&"'!A:A"), INDIRECT("'"&O$1&"'!B:B"), "") -> 60
A32: =EQ!A57 -> 88faa9b4e525ea83f6efab60ae88469da5222f0b0f52c16c3af4e4763baa1daf | B32: {=XLOOKUP(A32, Notes!A:A, Notes!B:B, "")} -> 59.75 | C32: =IFERROR(IMAGE(VLOOKUP(A32,DriveImages!A:C,3,FALSE),4,240,520),"") | D32: =IF($A32="","",IF(AND(N($G32)<=Params!$D$2,N($H32)<=Params!$E$2),"Peu actif",IF(AND(N($I32)>=Params!$F$4,N($E32)<=Params!$B$2,N($F32)<=Params!$C$2),"Efficace",IF(AND(N($F32)>=Params!$C$4,OR(N($I32)<=Params!$F$3,N($E32)>=Params!$B$4)),"Bloqué",IF(AND(OR(N($G32)>=Params!$D$4,N($H32)>=Params!$E$4),N($I32)<=Params!$F$3),"Persévérant",IF(AND(N($J32)>=Params!$G$4,OR(N($G32)<=Params!$D$3,N($H32)<=Params!$E$3)),"Sporadique","Intermédiaire")))))) -> Intermédiaire | E32: {=XLOOKUP(A32, EQ!A:A, EQ!B:B, "")} -> 0.16666667 | F32: {=XLOOKUP(A32, RED!A:A, RED!B:B, "")} -> 0.11111111 | G32: =XLOOKUP(A32, INDIRECT("'"&G$1&"'!A:A"), INDIRECT("'"&G$1&"'!B:B"), "") -> 14 | H32: =XLOOKUP($A32, INDIRECT("'"&H$1&"'!A:A"), INDIRECT("'"&H$1&"'!B:B"), "") -> 1 | I32: =XLOOKUP($A32, INDIRECT("'"&I$1&"'!A:A"), INDIRECT("'"&I$1&"'!B:B"), "") -> 0.64285714 | J32: =XLOOKUP($A32, INDIRECT("'"&J$1&"'!A:A"), INDIRECT("'"&J$1&"'!B:B"), "") -> 0 | K32: =XLOOKUP($A32, INDIRECT("'"&K$1&"'!A:A"), INDIRECT("'"&K$1&"'!B:B"), "") -> 0.48701307 | L32: =XLOOKUP($A32, INDIRECT("'"&L$1&"'!A:A"), INDIRECT("'"&L$1&"'!B:B"), "") -> 9.7833333 | M32: =XLOOKUP($A32, INDIRECT("'"&M$1&"'!A:A"), INDIRECT("'"&M$1&"'!B:B"), "") -> 10.05 | N32: =XLOOKUP($A32, INDIRECT("'"&N$1&"'!A:A"), INDIRECT("'"&N$1&"'!B:B"), "") -> 38.733333 | O32: =XLOOKUP($A32, INDIRECT("'"&O$1&"'!A:A"), INDIRECT("'"&O$1&"'!B:B"), "") -> 2.5333333
A33: =EQ!A108 -> fa7805c1d46ef49851de43750a665a993eef750b560159967106d3b96821759c | B33: {=XLOOKUP(A33, Notes!A:A, Notes!B:B, "")} -> 69.63 | C33: =IFERROR(IMAGE(VLOOKUP(A33,DriveImages!A:C,3,FALSE),4,240,520),"") | D33: =IF($A33="","",IF(AND(N($G33)<=Params!$D$2,N($H33)<=Params!$E$2),"Peu actif",IF(AND(N($I33)>=Params!$F$4,N($E33)<=Params!$B$2,N($F33)<=Params!$C$2),"Efficace",IF(AND(N($F33)>=Params!$C$4,OR(N($I33)<=Params!$F$3,N($E33)>=Params!$B$4)),"Bloqué",IF(AND(OR(N($G33)>=Params!$D$4,N($H33)>=Params!$E$4),N($I33)<=Params!$F$3),"Persévérant",IF(AND(N($J33)>=Params!$G$4,OR(N($G33)<=Params!$D$3,N($H33)<=Params!$E$3)),"Sporadique","Intermédiaire")))))) -> Intermédiaire | E33: {=XLOOKUP(A33, EQ!A:A, EQ!B:B, "")} -> 0.5 | F33: {=XLOOKUP(A33, RED!A:A, RED!B:B, "")} -> 0.34027778 | G33: =XLOOKUP(A33, INDIRECT("'"&G$1&"'!A:A"), INDIRECT("'"&G$1&"'!B:B"), "") -> 17 | H33: =XLOOKUP($A33, INDIRECT("'"&H$1&"'!A:A"), INDIRECT("'"&H$1&"'!B:B"), "") -> 2 | I33: =XLOOKUP($A33, INDIRECT("'"&I$1&"'!A:A"), INDIRECT("'"&I$1&"'!B:B"), "") -> 0.41176471 | J33: =XLOOKUP($A33, INDIRECT("'"&J$1&"'!A:A"), INDIRECT("'"&J$1&"'!B:B"), "") -> 0.0625 | K33: =XLOOKUP($A33, INDIRECT("'"&K$1&"'!A:A"), INDIRECT("'"&K$1&"'!B:B"), "") -> 0.31181324 | L33: =XLOOKUP($A33, INDIRECT("'"&L$1&"'!A:A"), INDIRECT("'"&L$1&"'!B:B"), "") -> 10.166667 | M33: =XLOOKUP($A33, INDIRECT("'"&M$1&"'!A:A"), INDIRECT("'"&M$1&"'!B:B"), "") -> 27.183333 | N33: =XLOOKUP($A33, INDIRECT("'"&N$1&"'!A:A"), INDIRECT("'"&N$1&"'!B:B"), "") -> 21.216667 | O33: =XLOOKUP($A33, INDIRECT("'"&O$1&"'!A:A"), INDIRECT("'"&O$1&"'!B:B"), "") -> 20.466667
A34: =EQ!A3 -> 080e819b7f2ec7fdf5df10abc0092a6ae39db49584244ea555a9ce18c8d57c53 | B34: {=XLOOKUP(A34, Notes!A:A, Notes!B:B, "")} -> 56.19 | C34: =IFERROR(IMAGE(VLOOKUP(A34,DriveImages!A:C,3,FALSE),4,240,520),"") | D34: =IF($A34="","",IF(AND(N($G34)<=Params!$D$2,N($H34)<=Params!$E$2),"Peu actif",IF(AND(N($I34)>=Params!$F$4,N($E34)<=Params!$B$2,N($F34)<=Params!$C$2),"Efficace",IF(AND(N($F34)>=Params!$C$4,OR(N($I34)<=Params!$F$3,N($E34)>=Params!$B$4)),"Bloqué",IF(AND(OR(N($G34)>=Params!$D$4,N($H34)>=Params!$E$4),N($I34)<=Params!$F$3),"Persévérant",IF(AND(N($J34)>=Params!$G$4,OR(N($G34)<=Params!$D$3,N($H34)<=Params!$E$3)),"Sporadique","Intermédiaire")))))) -> Peu actif | E34: {=XLOOKUP(A34, EQ!A:A, EQ!B:B, "")} -> 0.75 | F34: {=XLOOKUP(A34, RED!A:A, RED!B:B, "")} -> 0.5625 | G34: =XLOOKUP(A34, INDIRECT("'"&G$1&"'!A:A"), INDIRECT("'"&G$1&"'!B:B"), "") -> 5 | H34: =XLOOKUP($A34, INDIRECT("'"&H$1&"'!A:A"), INDIRECT("'"&H$1&"'!B:B"), "") -> 1 | I34: =XLOOKUP($A34, INDIRECT("'"&I$1&"'!A:A"), INDIRECT("'"&I$1&"'!B:B"), "") -> 0.2 | J34: =XLOOKUP($A34, INDIRECT("'"&J$1&"'!A:A"), INDIRECT("'"&J$1&"'!B:B"), "") -> 0 | K34: =XLOOKUP($A34, INDIRECT("'"&K$1&"'!A:A"), INDIRECT("'"&K$1&"'!B:B"), "") -> 0.2 | L34: =XLOOKUP($A34, INDIRECT("'"&L$1&"'!A:A"), INDIRECT("'"&L$1&"'!B:B"), "") -> 10.216667 | M34: =XLOOKUP($A34, INDIRECT("'"&M$1&"'!A:A"), INDIRECT("'"&M$1&"'!B:B"), "") -> 4.5666667 | N34: =XLOOKUP($A34, INDIRECT("'"&N$1&"'!A:A"), INDIRECT("'"&N$1&"'!B:B"), "") -> 43.783333 | O34: =XLOOKUP($A34, INDIRECT("'"&O$1&"'!A:A"), INDIRECT("'"&O$1&"'!B:B"), "") -> 4.5666667
A35: =EQ!A102 -> effa5fafd71a87510e477792561dc4c6a0d7a624d93f5ee78db77ac7c2a41d63 | B35: {=XLOOKUP(A35, Notes!A:A, Notes!B:B, "")} -> 63.66 | C35: =IFERROR(IMAGE(VLOOKUP(A35,DriveImages!A:C,3,FALSE),4,240,520),"") | D35: =IF($A35="","",IF(AND(N($G35)<=Params!$D$2,N($H35)<=Params!$E$2),"Peu actif",IF(AND(N($I35)>=Params!$F$4,N($E35)<=Params!$B$2,N($F35)<=Params!$C$2),"Efficace",IF(AND(N($F35)>=Params!$C$4,OR(N($I35)<=Params!$F$3,N($E35)>=Params!$B$4)),"Bloqué",IF(AND(OR(N($G35)>=Params!$D$4,N($H35)>=Params!$E$4),N($I35)<=Params!$F$3),"Persévérant",IF(AND(N($J35)>=Params!$G$4,OR(N($G35)<=Params!$D$3,N($H35)<=Params!$E$3)),"Sporadique","Intermédiaire")))))) -> Intermédiaire | E35: {=XLOOKUP(A35, EQ!A:A, EQ!B:B, "")} -> 0.21428571 | F35: {=XLOOKUP(A35, RED!A:A, RED!B:B, "")} -> 0.16190476 | G35: =XLOOKUP(A35, INDIRECT("'"&G$1&"'!A:A"), INDIRECT("'"&G$1&"'!B:B"), "") -> 33 | H35: =XLOOKUP($A35, INDIRECT("'"&H$1&"'!A:A"), INDIRECT("'"&H$1&"'!B:B"), "") -> 2 | I35: =XLOOKUP($A35, INDIRECT("'"&I$1&"'!A:A"), INDIRECT("'"&I$1&"'!B:B"), "") -> 0.6969697 | J35: =XLOOKUP($A35, INDIRECT("'"&J$1&"'!A:A"), INDIRECT("'"&J$1&"'!B:B"), "") -> 0.03125 | K35: =XLOOKUP($A35, INDIRECT("'"&K$1&"'!A:A"), INDIRECT("'"&K$1&"'!B:B"), "") -> 0.55661003 | L35: =XLOOKUP($A35, INDIRECT("'"&L$1&"'!A:A"), INDIRECT("'"&L$1&"'!B:B"), "") -> 10.25 | M35: =XLOOKUP($A35, INDIRECT("'"&M$1&"'!A:A"), INDIRECT("'"&M$1&"'!B:B"), "") -> 41.566667 | N35: =XLOOKUP($A35, INDIRECT("'"&N$1&"'!A:A"), INDIRECT("'"&N$1&"'!B:B"), "") -> 6.75 | O35: =XLOOKUP($A35, INDIRECT("'"&O$1&"'!A:A"), INDIRECT("'"&O$1&"'!B:B"), "") -> 0
A36: =EQ!A101 -> eefcecf5c7183df8d369a35df238dd9fd990564264dcadc7bafacbafbef888ac | B36: {=XLOOKUP(A36, Notes!A:A, Notes!B:B, "")} -> 39.81 | C36: =IFERROR(IMAGE(VLOOKUP(A36,DriveImages!A:C,3,FALSE),4,240,520),"") | D36: =IF($A36="","",IF(AND(N($G36)<=Params!$D$2,N($H36)<=Params!$E$2),"Peu actif",IF(AND(N($I36)>=Params!$F$4,N($E36)<=Params!$B$2,N($F36)<=Params!$C$2),"Efficace",IF(AND(N($F36)>=Params!$C$4,OR(N($I36)<=Params!$F$3,N($E36)>=Params!$B$4)),"Bloqué",IF(AND(OR(N($G36)>=Params!$D$4,N($H36)>=Params!$E$4),N($I36)<=Params!$F$3),"Persévérant",IF(AND(N($J36)>=Params!$G$4,OR(N($G36)<=Params!$D$3,N($H36)<=Params!$E$3)),"Sporadique","Intermédiaire")))))) -> Bloqué | E36: {=XLOOKUP(A36, EQ!A:A, EQ!B:B, "")} -> 1 | F36: {=XLOOKUP(A36, RED!A:A, RED!B:B, "")} -> 0.83333333 | G36: =XLOOKUP(A36, INDIRECT("'"&G$1&"'!A:A"), INDIRECT("'"&G$1&"'!B:B"), "") -> 6 | H36: =XLOOKUP($A36, INDIRECT("'"&H$1&"'!A:A"), INDIRECT("'"&H$1&"'!B:B"), "") -> 1 | I36: =XLOOKUP($A36, INDIRECT("'"&I$1&"'!A:A"), INDIRECT("'"&I$1&"'!B:B"), "") -> 0 | J36: =XLOOKUP($A36, INDIRECT("'"&J$1&"'!A:A"), INDIRECT("'"&J$1&"'!B:B"), "") -> 0 | K36: =XLOOKUP($A36, INDIRECT("'"&K$1&"'!A:A"), INDIRECT("'"&K$1&"'!B:B"), "") -> 0 | L36: =XLOOKUP($A36, INDIRECT("'"&L$1&"'!A:A"), INDIRECT("'"&L$1&"'!B:B"), "") -> 10.416667 | M36: =XLOOKUP($A36, INDIRECT("'"&M$1&"'!A:A"), INDIRECT("'"&M$1&"'!B:B"), "") -> 4.1833333 | N36: =XLOOKUP($A36, INDIRECT("'"&N$1&"'!A:A"), INDIRECT("'"&N$1&"'!B:B"), "") -> 43.966667 | O36: =XLOOKUP($A36, INDIRECT("'"&O$1&"'!A:A"), INDIRECT("'"&O$1&"'!B:B"), "") -> 60
A37: =EQ!A13 -> 23d73ca299f02110f10fe0b18902fd2ea5ad124d3a061f110083353b3899c369 | B37: {=XLOOKUP(A37, Notes!A:A, Notes!B:B, "")} -> 89.25 | C37: =IFERROR(IMAGE(VLOOKUP(A37,DriveImages!A:C,3,FALSE),4,240,520),"") | D37: =IF($A37="","",IF(AND(N($G37)<=Params!$D$2,N($H37)<=Params!$E$2),"Peu actif",IF(AND(N($I37)>=Params!$F$4,N($E37)<=Params!$B$2,N($F37)<=Params!$C$2),"Efficace",IF(AND(N($F37)>=Params!$C$4,OR(N($I37)<=Params!$F$3,N($E37)>=Params!$B$4)),"Bloqué",IF(AND(OR(N($G37)>=Params!$D$4,N($H37)>=Params!$E$4),N($I37)<=Params!$F$3),"Persévérant",IF(AND(N($J37)>=Params!$G$4,OR(N($G37)<=Params!$D$3,N($H37)<=Params!$E$3)),"Sporadique","Intermédiaire")))))) -> Intermédiaire | E37: {=XLOOKUP(A37, EQ!A:A, EQ!B:B, "")} -> 0.28571429 | F37: {=XLOOKUP(A37, RED!A:A, RED!B:B, "")} -> 0.16666667 | G37: =XLOOKUP(A37, INDIRECT("'"&G$1&"'!A:A"), INDIRECT("'"&G$1&"'!B:B"), "") -> 18 | H37: =XLOOKUP($A37, INDIRECT("'"&H$1&"'!A:A"), INDIRECT("'"&H$1&"'!B:B"), "") -> 3 | I37: =XLOOKUP($A37, INDIRECT("'"&I$1&"'!A:A"), INDIRECT("'"&I$1&"'!B:B"), "") -> 0.55555556 | J37: =XLOOKUP($A37, INDIRECT("'"&J$1&"'!A:A"), INDIRECT("'"&J$1&"'!B:B"), "") -> 0.11764706 | K37: =XLOOKUP($A37, INDIRECT("'"&K$1&"'!A:A"), INDIRECT("'"&K$1&"'!B:B"), "") -> 0.41388889 | L37: =XLOOKUP($A37, INDIRECT("'"&L$1&"'!A:A"), INDIRECT("'"&L$1&"'!B:B"), "") -> 10.55 | M37: =XLOOKUP($A37, INDIRECT("'"&M$1&"'!A:A"), INDIRECT("'"&M$1&"'!B:B"), "") -> 35.933333 | N37: =XLOOKUP($A37, INDIRECT("'"&N$1&"'!A:A"), INDIRECT("'"&N$1&"'!B:B"), "") -> 12.083333 | O37: =XLOOKUP($A37, INDIRECT("'"&O$1&"'!A:A"), INDIRECT("'"&O$1&"'!B:B"), "") -> 0
A38: =EQ!A49 -> 753b3dfbf00b265816877af61db67c39ee3fae2b4e0a7b8f387b5163ff85b1bc | B38: {=XLOOKUP(A38, Notes!A:A, Notes!B:B, "")} -> 53.44 | C38: =IFERROR(IMAGE(VLOOKUP(A38,DriveImages!A:C,3,FALSE),4,240,520),"") | D38: =IF($A38="","",IF(AND(N($G38)<=Params!$D$2,N($H38)<=Params!$E$2),"Peu actif",IF(AND(N($I38)>=Params!$F$4,N($E38)<=Params!$B$2,N($F38)<=Params!$C$2),"Efficace",IF(AND(N($F38)>=Params!$C$4,OR(N($I38)<=Params!$F$3,N($E38)>=Params!$B$4)),"Bloqué",IF(AND(OR(N($G38)>=Params!$D$4,N($H38)>=Params!$E$4),N($I38)<=Params!$F$3),"Persévérant",IF(AND(N($J38)>=Params!$G$4,OR(N($G38)<=Params!$D$3,N($H38)<=Params!$E$3)),"Sporadique","Intermédiaire")))))) -> Sporadique | E38: {=XLOOKUP(A38, EQ!A:A, EQ!B:B, "")} -> 0 | F38: {=XLOOKUP(A38, RED!A:A, RED!B:B, "")} -> 0 | G38: =XLOOKUP(A38, INDIRECT("'"&G$1&"'!A:A"), INDIRECT("'"&G$1&"'!B:B"), "") -> 9 | H38: =XLOOKUP($A38, INDIRECT("'"&H$1&"'!A:A"), INDIRECT("'"&H$1&"'!B:B"), "") -> 4 | I38: =XLOOKUP($A38, INDIRECT("'"&I$1&"'!A:A"), INDIRECT("'"&I$1&"'!B:B"), "") -> 0.66666667 | J38: =XLOOKUP($A38, INDIRECT("'"&J$1&"'!A:A"), INDIRECT("'"&J$1&"'!B:B"), "") -> 0.375 | K38: =XLOOKUP($A38, INDIRECT("'"&K$1&"'!A:A"), INDIRECT("'"&K$1&"'!B:B"), "") -> 0.459596 | L38: =XLOOKUP($A38, INDIRECT("'"&L$1&"'!A:A"), INDIRECT("'"&L$1&"'!B:B"), "") -> 10.633333 | M38: =XLOOKUP($A38, INDIRECT("'"&M$1&"'!A:A"), INDIRECT("'"&M$1&"'!B:B"), "") -> 41.05 | N38: =XLOOKUP($A38, INDIRECT("'"&N$1&"'!A:A"), INDIRECT("'"&N$1&"'!B:B"), "") -> 6.8833333 | O38: =XLOOKUP($A38, INDIRECT("'"&O$1&"'!A:A"), INDIRECT("'"&O$1&"'!B:B"), "") -> 1.7666667
